{
  "_opis": "Mali voz sena kot v vaski kmetiji.",
  "_category": "decor",
  "_kind": "decor",
  "_aliases": [
    "voz sena",
    "cart"
  ],
  "size": [
    7,
    4,
    5
  ],
  "blocks": [
    {
      "x": 0,
      "y": 0,
      "z": 0,
      "name": "grass_block"
    },
    {
      "x": 1,
      "y": 0,
      "z": 0,
      "name": "grass_block"
    },
    {
      "x": 2,
      "y": 0,
      "z": 0,
      "name": "grass_block"
    },
    {
      "x": 3,
      "y": 0,
      "z": 0,
      "name": "grass_block"
    },
    {
      "x": 4,
      "y": 0,
      "z": 0,
      "name": "grass_block"
    },
    {
      "x": 5,
      "y": 0,
      "z": 0,
      "name": "grass_block"
    },
    {
      "x": 6,
      "y": 0,
      "z": 0,
      "name": "grass_block"
    },
    {
      "x": 0,
      "y": 0,
      "z": 1,
      "name": "grass_block"
    },
    {
      "x": 1,
      "y": 0,
      "z": 1,
      "name": "grass_block"
    },
    {
      "x": 2,
      "y": 0,
      "z": 1,
      "name": "grass_block"
    },
    {
      "x": 3,
      "y": 0,
      "z": 1,
      "name": "grass_block"
    },
    {
      "x": 4,
      "y": 0,
      "z": 1,
      "name": "grass_block"
    },
    {
      "x": 5,
      "y": 0,
      "z": 1,
      "name": "grass_block"
    },
    {
      "x": 6,
      "y": 0,
      "z": 1,
      "name": "grass_block"
    },
    {
      "x": 0,
      "y": 0,
      "z": 2,
      "name": "grass_block"
    },
    {
      "x": 1,
      "y": 0,
      "z": 2,
      "name": "grass_block"
    },
    {
      "x": 2,
      "y": 0,
      "z": 2,
      "name": "grass_block"
    },
    {
      "x": 3,
      "y": 0,
      "z": 2,
      "name": "grass_block"
    },
    {
      "x": 4,
      "y": 0,
      "z": 2,
      "name": "grass_block"
    },
    {
      "x": 5,
      "y": 0,
      "z": 2,
      "name": "grass_block"
    },
    {
      "x": 6,
      "y": 0,
      "z": 2,
      "name": "grass_block"
    },
    {
      "x": 0,
      "y": 0,
      "z": 3,
      "name": "grass_block"
    },
    {
      "x": 1,
      "y": 0,
      "z": 3,
      "name": "grass_block"
    },
    {
      "x": 2,
      "y": 0,
      "z": 3,
      "name": "grass_block"
    },
    {
      "x": 3,
      "y": 0,
      "z": 3,
      "name": "grass_block"
    },
    {
      "x": 4,
      "y": 0,
      "z": 3,
      "name": "grass_block"
    },
    {
      "x": 5,
      "y": 0,
      "z": 3,
      "name": "grass_block"
    },
    {
      "x": 6,
      "y": 0,
      "z": 3,
      "name": "grass_block"
    },
    {
      "x": 0,
      "y": 0,
      "z": 4,
      "name": "grass_block"
    },
    {
      "x": 1,
      "y": 0,
      "z": 4,
      "name": "grass_block"
    },
    {
      "x": 2,
      "y": 0,
      "z": 4,
      "name": "grass_block"
    },
    {
      "x": 3,
      "y": 0,
      "z": 4,
      "name": "grass_block"
    },
    {
      "x": 4,
      "y": 0,
      "z": 4,
      "name": "grass_block"
    },
    {
      "x": 5,
      "y": 0,
      "z": 4,
      "name": "grass_block"
    },
    {
      "x": 6,
      "y": 0,
      "z": 4,
      "name": "grass_block"
    },
    {
      "x": 1,
      "y": 1,
      "z": 0,
      "name": "blackstone"
    },
    {
      "x": 5,
      "y": 1,
      "z": 0,
      "name": "blackstone"
    },
    {
      "x": 1,
      "y": 1,
      "z": 1,
      "name": "oak_slab"
    },
    {
      "x": 2,
      "y": 1,
      "z": 1,
      "name": "oak_slab"
    },
    {
      "x": 3,
      "y": 1,
      "z": 1,
      "name": "oak_slab"
    },
    {
      "x": 4,
      "y": 1,
      "z": 1,
      "name": "oak_slab"
    },
    {
      "x": 5,
      "y": 1,
      "z": 1,
      "name": "oak_slab"
    },
    {
      "x": 1,
      "y": 1,
      "z": 2,
      "name": "oak_slab"
    },
    {
      "x": 2,
      "y": 1,
      "z": 2,
      "name": "oak_slab"
    },
    {
      "x": 3,
      "y": 1,
      "z": 2,
      "name": "oak_slab"
    },
    {
      "x": 4,
      "y": 1,
      "z": 2,
      "name": "oak_slab"
    },
    {
      "x": 5,
      "y": 1,
      "z": 2,
      "name": "oak_slab"
    },
    {
      "x": 1,
      "y": 1,
      "z": 3,
      "name": "oak_slab"
    },
    {
      "x": 2,
      "y": 1,
      "z": 3,
      "name": "oak_slab"
    },
    {
      "x": 3,
      "y": 1,
      "z": 3,
      "name": "oak_slab"
    },
    {
      "x": 4,
      "y": 1,
      "z": 3,
      "name": "oak_slab"
    },
    {
      "x": 5,
      "y": 1,
      "z": 3,
      "name": "oak_slab"
    },
    {
      "x": 1,
      "y": 1,
      "z": 4,
      "name": "blackstone"
    },
    {
      "x": 5,
      "y": 1,
      "z": 4,
      "name": "blackstone"
    },
    {
      "x": 2,
      "y": 2,
      "z": 1,
      "name": "hay_block"
    },
    {
      "x": 3,
      "y": 2,
      "z": 1,
      "name": "hay_block"
    },
    {
      "x": 4,
      "y": 2,
      "z": 1,
      "name": "hay_block"
    },
    {
      "x": 0,
      "y": 2,
      "z": 2,
      "name": "oak_fence"
    },
    {
      "x": 1,
      "y": 2,
      "z": 2,
      "name": "oak_fence"
    },
    {
      "x": 2,
      "y": 2,
      "z": 2,
      "name": "hay_block"
    },
    {
      "x": 3,
      "y": 2,
      "z": 2,
      "name": "hay_block"
    },
    {
      "x": 4,
      "y": 2,
      "z": 2,
      "name": "hay_block"
    },
    {
      "x": 5,
      "y": 2,
      "z": 2,
      "name": "oak_fence"
    },
    {
      "x": 6,
      "y": 2,
      "z": 2,
      "name": "oak_fence"
    },
    {
      "x": 2,
      "y": 2,
      "z": 3,
      "name": "hay_block"
    },
    {
      "x": 3,
      "y": 2,
      "z": 3,
      "name": "hay_block"
    },
    {
      "x": 4,
      "y": 2,
      "z": 3,
      "name": "hay_block"
    }
  ]
}
