{"_opis":"Preprosta 5x5 koca iz desk z vrati","size":[5,5,5],"blocks":[{"x":0,"y":0,"z":0,"name":"oak_planks"},{"x":0,"y":4,"z":0,"name":"oak_planks"},{"x":0,"y":0,"z":1,"name":"oak_planks"},{"x":0,"y":4,"z":1,"name":"oak_planks"},{"x":0,"y":0,"z":2,"name":"oak_planks"},{"x":0,"y":4,"z":2,"name":"oak_planks"},{"x":0,"y":0,"z":3,"name":"oak_planks"},{"x":0,"y":4,"z":3,"name":"oak_planks"},{"x":0,"y":0,"z":4,"name":"oak_planks"},{"x":0,"y":4,"z":4,"name":"oak_planks"},{"x":1,"y":0,"z":0,"name":"oak_planks"},{"x":1,"y":4,"z":0,"name":"oak_planks"},{"x":1,"y":0,"z":1,"name":"oak_planks"},{"x":1,"y":4,"z":1,"name":"oak_planks"},{"x":1,"y":0,"z":2,"name":"oak_planks"},{"x":1,"y":4,"z":2,"name":"oak_planks"},{"x":1,"y":0,"z":3,"name":"oak_planks"},{"x":1,"y":4,"z":3,"name":"oak_planks"},{"x":1,"y":0,"z":4,"name":"oak_planks"},{"x":1,"y":4,"z":4,"name":"oak_planks"},{"x":2,"y":0,"z":0,"name":"oak_planks"},{"x":2,"y":4,"z":0,"name":"oak_planks"},{"x":2,"y":0,"z":1,"name":"oak_planks"},{"x":2,"y":4,"z":1,"name":"oak_planks"},{"x":2,"y":0,"z":2,"name":"oak_planks"},{"x":2,"y":4,"z":2,"name":"oak_planks"},{"x":2,"y":0,"z":3,"name":"oak_planks"},{"x":2,"y":4,"z":3,"name":"oak_planks"},{"x":2,"y":0,"z":4,"name":"oak_planks"},{"x":2,"y":4,"z":4,"name":"oak_planks"},{"x":3,"y":0,"z":0,"name":"oak_planks"},{"x":3,"y":4,"z":0,"name":"oak_planks"},{"x":3,"y":0,"z":1,"name":"oak_planks"},{"x":3,"y":4,"z":1,"name":"oak_planks"},{"x":3,"y":0,"z":2,"name":"oak_planks"},{"x":3,"y":4,"z":2,"name":"oak_planks"},{"x":3,"y":0,"z":3,"name":"oak_planks"},{"x":3,"y":4,"z":3,"name":"oak_planks"},{"x":3,"y":0,"z":4,"name":"oak_planks"},{"x":3,"y":4,"z":4,"name":"oak_planks"},{"x":4,"y":0,"z":0,"name":"oak_planks"},{"x":4,"y":4,"z":0,"name":"oak_planks"},{"x":4,"y":0,"z":1,"name":"oak_planks"},{"x":4,"y":4,"z":1,"name":"oak_planks"},{"x":4,"y":0,"z":2,"name":"oak_planks"},{"x":4,"y":4,"z":2,"name":"oak_planks"},{"x":4,"y":0,"z":3,"name":"oak_planks"},{"x":4,"y":4,"z":3,"name":"oak_planks"},{"x":4,"y":0,"z":4,"name":"oak_planks"},{"x":4,"y":4,"z":4,"name":"oak_planks"},{"x":0,"y":1,"z":0,"name":"oak_planks"},{"x":0,"y":1,"z":1,"name":"oak_planks"},{"x":0,"y":1,"z":2,"name":"oak_planks"},{"x":0,"y":1,"z":3,"name":"oak_planks"},{"x":0,"y":1,"z":4,"name":"oak_planks"},{"x":1,"y":1,"z":0,"name":"oak_planks"},{"x":1,"y":1,"z":4,"name":"oak_planks"},{"x":2,"y":1,"z":4,"name":"oak_planks"},{"x":3,"y":1,"z":0,"name":"oak_planks"},{"x":3,"y":1,"z":4,"name":"oak_planks"},{"x":4,"y":1,"z":0,"name":"oak_planks"},{"x":4,"y":1,"z":1,"name":"oak_planks"},{"x":4,"y":1,"z":2,"name":"oak_planks"},{"x":4,"y":1,"z":3,"name":"oak_planks"},{"x":4,"y":1,"z":4,"name":"oak_planks"},{"x":0,"y":2,"z":0,"name":"oak_planks"},{"x":0,"y":2,"z":1,"name":"oak_planks"},{"x":0,"y":2,"z":2,"name":"oak_planks"},{"x":0,"y":2,"z":3,"name":"oak_planks"},{"x":0,"y":2,"z":4,"name":"oak_planks"},{"x":1,"y":2,"z":0,"name":"oak_planks"},{"x":1,"y":2,"z":4,"name":"oak_planks"},{"x":3,"y":2,"z":0,"name":"oak_planks"},{"x":3,"y":2,"z":4,"name":"oak_planks"},{"x":4,"y":2,"z":0,"name":"oak_planks"},{"x":4,"y":2,"z":1,"name":"oak_planks"},{"x":4,"y":2,"z":2,"name":"oak_planks"},{"x":4,"y":2,"z":3,"name":"oak_planks"},{"x":4,"y":2,"z":4,"name":"oak_planks"},{"x":0,"y":3,"z":0,"name":"oak_planks"},{"x":0,"y":3,"z":1,"name":"oak_planks"},{"x":0,"y":3,"z":2,"name":"oak_planks"},{"x":0,"y":3,"z":3,"name":"oak_planks"},{"x":0,"y":3,"z":4,"name":"oak_planks"},{"x":1,"y":3,"z":0,"name":"oak_planks"},{"x":1,"y":3,"z":4,"name":"oak_planks"},{"x":2,"y":3,"z":0,"name":"oak_planks"},{"x":2,"y":3,"z":4,"name":"oak_planks"},{"x":3,"y":3,"z":0,"name":"oak_planks"},{"x":3,"y":3,"z":4,"name":"oak_planks"},{"x":4,"y":3,"z":0,"name":"oak_planks"},{"x":4,"y":3,"z":1,"name":"oak_planks"},{"x":4,"y":3,"z":2,"name":"oak_planks"},{"x":4,"y":3,"z":3,"name":"oak_planks"},{"x":4,"y":3,"z":4,"name":"oak_planks"}]}