{
  "_opis": "Majhna kamnita kapela z visokim barvnim oknom.",
  "_category": "medieval",
  "_kind": "building",
  "_aliases": [
    "kapela",
    "cerkev"
  ],
  "size": [
    9,
    14,
    13
  ],
  "blocks": [
    {
      "x": 0,
      "y": 0,
      "z": 0,
      "name": "polished_andesite"
    },
    {
      "x": 1,
      "y": 0,
      "z": 0,
      "name": "polished_andesite"
    },
    {
      "x": 2,
      "y": 0,
      "z": 0,
      "name": "polished_andesite"
    },
    {
      "x": 3,
      "y": 0,
      "z": 0,
      "name": "polished_andesite"
    },
    {
      "x": 4,
      "y": 0,
      "z": 0,
      "name": "polished_andesite"
    },
    {
      "x": 5,
      "y": 0,
      "z": 0,
      "name": "polished_andesite"
    },
    {
      "x": 6,
      "y": 0,
      "z": 0,
      "name": "polished_andesite"
    },
    {
      "x": 7,
      "y": 0,
      "z": 0,
      "name": "polished_andesite"
    },
    {
      "x": 8,
      "y": 0,
      "z": 0,
      "name": "polished_andesite"
    },
    {
      "x": 0,
      "y": 0,
      "z": 1,
      "name": "polished_andesite"
    },
    {
      "x": 1,
      "y": 0,
      "z": 1,
      "name": "polished_andesite"
    },
    {
      "x": 2,
      "y": 0,
      "z": 1,
      "name": "polished_andesite"
    },
    {
      "x": 3,
      "y": 0,
      "z": 1,
      "name": "polished_andesite"
    },
    {
      "x": 4,
      "y": 0,
      "z": 1,
      "name": "polished_andesite"
    },
    {
      "x": 5,
      "y": 0,
      "z": 1,
      "name": "polished_andesite"
    },
    {
      "x": 6,
      "y": 0,
      "z": 1,
      "name": "polished_andesite"
    },
    {
      "x": 7,
      "y": 0,
      "z": 1,
      "name": "polished_andesite"
    },
    {
      "x": 8,
      "y": 0,
      "z": 1,
      "name": "polished_andesite"
    },
    {
      "x": 0,
      "y": 0,
      "z": 2,
      "name": "polished_andesite"
    },
    {
      "x": 1,
      "y": 0,
      "z": 2,
      "name": "polished_andesite"
    },
    {
      "x": 2,
      "y": 0,
      "z": 2,
      "name": "polished_andesite"
    },
    {
      "x": 3,
      "y": 0,
      "z": 2,
      "name": "polished_andesite"
    },
    {
      "x": 4,
      "y": 0,
      "z": 2,
      "name": "polished_andesite"
    },
    {
      "x": 5,
      "y": 0,
      "z": 2,
      "name": "polished_andesite"
    },
    {
      "x": 6,
      "y": 0,
      "z": 2,
      "name": "polished_andesite"
    },
    {
      "x": 7,
      "y": 0,
      "z": 2,
      "name": "polished_andesite"
    },
    {
      "x": 8,
      "y": 0,
      "z": 2,
      "name": "polished_andesite"
    },
    {
      "x": 0,
      "y": 0,
      "z": 3,
      "name": "polished_andesite"
    },
    {
      "x": 1,
      "y": 0,
      "z": 3,
      "name": "polished_andesite"
    },
    {
      "x": 2,
      "y": 0,
      "z": 3,
      "name": "polished_andesite"
    },
    {
      "x": 3,
      "y": 0,
      "z": 3,
      "name": "polished_andesite"
    },
    {
      "x": 4,
      "y": 0,
      "z": 3,
      "name": "polished_andesite"
    },
    {
      "x": 5,
      "y": 0,
      "z": 3,
      "name": "polished_andesite"
    },
    {
      "x": 6,
      "y": 0,
      "z": 3,
      "name": "polished_andesite"
    },
    {
      "x": 7,
      "y": 0,
      "z": 3,
      "name": "polished_andesite"
    },
    {
      "x": 8,
      "y": 0,
      "z": 3,
      "name": "polished_andesite"
    },
    {
      "x": 0,
      "y": 0,
      "z": 4,
      "name": "polished_andesite"
    },
    {
      "x": 1,
      "y": 0,
      "z": 4,
      "name": "polished_andesite"
    },
    {
      "x": 2,
      "y": 0,
      "z": 4,
      "name": "polished_andesite"
    },
    {
      "x": 3,
      "y": 0,
      "z": 4,
      "name": "polished_andesite"
    },
    {
      "x": 4,
      "y": 0,
      "z": 4,
      "name": "polished_andesite"
    },
    {
      "x": 5,
      "y": 0,
      "z": 4,
      "name": "polished_andesite"
    },
    {
      "x": 6,
      "y": 0,
      "z": 4,
      "name": "polished_andesite"
    },
    {
      "x": 7,
      "y": 0,
      "z": 4,
      "name": "polished_andesite"
    },
    {
      "x": 8,
      "y": 0,
      "z": 4,
      "name": "polished_andesite"
    },
    {
      "x": 0,
      "y": 0,
      "z": 5,
      "name": "polished_andesite"
    },
    {
      "x": 1,
      "y": 0,
      "z": 5,
      "name": "polished_andesite"
    },
    {
      "x": 2,
      "y": 0,
      "z": 5,
      "name": "polished_andesite"
    },
    {
      "x": 3,
      "y": 0,
      "z": 5,
      "name": "polished_andesite"
    },
    {
      "x": 4,
      "y": 0,
      "z": 5,
      "name": "polished_andesite"
    },
    {
      "x": 5,
      "y": 0,
      "z": 5,
      "name": "polished_andesite"
    },
    {
      "x": 6,
      "y": 0,
      "z": 5,
      "name": "polished_andesite"
    },
    {
      "x": 7,
      "y": 0,
      "z": 5,
      "name": "polished_andesite"
    },
    {
      "x": 8,
      "y": 0,
      "z": 5,
      "name": "polished_andesite"
    },
    {
      "x": 0,
      "y": 0,
      "z": 6,
      "name": "polished_andesite"
    },
    {
      "x": 1,
      "y": 0,
      "z": 6,
      "name": "polished_andesite"
    },
    {
      "x": 2,
      "y": 0,
      "z": 6,
      "name": "polished_andesite"
    },
    {
      "x": 3,
      "y": 0,
      "z": 6,
      "name": "polished_andesite"
    },
    {
      "x": 4,
      "y": 0,
      "z": 6,
      "name": "polished_andesite"
    },
    {
      "x": 5,
      "y": 0,
      "z": 6,
      "name": "polished_andesite"
    },
    {
      "x": 6,
      "y": 0,
      "z": 6,
      "name": "polished_andesite"
    },
    {
      "x": 7,
      "y": 0,
      "z": 6,
      "name": "polished_andesite"
    },
    {
      "x": 8,
      "y": 0,
      "z": 6,
      "name": "polished_andesite"
    },
    {
      "x": 0,
      "y": 0,
      "z": 7,
      "name": "polished_andesite"
    },
    {
      "x": 1,
      "y": 0,
      "z": 7,
      "name": "polished_andesite"
    },
    {
      "x": 2,
      "y": 0,
      "z": 7,
      "name": "polished_andesite"
    },
    {
      "x": 3,
      "y": 0,
      "z": 7,
      "name": "polished_andesite"
    },
    {
      "x": 4,
      "y": 0,
      "z": 7,
      "name": "polished_andesite"
    },
    {
      "x": 5,
      "y": 0,
      "z": 7,
      "name": "polished_andesite"
    },
    {
      "x": 6,
      "y": 0,
      "z": 7,
      "name": "polished_andesite"
    },
    {
      "x": 7,
      "y": 0,
      "z": 7,
      "name": "polished_andesite"
    },
    {
      "x": 8,
      "y": 0,
      "z": 7,
      "name": "polished_andesite"
    },
    {
      "x": 0,
      "y": 0,
      "z": 8,
      "name": "polished_andesite"
    },
    {
      "x": 1,
      "y": 0,
      "z": 8,
      "name": "polished_andesite"
    },
    {
      "x": 2,
      "y": 0,
      "z": 8,
      "name": "polished_andesite"
    },
    {
      "x": 3,
      "y": 0,
      "z": 8,
      "name": "polished_andesite"
    },
    {
      "x": 4,
      "y": 0,
      "z": 8,
      "name": "polished_andesite"
    },
    {
      "x": 5,
      "y": 0,
      "z": 8,
      "name": "polished_andesite"
    },
    {
      "x": 6,
      "y": 0,
      "z": 8,
      "name": "polished_andesite"
    },
    {
      "x": 7,
      "y": 0,
      "z": 8,
      "name": "polished_andesite"
    },
    {
      "x": 8,
      "y": 0,
      "z": 8,
      "name": "polished_andesite"
    },
    {
      "x": 0,
      "y": 0,
      "z": 9,
      "name": "polished_andesite"
    },
    {
      "x": 1,
      "y": 0,
      "z": 9,
      "name": "polished_andesite"
    },
    {
      "x": 2,
      "y": 0,
      "z": 9,
      "name": "polished_andesite"
    },
    {
      "x": 3,
      "y": 0,
      "z": 9,
      "name": "polished_andesite"
    },
    {
      "x": 4,
      "y": 0,
      "z": 9,
      "name": "polished_andesite"
    },
    {
      "x": 5,
      "y": 0,
      "z": 9,
      "name": "polished_andesite"
    },
    {
      "x": 6,
      "y": 0,
      "z": 9,
      "name": "polished_andesite"
    },
    {
      "x": 7,
      "y": 0,
      "z": 9,
      "name": "polished_andesite"
    },
    {
      "x": 8,
      "y": 0,
      "z": 9,
      "name": "polished_andesite"
    },
    {
      "x": 0,
      "y": 0,
      "z": 10,
      "name": "polished_andesite"
    },
    {
      "x": 1,
      "y": 0,
      "z": 10,
      "name": "polished_andesite"
    },
    {
      "x": 2,
      "y": 0,
      "z": 10,
      "name": "polished_andesite"
    },
    {
      "x": 3,
      "y": 0,
      "z": 10,
      "name": "polished_andesite"
    },
    {
      "x": 4,
      "y": 0,
      "z": 10,
      "name": "polished_andesite"
    },
    {
      "x": 5,
      "y": 0,
      "z": 10,
      "name": "polished_andesite"
    },
    {
      "x": 6,
      "y": 0,
      "z": 10,
      "name": "polished_andesite"
    },
    {
      "x": 7,
      "y": 0,
      "z": 10,
      "name": "polished_andesite"
    },
    {
      "x": 8,
      "y": 0,
      "z": 10,
      "name": "polished_andesite"
    },
    {
      "x": 0,
      "y": 0,
      "z": 11,
      "name": "polished_andesite"
    },
    {
      "x": 1,
      "y": 0,
      "z": 11,
      "name": "polished_andesite"
    },
    {
      "x": 2,
      "y": 0,
      "z": 11,
      "name": "polished_andesite"
    },
    {
      "x": 3,
      "y": 0,
      "z": 11,
      "name": "polished_andesite"
    },
    {
      "x": 4,
      "y": 0,
      "z": 11,
      "name": "polished_andesite"
    },
    {
      "x": 5,
      "y": 0,
      "z": 11,
      "name": "polished_andesite"
    },
    {
      "x": 6,
      "y": 0,
      "z": 11,
      "name": "polished_andesite"
    },
    {
      "x": 7,
      "y": 0,
      "z": 11,
      "name": "polished_andesite"
    },
    {
      "x": 8,
      "y": 0,
      "z": 11,
      "name": "polished_andesite"
    },
    {
      "x": 0,
      "y": 0,
      "z": 12,
      "name": "polished_andesite"
    },
    {
      "x": 1,
      "y": 0,
      "z": 12,
      "name": "polished_andesite"
    },
    {
      "x": 2,
      "y": 0,
      "z": 12,
      "name": "polished_andesite"
    },
    {
      "x": 3,
      "y": 0,
      "z": 12,
      "name": "polished_andesite"
    },
    {
      "x": 4,
      "y": 0,
      "z": 12,
      "name": "polished_andesite"
    },
    {
      "x": 5,
      "y": 0,
      "z": 12,
      "name": "polished_andesite"
    },
    {
      "x": 6,
      "y": 0,
      "z": 12,
      "name": "polished_andesite"
    },
    {
      "x": 7,
      "y": 0,
      "z": 12,
      "name": "polished_andesite"
    },
    {
      "x": 8,
      "y": 0,
      "z": 12,
      "name": "polished_andesite"
    },
    {
      "x": 0,
      "y": 1,
      "z": 0,
      "name": "cobblestone"
    },
    {
      "x": 1,
      "y": 1,
      "z": 0,
      "name": "stone_bricks"
    },
    {
      "x": 2,
      "y": 1,
      "z": 0,
      "name": "stone_bricks"
    },
    {
      "x": 3,
      "y": 1,
      "z": 0,
      "name": "stone_bricks"
    },
    {
      "x": 4,
      "y": 1,
      "z": 0,
      "name": "dark_oak_door"
    },
    {
      "x": 5,
      "y": 1,
      "z": 0,
      "name": "stone_bricks"
    },
    {
      "x": 6,
      "y": 1,
      "z": 0,
      "name": "stone_bricks"
    },
    {
      "x": 7,
      "y": 1,
      "z": 0,
      "name": "stone_bricks"
    },
    {
      "x": 8,
      "y": 1,
      "z": 0,
      "name": "cobblestone"
    },
    {
      "x": 0,
      "y": 1,
      "z": 1,
      "name": "stone_bricks"
    },
    {
      "x": 1,
      "y": 1,
      "z": 1,
      "name": "crafting_table"
    },
    {
      "x": 7,
      "y": 1,
      "z": 1,
      "name": "furnace"
    },
    {
      "x": 8,
      "y": 1,
      "z": 1,
      "name": "stone_bricks"
    },
    {
      "x": 0,
      "y": 1,
      "z": 2,
      "name": "stone_bricks"
    },
    {
      "x": 8,
      "y": 1,
      "z": 2,
      "name": "stone_bricks"
    },
    {
      "x": 0,
      "y": 1,
      "z": 3,
      "name": "stone_bricks"
    },
    {
      "x": 8,
      "y": 1,
      "z": 3,
      "name": "stone_bricks"
    },
    {
      "x": 0,
      "y": 1,
      "z": 4,
      "name": "stone_bricks"
    },
    {
      "x": 8,
      "y": 1,
      "z": 4,
      "name": "stone_bricks"
    },
    {
      "x": 0,
      "y": 1,
      "z": 5,
      "name": "stone_bricks"
    },
    {
      "x": 8,
      "y": 1,
      "z": 5,
      "name": "stone_bricks"
    },
    {
      "x": 0,
      "y": 1,
      "z": 6,
      "name": "stone_bricks"
    },
    {
      "x": 8,
      "y": 1,
      "z": 6,
      "name": "stone_bricks"
    },
    {
      "x": 0,
      "y": 1,
      "z": 7,
      "name": "stone_bricks"
    },
    {
      "x": 8,
      "y": 1,
      "z": 7,
      "name": "stone_bricks"
    },
    {
      "x": 0,
      "y": 1,
      "z": 8,
      "name": "stone_bricks"
    },
    {
      "x": 8,
      "y": 1,
      "z": 8,
      "name": "stone_bricks"
    },
    {
      "x": 0,
      "y": 1,
      "z": 9,
      "name": "stone_bricks"
    },
    {
      "x": 3,
      "y": 1,
      "z": 9,
      "name": "oak_planks"
    },
    {
      "x": 4,
      "y": 1,
      "z": 9,
      "name": "oak_planks"
    },
    {
      "x": 5,
      "y": 1,
      "z": 9,
      "name": "oak_planks"
    },
    {
      "x": 8,
      "y": 1,
      "z": 9,
      "name": "stone_bricks"
    },
    {
      "x": 0,
      "y": 1,
      "z": 10,
      "name": "stone_bricks"
    },
    {
      "x": 8,
      "y": 1,
      "z": 10,
      "name": "stone_bricks"
    },
    {
      "x": 0,
      "y": 1,
      "z": 11,
      "name": "stone_bricks"
    },
    {
      "x": 7,
      "y": 1,
      "z": 11,
      "name": "chest"
    },
    {
      "x": 8,
      "y": 1,
      "z": 11,
      "name": "stone_bricks"
    },
    {
      "x": 0,
      "y": 1,
      "z": 12,
      "name": "cobblestone"
    },
    {
      "x": 1,
      "y": 1,
      "z": 12,
      "name": "stone_bricks"
    },
    {
      "x": 2,
      "y": 1,
      "z": 12,
      "name": "stone_bricks"
    },
    {
      "x": 3,
      "y": 1,
      "z": 12,
      "name": "stone_bricks"
    },
    {
      "x": 4,
      "y": 1,
      "z": 12,
      "name": "stone_bricks"
    },
    {
      "x": 5,
      "y": 1,
      "z": 12,
      "name": "stone_bricks"
    },
    {
      "x": 6,
      "y": 1,
      "z": 12,
      "name": "stone_bricks"
    },
    {
      "x": 7,
      "y": 1,
      "z": 12,
      "name": "stone_bricks"
    },
    {
      "x": 8,
      "y": 1,
      "z": 12,
      "name": "cobblestone"
    },
    {
      "x": 0,
      "y": 2,
      "z": 0,
      "name": "cobblestone"
    },
    {
      "x": 1,
      "y": 2,
      "z": 0,
      "name": "stone_bricks"
    },
    {
      "x": 2,
      "y": 2,
      "z": 0,
      "name": "yellow_stained_glass"
    },
    {
      "x": 3,
      "y": 2,
      "z": 0,
      "name": "stone_bricks"
    },
    {
      "x": 5,
      "y": 2,
      "z": 0,
      "name": "stone_bricks"
    },
    {
      "x": 6,
      "y": 2,
      "z": 0,
      "name": "yellow_stained_glass"
    },
    {
      "x": 7,
      "y": 2,
      "z": 0,
      "name": "stone_bricks"
    },
    {
      "x": 8,
      "y": 2,
      "z": 0,
      "name": "cobblestone"
    },
    {
      "x": 0,
      "y": 2,
      "z": 1,
      "name": "stone_bricks"
    },
    {
      "x": 8,
      "y": 2,
      "z": 1,
      "name": "stone_bricks"
    },
    {
      "x": 0,
      "y": 2,
      "z": 2,
      "name": "yellow_stained_glass"
    },
    {
      "x": 8,
      "y": 2,
      "z": 2,
      "name": "yellow_stained_glass"
    },
    {
      "x": 0,
      "y": 2,
      "z": 3,
      "name": "stone_bricks"
    },
    {
      "x": 8,
      "y": 2,
      "z": 3,
      "name": "stone_bricks"
    },
    {
      "x": 0,
      "y": 2,
      "z": 4,
      "name": "stone_bricks"
    },
    {
      "x": 8,
      "y": 2,
      "z": 4,
      "name": "stone_bricks"
    },
    {
      "x": 0,
      "y": 2,
      "z": 5,
      "name": "stone_bricks"
    },
    {
      "x": 8,
      "y": 2,
      "z": 5,
      "name": "stone_bricks"
    },
    {
      "x": 0,
      "y": 2,
      "z": 6,
      "name": "stone_bricks"
    },
    {
      "x": 8,
      "y": 2,
      "z": 6,
      "name": "stone_bricks"
    },
    {
      "x": 0,
      "y": 2,
      "z": 7,
      "name": "stone_bricks"
    },
    {
      "x": 8,
      "y": 2,
      "z": 7,
      "name": "stone_bricks"
    },
    {
      "x": 0,
      "y": 2,
      "z": 8,
      "name": "stone_bricks"
    },
    {
      "x": 8,
      "y": 2,
      "z": 8,
      "name": "stone_bricks"
    },
    {
      "x": 0,
      "y": 2,
      "z": 9,
      "name": "stone_bricks"
    },
    {
      "x": 4,
      "y": 2,
      "z": 9,
      "name": "lantern"
    },
    {
      "x": 8,
      "y": 2,
      "z": 9,
      "name": "stone_bricks"
    },
    {
      "x": 0,
      "y": 2,
      "z": 10,
      "name": "yellow_stained_glass"
    },
    {
      "x": 8,
      "y": 2,
      "z": 10,
      "name": "yellow_stained_glass"
    },
    {
      "x": 0,
      "y": 2,
      "z": 11,
      "name": "stone_bricks"
    },
    {
      "x": 8,
      "y": 2,
      "z": 11,
      "name": "stone_bricks"
    },
    {
      "x": 0,
      "y": 2,
      "z": 12,
      "name": "cobblestone"
    },
    {
      "x": 1,
      "y": 2,
      "z": 12,
      "name": "stone_bricks"
    },
    {
      "x": 2,
      "y": 2,
      "z": 12,
      "name": "yellow_stained_glass"
    },
    {
      "x": 3,
      "y": 2,
      "z": 12,
      "name": "stone_bricks"
    },
    {
      "x": 4,
      "y": 2,
      "z": 12,
      "name": "red_stained_glass"
    },
    {
      "x": 5,
      "y": 2,
      "z": 12,
      "name": "stone_bricks"
    },
    {
      "x": 6,
      "y": 2,
      "z": 12,
      "name": "yellow_stained_glass"
    },
    {
      "x": 7,
      "y": 2,
      "z": 12,
      "name": "stone_bricks"
    },
    {
      "x": 8,
      "y": 2,
      "z": 12,
      "name": "cobblestone"
    },
    {
      "x": 0,
      "y": 3,
      "z": 0,
      "name": "cobblestone"
    },
    {
      "x": 1,
      "y": 3,
      "z": 0,
      "name": "stone_bricks"
    },
    {
      "x": 2,
      "y": 3,
      "z": 0,
      "name": "stone_bricks"
    },
    {
      "x": 3,
      "y": 3,
      "z": 0,
      "name": "stone_bricks"
    },
    {
      "x": 4,
      "y": 3,
      "z": 0,
      "name": "stone_bricks"
    },
    {
      "x": 5,
      "y": 3,
      "z": 0,
      "name": "stone_bricks"
    },
    {
      "x": 6,
      "y": 3,
      "z": 0,
      "name": "stone_bricks"
    },
    {
      "x": 7,
      "y": 3,
      "z": 0,
      "name": "stone_bricks"
    },
    {
      "x": 8,
      "y": 3,
      "z": 0,
      "name": "cobblestone"
    },
    {
      "x": 0,
      "y": 3,
      "z": 1,
      "name": "stone_bricks"
    },
    {
      "x": 8,
      "y": 3,
      "z": 1,
      "name": "stone_bricks"
    },
    {
      "x": 0,
      "y": 3,
      "z": 2,
      "name": "stone_bricks"
    },
    {
      "x": 8,
      "y": 3,
      "z": 2,
      "name": "stone_bricks"
    },
    {
      "x": 0,
      "y": 3,
      "z": 3,
      "name": "stone_bricks"
    },
    {
      "x": 8,
      "y": 3,
      "z": 3,
      "name": "stone_bricks"
    },
    {
      "x": 0,
      "y": 3,
      "z": 4,
      "name": "stone_bricks"
    },
    {
      "x": 8,
      "y": 3,
      "z": 4,
      "name": "stone_bricks"
    },
    {
      "x": 0,
      "y": 3,
      "z": 5,
      "name": "stone_bricks"
    },
    {
      "x": 8,
      "y": 3,
      "z": 5,
      "name": "stone_bricks"
    },
    {
      "x": 0,
      "y": 3,
      "z": 6,
      "name": "stone_bricks"
    },
    {
      "x": 8,
      "y": 3,
      "z": 6,
      "name": "stone_bricks"
    },
    {
      "x": 0,
      "y": 3,
      "z": 7,
      "name": "stone_bricks"
    },
    {
      "x": 8,
      "y": 3,
      "z": 7,
      "name": "stone_bricks"
    },
    {
      "x": 0,
      "y": 3,
      "z": 8,
      "name": "stone_bricks"
    },
    {
      "x": 8,
      "y": 3,
      "z": 8,
      "name": "stone_bricks"
    },
    {
      "x": 0,
      "y": 3,
      "z": 9,
      "name": "stone_bricks"
    },
    {
      "x": 8,
      "y": 3,
      "z": 9,
      "name": "stone_bricks"
    },
    {
      "x": 0,
      "y": 3,
      "z": 10,
      "name": "stone_bricks"
    },
    {
      "x": 8,
      "y": 3,
      "z": 10,
      "name": "stone_bricks"
    },
    {
      "x": 0,
      "y": 3,
      "z": 11,
      "name": "stone_bricks"
    },
    {
      "x": 8,
      "y": 3,
      "z": 11,
      "name": "stone_bricks"
    },
    {
      "x": 0,
      "y": 3,
      "z": 12,
      "name": "cobblestone"
    },
    {
      "x": 1,
      "y": 3,
      "z": 12,
      "name": "stone_bricks"
    },
    {
      "x": 2,
      "y": 3,
      "z": 12,
      "name": "stone_bricks"
    },
    {
      "x": 3,
      "y": 3,
      "z": 12,
      "name": "stone_bricks"
    },
    {
      "x": 4,
      "y": 3,
      "z": 12,
      "name": "yellow_stained_glass"
    },
    {
      "x": 5,
      "y": 3,
      "z": 12,
      "name": "stone_bricks"
    },
    {
      "x": 6,
      "y": 3,
      "z": 12,
      "name": "stone_bricks"
    },
    {
      "x": 7,
      "y": 3,
      "z": 12,
      "name": "stone_bricks"
    },
    {
      "x": 8,
      "y": 3,
      "z": 12,
      "name": "cobblestone"
    },
    {
      "x": 0,
      "y": 4,
      "z": 0,
      "name": "cobblestone"
    },
    {
      "x": 1,
      "y": 4,
      "z": 0,
      "name": "stone_bricks"
    },
    {
      "x": 2,
      "y": 4,
      "z": 0,
      "name": "stone_bricks"
    },
    {
      "x": 3,
      "y": 4,
      "z": 0,
      "name": "stone_bricks"
    },
    {
      "x": 4,
      "y": 4,
      "z": 0,
      "name": "stone_bricks"
    },
    {
      "x": 5,
      "y": 4,
      "z": 0,
      "name": "stone_bricks"
    },
    {
      "x": 6,
      "y": 4,
      "z": 0,
      "name": "stone_bricks"
    },
    {
      "x": 7,
      "y": 4,
      "z": 0,
      "name": "stone_bricks"
    },
    {
      "x": 8,
      "y": 4,
      "z": 0,
      "name": "cobblestone"
    },
    {
      "x": 0,
      "y": 4,
      "z": 1,
      "name": "stone_bricks"
    },
    {
      "x": 8,
      "y": 4,
      "z": 1,
      "name": "stone_bricks"
    },
    {
      "x": 0,
      "y": 4,
      "z": 2,
      "name": "stone_bricks"
    },
    {
      "x": 8,
      "y": 4,
      "z": 2,
      "name": "stone_bricks"
    },
    {
      "x": 0,
      "y": 4,
      "z": 3,
      "name": "stone_bricks"
    },
    {
      "x": 8,
      "y": 4,
      "z": 3,
      "name": "stone_bricks"
    },
    {
      "x": 0,
      "y": 4,
      "z": 4,
      "name": "stone_bricks"
    },
    {
      "x": 8,
      "y": 4,
      "z": 4,
      "name": "stone_bricks"
    },
    {
      "x": 0,
      "y": 4,
      "z": 5,
      "name": "stone_bricks"
    },
    {
      "x": 8,
      "y": 4,
      "z": 5,
      "name": "stone_bricks"
    },
    {
      "x": 0,
      "y": 4,
      "z": 6,
      "name": "stone_bricks"
    },
    {
      "x": 8,
      "y": 4,
      "z": 6,
      "name": "stone_bricks"
    },
    {
      "x": 0,
      "y": 4,
      "z": 7,
      "name": "stone_bricks"
    },
    {
      "x": 8,
      "y": 4,
      "z": 7,
      "name": "stone_bricks"
    },
    {
      "x": 0,
      "y": 4,
      "z": 8,
      "name": "stone_bricks"
    },
    {
      "x": 8,
      "y": 4,
      "z": 8,
      "name": "stone_bricks"
    },
    {
      "x": 0,
      "y": 4,
      "z": 9,
      "name": "stone_bricks"
    },
    {
      "x": 8,
      "y": 4,
      "z": 9,
      "name": "stone_bricks"
    },
    {
      "x": 0,
      "y": 4,
      "z": 10,
      "name": "stone_bricks"
    },
    {
      "x": 8,
      "y": 4,
      "z": 10,
      "name": "stone_bricks"
    },
    {
      "x": 0,
      "y": 4,
      "z": 11,
      "name": "stone_bricks"
    },
    {
      "x": 8,
      "y": 4,
      "z": 11,
      "name": "stone_bricks"
    },
    {
      "x": 0,
      "y": 4,
      "z": 12,
      "name": "cobblestone"
    },
    {
      "x": 1,
      "y": 4,
      "z": 12,
      "name": "stone_bricks"
    },
    {
      "x": 2,
      "y": 4,
      "z": 12,
      "name": "stone_bricks"
    },
    {
      "x": 3,
      "y": 4,
      "z": 12,
      "name": "stone_bricks"
    },
    {
      "x": 4,
      "y": 4,
      "z": 12,
      "name": "red_stained_glass"
    },
    {
      "x": 5,
      "y": 4,
      "z": 12,
      "name": "stone_bricks"
    },
    {
      "x": 6,
      "y": 4,
      "z": 12,
      "name": "stone_bricks"
    },
    {
      "x": 7,
      "y": 4,
      "z": 12,
      "name": "stone_bricks"
    },
    {
      "x": 8,
      "y": 4,
      "z": 12,
      "name": "cobblestone"
    },
    {
      "x": 0,
      "y": 5,
      "z": 0,
      "name": "cobblestone"
    },
    {
      "x": 1,
      "y": 5,
      "z": 0,
      "name": "stone_bricks"
    },
    {
      "x": 2,
      "y": 5,
      "z": 0,
      "name": "stone_bricks"
    },
    {
      "x": 3,
      "y": 5,
      "z": 0,
      "name": "stone_bricks"
    },
    {
      "x": 4,
      "y": 5,
      "z": 0,
      "name": "stone_bricks"
    },
    {
      "x": 5,
      "y": 5,
      "z": 0,
      "name": "stone_bricks"
    },
    {
      "x": 6,
      "y": 5,
      "z": 0,
      "name": "stone_bricks"
    },
    {
      "x": 7,
      "y": 5,
      "z": 0,
      "name": "stone_bricks"
    },
    {
      "x": 8,
      "y": 5,
      "z": 0,
      "name": "cobblestone"
    },
    {
      "x": 0,
      "y": 5,
      "z": 1,
      "name": "stone_bricks"
    },
    {
      "x": 8,
      "y": 5,
      "z": 1,
      "name": "stone_bricks"
    },
    {
      "x": 0,
      "y": 5,
      "z": 2,
      "name": "stone_bricks"
    },
    {
      "x": 8,
      "y": 5,
      "z": 2,
      "name": "stone_bricks"
    },
    {
      "x": 0,
      "y": 5,
      "z": 3,
      "name": "stone_bricks"
    },
    {
      "x": 8,
      "y": 5,
      "z": 3,
      "name": "stone_bricks"
    },
    {
      "x": 0,
      "y": 5,
      "z": 4,
      "name": "stone_bricks"
    },
    {
      "x": 8,
      "y": 5,
      "z": 4,
      "name": "stone_bricks"
    },
    {
      "x": 0,
      "y": 5,
      "z": 5,
      "name": "stone_bricks"
    },
    {
      "x": 8,
      "y": 5,
      "z": 5,
      "name": "stone_bricks"
    },
    {
      "x": 0,
      "y": 5,
      "z": 6,
      "name": "stone_bricks"
    },
    {
      "x": 8,
      "y": 5,
      "z": 6,
      "name": "stone_bricks"
    },
    {
      "x": 0,
      "y": 5,
      "z": 7,
      "name": "stone_bricks"
    },
    {
      "x": 8,
      "y": 5,
      "z": 7,
      "name": "stone_bricks"
    },
    {
      "x": 0,
      "y": 5,
      "z": 8,
      "name": "stone_bricks"
    },
    {
      "x": 8,
      "y": 5,
      "z": 8,
      "name": "stone_bricks"
    },
    {
      "x": 0,
      "y": 5,
      "z": 9,
      "name": "stone_bricks"
    },
    {
      "x": 8,
      "y": 5,
      "z": 9,
      "name": "stone_bricks"
    },
    {
      "x": 0,
      "y": 5,
      "z": 10,
      "name": "stone_bricks"
    },
    {
      "x": 8,
      "y": 5,
      "z": 10,
      "name": "stone_bricks"
    },
    {
      "x": 0,
      "y": 5,
      "z": 11,
      "name": "stone_bricks"
    },
    {
      "x": 8,
      "y": 5,
      "z": 11,
      "name": "stone_bricks"
    },
    {
      "x": 0,
      "y": 5,
      "z": 12,
      "name": "cobblestone"
    },
    {
      "x": 1,
      "y": 5,
      "z": 12,
      "name": "stone_bricks"
    },
    {
      "x": 2,
      "y": 5,
      "z": 12,
      "name": "stone_bricks"
    },
    {
      "x": 3,
      "y": 5,
      "z": 12,
      "name": "stone_bricks"
    },
    {
      "x": 4,
      "y": 5,
      "z": 12,
      "name": "stone_bricks"
    },
    {
      "x": 5,
      "y": 5,
      "z": 12,
      "name": "stone_bricks"
    },
    {
      "x": 6,
      "y": 5,
      "z": 12,
      "name": "stone_bricks"
    },
    {
      "x": 7,
      "y": 5,
      "z": 12,
      "name": "stone_bricks"
    },
    {
      "x": 8,
      "y": 5,
      "z": 12,
      "name": "cobblestone"
    },
    {
      "x": 0,
      "y": 6,
      "z": 0,
      "name": "deepslate_tiles"
    },
    {
      "x": 1,
      "y": 6,
      "z": 0,
      "name": "deepslate_tiles"
    },
    {
      "x": 2,
      "y": 6,
      "z": 0,
      "name": "deepslate_tiles"
    },
    {
      "x": 3,
      "y": 6,
      "z": 0,
      "name": "deepslate_tiles"
    },
    {
      "x": 4,
      "y": 6,
      "z": 0,
      "name": "deepslate_tiles"
    },
    {
      "x": 5,
      "y": 6,
      "z": 0,
      "name": "deepslate_tiles"
    },
    {
      "x": 6,
      "y": 6,
      "z": 0,
      "name": "deepslate_tiles"
    },
    {
      "x": 7,
      "y": 6,
      "z": 0,
      "name": "deepslate_tiles"
    },
    {
      "x": 8,
      "y": 6,
      "z": 0,
      "name": "deepslate_tiles"
    },
    {
      "x": 0,
      "y": 6,
      "z": 12,
      "name": "deepslate_tiles"
    },
    {
      "x": 1,
      "y": 6,
      "z": 12,
      "name": "deepslate_tiles"
    },
    {
      "x": 2,
      "y": 6,
      "z": 12,
      "name": "deepslate_tiles"
    },
    {
      "x": 3,
      "y": 6,
      "z": 12,
      "name": "deepslate_tiles"
    },
    {
      "x": 4,
      "y": 6,
      "z": 12,
      "name": "deepslate_tiles"
    },
    {
      "x": 5,
      "y": 6,
      "z": 12,
      "name": "deepslate_tiles"
    },
    {
      "x": 6,
      "y": 6,
      "z": 12,
      "name": "deepslate_tiles"
    },
    {
      "x": 7,
      "y": 6,
      "z": 12,
      "name": "deepslate_tiles"
    },
    {
      "x": 8,
      "y": 6,
      "z": 12,
      "name": "deepslate_tiles"
    },
    {
      "x": 0,
      "y": 7,
      "z": 1,
      "name": "deepslate_tiles"
    },
    {
      "x": 1,
      "y": 7,
      "z": 1,
      "name": "deepslate_tiles"
    },
    {
      "x": 2,
      "y": 7,
      "z": 1,
      "name": "deepslate_tiles"
    },
    {
      "x": 3,
      "y": 7,
      "z": 1,
      "name": "deepslate_tiles"
    },
    {
      "x": 4,
      "y": 7,
      "z": 1,
      "name": "deepslate_tiles"
    },
    {
      "x": 5,
      "y": 7,
      "z": 1,
      "name": "deepslate_tiles"
    },
    {
      "x": 6,
      "y": 7,
      "z": 1,
      "name": "deepslate_tiles"
    },
    {
      "x": 7,
      "y": 7,
      "z": 1,
      "name": "deepslate_tiles"
    },
    {
      "x": 8,
      "y": 7,
      "z": 1,
      "name": "deepslate_tiles"
    },
    {
      "x": 0,
      "y": 7,
      "z": 11,
      "name": "deepslate_tiles"
    },
    {
      "x": 1,
      "y": 7,
      "z": 11,
      "name": "deepslate_tiles"
    },
    {
      "x": 2,
      "y": 7,
      "z": 11,
      "name": "deepslate_tiles"
    },
    {
      "x": 3,
      "y": 7,
      "z": 11,
      "name": "deepslate_tiles"
    },
    {
      "x": 4,
      "y": 7,
      "z": 11,
      "name": "deepslate_tiles"
    },
    {
      "x": 5,
      "y": 7,
      "z": 11,
      "name": "deepslate_tiles"
    },
    {
      "x": 6,
      "y": 7,
      "z": 11,
      "name": "deepslate_tiles"
    },
    {
      "x": 7,
      "y": 7,
      "z": 11,
      "name": "deepslate_tiles"
    },
    {
      "x": 8,
      "y": 7,
      "z": 11,
      "name": "deepslate_tiles"
    },
    {
      "x": 0,
      "y": 8,
      "z": 2,
      "name": "deepslate_tiles"
    },
    {
      "x": 1,
      "y": 8,
      "z": 2,
      "name": "deepslate_tiles"
    },
    {
      "x": 2,
      "y": 8,
      "z": 2,
      "name": "deepslate_tiles"
    },
    {
      "x": 3,
      "y": 8,
      "z": 2,
      "name": "deepslate_tiles"
    },
    {
      "x": 4,
      "y": 8,
      "z": 2,
      "name": "deepslate_tiles"
    },
    {
      "x": 5,
      "y": 8,
      "z": 2,
      "name": "deepslate_tiles"
    },
    {
      "x": 6,
      "y": 8,
      "z": 2,
      "name": "deepslate_tiles"
    },
    {
      "x": 7,
      "y": 8,
      "z": 2,
      "name": "deepslate_tiles"
    },
    {
      "x": 8,
      "y": 8,
      "z": 2,
      "name": "deepslate_tiles"
    },
    {
      "x": 0,
      "y": 8,
      "z": 10,
      "name": "deepslate_tiles"
    },
    {
      "x": 1,
      "y": 8,
      "z": 10,
      "name": "deepslate_tiles"
    },
    {
      "x": 2,
      "y": 8,
      "z": 10,
      "name": "deepslate_tiles"
    },
    {
      "x": 3,
      "y": 8,
      "z": 10,
      "name": "deepslate_tiles"
    },
    {
      "x": 4,
      "y": 8,
      "z": 10,
      "name": "deepslate_tiles"
    },
    {
      "x": 5,
      "y": 8,
      "z": 10,
      "name": "deepslate_tiles"
    },
    {
      "x": 6,
      "y": 8,
      "z": 10,
      "name": "deepslate_tiles"
    },
    {
      "x": 7,
      "y": 8,
      "z": 10,
      "name": "deepslate_tiles"
    },
    {
      "x": 8,
      "y": 8,
      "z": 10,
      "name": "deepslate_tiles"
    },
    {
      "x": 0,
      "y": 9,
      "z": 3,
      "name": "deepslate_tiles"
    },
    {
      "x": 1,
      "y": 9,
      "z": 3,
      "name": "deepslate_tiles"
    },
    {
      "x": 2,
      "y": 9,
      "z": 3,
      "name": "deepslate_tiles"
    },
    {
      "x": 3,
      "y": 9,
      "z": 3,
      "name": "deepslate_tiles"
    },
    {
      "x": 4,
      "y": 9,
      "z": 3,
      "name": "deepslate_tiles"
    },
    {
      "x": 5,
      "y": 9,
      "z": 3,
      "name": "deepslate_tiles"
    },
    {
      "x": 6,
      "y": 9,
      "z": 3,
      "name": "deepslate_tiles"
    },
    {
      "x": 7,
      "y": 9,
      "z": 3,
      "name": "deepslate_tiles"
    },
    {
      "x": 8,
      "y": 9,
      "z": 3,
      "name": "deepslate_tiles"
    },
    {
      "x": 0,
      "y": 9,
      "z": 9,
      "name": "deepslate_tiles"
    },
    {
      "x": 1,
      "y": 9,
      "z": 9,
      "name": "deepslate_tiles"
    },
    {
      "x": 2,
      "y": 9,
      "z": 9,
      "name": "deepslate_tiles"
    },
    {
      "x": 3,
      "y": 9,
      "z": 9,
      "name": "deepslate_tiles"
    },
    {
      "x": 4,
      "y": 9,
      "z": 9,
      "name": "deepslate_tiles"
    },
    {
      "x": 5,
      "y": 9,
      "z": 9,
      "name": "deepslate_tiles"
    },
    {
      "x": 6,
      "y": 9,
      "z": 9,
      "name": "deepslate_tiles"
    },
    {
      "x": 7,
      "y": 9,
      "z": 9,
      "name": "deepslate_tiles"
    },
    {
      "x": 8,
      "y": 9,
      "z": 9,
      "name": "deepslate_tiles"
    },
    {
      "x": 0,
      "y": 10,
      "z": 4,
      "name": "deepslate_tiles"
    },
    {
      "x": 1,
      "y": 10,
      "z": 4,
      "name": "deepslate_tiles"
    },
    {
      "x": 2,
      "y": 10,
      "z": 4,
      "name": "deepslate_tiles"
    },
    {
      "x": 3,
      "y": 10,
      "z": 4,
      "name": "deepslate_tiles"
    },
    {
      "x": 4,
      "y": 10,
      "z": 4,
      "name": "deepslate_tiles"
    },
    {
      "x": 5,
      "y": 10,
      "z": 4,
      "name": "deepslate_tiles"
    },
    {
      "x": 6,
      "y": 10,
      "z": 4,
      "name": "deepslate_tiles"
    },
    {
      "x": 7,
      "y": 10,
      "z": 4,
      "name": "deepslate_tiles"
    },
    {
      "x": 8,
      "y": 10,
      "z": 4,
      "name": "deepslate_tiles"
    },
    {
      "x": 0,
      "y": 10,
      "z": 8,
      "name": "deepslate_tiles"
    },
    {
      "x": 1,
      "y": 10,
      "z": 8,
      "name": "deepslate_tiles"
    },
    {
      "x": 2,
      "y": 10,
      "z": 8,
      "name": "deepslate_tiles"
    },
    {
      "x": 3,
      "y": 10,
      "z": 8,
      "name": "deepslate_tiles"
    },
    {
      "x": 4,
      "y": 10,
      "z": 8,
      "name": "deepslate_tiles"
    },
    {
      "x": 5,
      "y": 10,
      "z": 8,
      "name": "deepslate_tiles"
    },
    {
      "x": 6,
      "y": 10,
      "z": 8,
      "name": "deepslate_tiles"
    },
    {
      "x": 7,
      "y": 10,
      "z": 8,
      "name": "deepslate_tiles"
    },
    {
      "x": 8,
      "y": 10,
      "z": 8,
      "name": "deepslate_tiles"
    },
    {
      "x": 0,
      "y": 11,
      "z": 5,
      "name": "deepslate_tiles"
    },
    {
      "x": 1,
      "y": 11,
      "z": 5,
      "name": "deepslate_tiles"
    },
    {
      "x": 2,
      "y": 11,
      "z": 5,
      "name": "deepslate_tiles"
    },
    {
      "x": 3,
      "y": 11,
      "z": 5,
      "name": "deepslate_tiles"
    },
    {
      "x": 4,
      "y": 11,
      "z": 5,
      "name": "deepslate_tiles"
    },
    {
      "x": 5,
      "y": 11,
      "z": 5,
      "name": "deepslate_tiles"
    },
    {
      "x": 6,
      "y": 11,
      "z": 5,
      "name": "deepslate_tiles"
    },
    {
      "x": 7,
      "y": 11,
      "z": 5,
      "name": "deepslate_tiles"
    },
    {
      "x": 8,
      "y": 11,
      "z": 5,
      "name": "deepslate_tiles"
    },
    {
      "x": 0,
      "y": 11,
      "z": 7,
      "name": "deepslate_tiles"
    },
    {
      "x": 1,
      "y": 11,
      "z": 7,
      "name": "deepslate_tiles"
    },
    {
      "x": 2,
      "y": 11,
      "z": 7,
      "name": "deepslate_tiles"
    },
    {
      "x": 3,
      "y": 11,
      "z": 7,
      "name": "deepslate_tiles"
    },
    {
      "x": 4,
      "y": 11,
      "z": 7,
      "name": "deepslate_tiles"
    },
    {
      "x": 5,
      "y": 11,
      "z": 7,
      "name": "deepslate_tiles"
    },
    {
      "x": 6,
      "y": 11,
      "z": 7,
      "name": "deepslate_tiles"
    },
    {
      "x": 7,
      "y": 11,
      "z": 7,
      "name": "deepslate_tiles"
    },
    {
      "x": 8,
      "y": 11,
      "z": 7,
      "name": "deepslate_tiles"
    },
    {
      "x": 0,
      "y": 12,
      "z": 6,
      "name": "deepslate_tiles"
    },
    {
      "x": 1,
      "y": 12,
      "z": 6,
      "name": "deepslate_tiles"
    },
    {
      "x": 2,
      "y": 12,
      "z": 6,
      "name": "deepslate_tiles"
    },
    {
      "x": 3,
      "y": 12,
      "z": 6,
      "name": "deepslate_tiles"
    },
    {
      "x": 4,
      "y": 12,
      "z": 6,
      "name": "deepslate_tiles"
    },
    {
      "x": 5,
      "y": 12,
      "z": 6,
      "name": "deepslate_tiles"
    },
    {
      "x": 6,
      "y": 12,
      "z": 6,
      "name": "deepslate_tiles"
    },
    {
      "x": 7,
      "y": 12,
      "z": 6,
      "name": "deepslate_tiles"
    },
    {
      "x": 8,
      "y": 12,
      "z": 6,
      "name": "deepslate_tiles"
    }
  ]
}
