{
  "_opis": "Visok srednjeveski strazni stolp z lesenim vrhom.",
  "_category": "medieval",
  "_kind": "building",
  "_aliases": [
    "strazni stolp"
  ],
  "size": [
    7,
    13,
    7
  ],
  "blocks": [
    {
      "x": 0,
      "y": 0,
      "z": 0,
      "name": "stone_bricks"
    },
    {
      "x": 1,
      "y": 0,
      "z": 0,
      "name": "stone_bricks"
    },
    {
      "x": 2,
      "y": 0,
      "z": 0,
      "name": "stone_bricks"
    },
    {
      "x": 3,
      "y": 0,
      "z": 0,
      "name": "stone_bricks"
    },
    {
      "x": 4,
      "y": 0,
      "z": 0,
      "name": "stone_bricks"
    },
    {
      "x": 5,
      "y": 0,
      "z": 0,
      "name": "stone_bricks"
    },
    {
      "x": 6,
      "y": 0,
      "z": 0,
      "name": "stone_bricks"
    },
    {
      "x": 0,
      "y": 0,
      "z": 1,
      "name": "stone_bricks"
    },
    {
      "x": 1,
      "y": 0,
      "z": 1,
      "name": "stone_bricks"
    },
    {
      "x": 2,
      "y": 0,
      "z": 1,
      "name": "stone_bricks"
    },
    {
      "x": 3,
      "y": 0,
      "z": 1,
      "name": "stone_bricks"
    },
    {
      "x": 4,
      "y": 0,
      "z": 1,
      "name": "stone_bricks"
    },
    {
      "x": 5,
      "y": 0,
      "z": 1,
      "name": "stone_bricks"
    },
    {
      "x": 6,
      "y": 0,
      "z": 1,
      "name": "stone_bricks"
    },
    {
      "x": 0,
      "y": 0,
      "z": 2,
      "name": "stone_bricks"
    },
    {
      "x": 1,
      "y": 0,
      "z": 2,
      "name": "stone_bricks"
    },
    {
      "x": 2,
      "y": 0,
      "z": 2,
      "name": "stone_bricks"
    },
    {
      "x": 3,
      "y": 0,
      "z": 2,
      "name": "stone_bricks"
    },
    {
      "x": 4,
      "y": 0,
      "z": 2,
      "name": "stone_bricks"
    },
    {
      "x": 5,
      "y": 0,
      "z": 2,
      "name": "stone_bricks"
    },
    {
      "x": 6,
      "y": 0,
      "z": 2,
      "name": "stone_bricks"
    },
    {
      "x": 0,
      "y": 0,
      "z": 3,
      "name": "stone_bricks"
    },
    {
      "x": 1,
      "y": 0,
      "z": 3,
      "name": "stone_bricks"
    },
    {
      "x": 2,
      "y": 0,
      "z": 3,
      "name": "stone_bricks"
    },
    {
      "x": 3,
      "y": 0,
      "z": 3,
      "name": "stone_bricks"
    },
    {
      "x": 4,
      "y": 0,
      "z": 3,
      "name": "stone_bricks"
    },
    {
      "x": 5,
      "y": 0,
      "z": 3,
      "name": "stone_bricks"
    },
    {
      "x": 6,
      "y": 0,
      "z": 3,
      "name": "stone_bricks"
    },
    {
      "x": 0,
      "y": 0,
      "z": 4,
      "name": "stone_bricks"
    },
    {
      "x": 1,
      "y": 0,
      "z": 4,
      "name": "stone_bricks"
    },
    {
      "x": 2,
      "y": 0,
      "z": 4,
      "name": "stone_bricks"
    },
    {
      "x": 3,
      "y": 0,
      "z": 4,
      "name": "stone_bricks"
    },
    {
      "x": 4,
      "y": 0,
      "z": 4,
      "name": "stone_bricks"
    },
    {
      "x": 5,
      "y": 0,
      "z": 4,
      "name": "stone_bricks"
    },
    {
      "x": 6,
      "y": 0,
      "z": 4,
      "name": "stone_bricks"
    },
    {
      "x": 0,
      "y": 0,
      "z": 5,
      "name": "stone_bricks"
    },
    {
      "x": 1,
      "y": 0,
      "z": 5,
      "name": "stone_bricks"
    },
    {
      "x": 2,
      "y": 0,
      "z": 5,
      "name": "stone_bricks"
    },
    {
      "x": 3,
      "y": 0,
      "z": 5,
      "name": "stone_bricks"
    },
    {
      "x": 4,
      "y": 0,
      "z": 5,
      "name": "stone_bricks"
    },
    {
      "x": 5,
      "y": 0,
      "z": 5,
      "name": "stone_bricks"
    },
    {
      "x": 6,
      "y": 0,
      "z": 5,
      "name": "stone_bricks"
    },
    {
      "x": 0,
      "y": 0,
      "z": 6,
      "name": "stone_bricks"
    },
    {
      "x": 1,
      "y": 0,
      "z": 6,
      "name": "stone_bricks"
    },
    {
      "x": 2,
      "y": 0,
      "z": 6,
      "name": "stone_bricks"
    },
    {
      "x": 3,
      "y": 0,
      "z": 6,
      "name": "stone_bricks"
    },
    {
      "x": 4,
      "y": 0,
      "z": 6,
      "name": "stone_bricks"
    },
    {
      "x": 5,
      "y": 0,
      "z": 6,
      "name": "stone_bricks"
    },
    {
      "x": 6,
      "y": 0,
      "z": 6,
      "name": "stone_bricks"
    },
    {
      "x": 0,
      "y": 1,
      "z": 0,
      "name": "spruce_log"
    },
    {
      "x": 1,
      "y": 1,
      "z": 0,
      "name": "stone_bricks"
    },
    {
      "x": 2,
      "y": 1,
      "z": 0,
      "name": "stone_bricks"
    },
    {
      "x": 3,
      "y": 1,
      "z": 0,
      "name": "spruce_door"
    },
    {
      "x": 4,
      "y": 1,
      "z": 0,
      "name": "stone_bricks"
    },
    {
      "x": 5,
      "y": 1,
      "z": 0,
      "name": "stone_bricks"
    },
    {
      "x": 6,
      "y": 1,
      "z": 0,
      "name": "spruce_log"
    },
    {
      "x": 0,
      "y": 1,
      "z": 1,
      "name": "stone_bricks"
    },
    {
      "x": 6,
      "y": 1,
      "z": 1,
      "name": "stone_bricks"
    },
    {
      "x": 0,
      "y": 1,
      "z": 2,
      "name": "stone_bricks"
    },
    {
      "x": 6,
      "y": 1,
      "z": 2,
      "name": "stone_bricks"
    },
    {
      "x": 0,
      "y": 1,
      "z": 3,
      "name": "stone_bricks"
    },
    {
      "x": 6,
      "y": 1,
      "z": 3,
      "name": "stone_bricks"
    },
    {
      "x": 0,
      "y": 1,
      "z": 4,
      "name": "stone_bricks"
    },
    {
      "x": 6,
      "y": 1,
      "z": 4,
      "name": "stone_bricks"
    },
    {
      "x": 0,
      "y": 1,
      "z": 5,
      "name": "stone_bricks"
    },
    {
      "x": 6,
      "y": 1,
      "z": 5,
      "name": "stone_bricks"
    },
    {
      "x": 0,
      "y": 1,
      "z": 6,
      "name": "spruce_log"
    },
    {
      "x": 1,
      "y": 1,
      "z": 6,
      "name": "stone_bricks"
    },
    {
      "x": 2,
      "y": 1,
      "z": 6,
      "name": "stone_bricks"
    },
    {
      "x": 3,
      "y": 1,
      "z": 6,
      "name": "stone_bricks"
    },
    {
      "x": 4,
      "y": 1,
      "z": 6,
      "name": "stone_bricks"
    },
    {
      "x": 5,
      "y": 1,
      "z": 6,
      "name": "stone_bricks"
    },
    {
      "x": 6,
      "y": 1,
      "z": 6,
      "name": "spruce_log"
    },
    {
      "x": 0,
      "y": 2,
      "z": 0,
      "name": "spruce_log"
    },
    {
      "x": 1,
      "y": 2,
      "z": 0,
      "name": "stone_bricks"
    },
    {
      "x": 2,
      "y": 2,
      "z": 0,
      "name": "stone_bricks"
    },
    {
      "x": 4,
      "y": 2,
      "z": 0,
      "name": "stone_bricks"
    },
    {
      "x": 5,
      "y": 2,
      "z": 0,
      "name": "stone_bricks"
    },
    {
      "x": 6,
      "y": 2,
      "z": 0,
      "name": "spruce_log"
    },
    {
      "x": 0,
      "y": 2,
      "z": 1,
      "name": "stone_bricks"
    },
    {
      "x": 6,
      "y": 2,
      "z": 1,
      "name": "stone_bricks"
    },
    {
      "x": 0,
      "y": 2,
      "z": 2,
      "name": "stone_bricks"
    },
    {
      "x": 6,
      "y": 2,
      "z": 2,
      "name": "stone_bricks"
    },
    {
      "x": 0,
      "y": 2,
      "z": 3,
      "name": "stone_bricks"
    },
    {
      "x": 6,
      "y": 2,
      "z": 3,
      "name": "stone_bricks"
    },
    {
      "x": 0,
      "y": 2,
      "z": 4,
      "name": "stone_bricks"
    },
    {
      "x": 6,
      "y": 2,
      "z": 4,
      "name": "stone_bricks"
    },
    {
      "x": 0,
      "y": 2,
      "z": 5,
      "name": "stone_bricks"
    },
    {
      "x": 6,
      "y": 2,
      "z": 5,
      "name": "stone_bricks"
    },
    {
      "x": 0,
      "y": 2,
      "z": 6,
      "name": "spruce_log"
    },
    {
      "x": 1,
      "y": 2,
      "z": 6,
      "name": "stone_bricks"
    },
    {
      "x": 2,
      "y": 2,
      "z": 6,
      "name": "stone_bricks"
    },
    {
      "x": 3,
      "y": 2,
      "z": 6,
      "name": "stone_bricks"
    },
    {
      "x": 4,
      "y": 2,
      "z": 6,
      "name": "stone_bricks"
    },
    {
      "x": 5,
      "y": 2,
      "z": 6,
      "name": "stone_bricks"
    },
    {
      "x": 6,
      "y": 2,
      "z": 6,
      "name": "spruce_log"
    },
    {
      "x": 0,
      "y": 3,
      "z": 0,
      "name": "spruce_log"
    },
    {
      "x": 1,
      "y": 3,
      "z": 0,
      "name": "stone_bricks"
    },
    {
      "x": 2,
      "y": 3,
      "z": 0,
      "name": "stone_bricks"
    },
    {
      "x": 3,
      "y": 3,
      "z": 0,
      "name": "stone_bricks"
    },
    {
      "x": 4,
      "y": 3,
      "z": 0,
      "name": "stone_bricks"
    },
    {
      "x": 5,
      "y": 3,
      "z": 0,
      "name": "stone_bricks"
    },
    {
      "x": 6,
      "y": 3,
      "z": 0,
      "name": "spruce_log"
    },
    {
      "x": 0,
      "y": 3,
      "z": 1,
      "name": "stone_bricks"
    },
    {
      "x": 6,
      "y": 3,
      "z": 1,
      "name": "stone_bricks"
    },
    {
      "x": 0,
      "y": 3,
      "z": 2,
      "name": "stone_bricks"
    },
    {
      "x": 6,
      "y": 3,
      "z": 2,
      "name": "stone_bricks"
    },
    {
      "x": 0,
      "y": 3,
      "z": 3,
      "name": "stone_bricks"
    },
    {
      "x": 6,
      "y": 3,
      "z": 3,
      "name": "stone_bricks"
    },
    {
      "x": 0,
      "y": 3,
      "z": 4,
      "name": "stone_bricks"
    },
    {
      "x": 6,
      "y": 3,
      "z": 4,
      "name": "stone_bricks"
    },
    {
      "x": 0,
      "y": 3,
      "z": 5,
      "name": "stone_bricks"
    },
    {
      "x": 6,
      "y": 3,
      "z": 5,
      "name": "stone_bricks"
    },
    {
      "x": 0,
      "y": 3,
      "z": 6,
      "name": "spruce_log"
    },
    {
      "x": 1,
      "y": 3,
      "z": 6,
      "name": "stone_bricks"
    },
    {
      "x": 2,
      "y": 3,
      "z": 6,
      "name": "stone_bricks"
    },
    {
      "x": 3,
      "y": 3,
      "z": 6,
      "name": "stone_bricks"
    },
    {
      "x": 4,
      "y": 3,
      "z": 6,
      "name": "stone_bricks"
    },
    {
      "x": 5,
      "y": 3,
      "z": 6,
      "name": "stone_bricks"
    },
    {
      "x": 6,
      "y": 3,
      "z": 6,
      "name": "spruce_log"
    },
    {
      "x": 0,
      "y": 4,
      "z": 0,
      "name": "spruce_log"
    },
    {
      "x": 1,
      "y": 4,
      "z": 0,
      "name": "stone_bricks"
    },
    {
      "x": 2,
      "y": 4,
      "z": 0,
      "name": "stone_bricks"
    },
    {
      "x": 3,
      "y": 4,
      "z": 0,
      "name": "stone_bricks"
    },
    {
      "x": 4,
      "y": 4,
      "z": 0,
      "name": "stone_bricks"
    },
    {
      "x": 5,
      "y": 4,
      "z": 0,
      "name": "stone_bricks"
    },
    {
      "x": 6,
      "y": 4,
      "z": 0,
      "name": "spruce_log"
    },
    {
      "x": 0,
      "y": 4,
      "z": 1,
      "name": "stone_bricks"
    },
    {
      "x": 6,
      "y": 4,
      "z": 1,
      "name": "stone_bricks"
    },
    {
      "x": 0,
      "y": 4,
      "z": 2,
      "name": "stone_bricks"
    },
    {
      "x": 6,
      "y": 4,
      "z": 2,
      "name": "stone_bricks"
    },
    {
      "x": 0,
      "y": 4,
      "z": 3,
      "name": "stone_bricks"
    },
    {
      "x": 6,
      "y": 4,
      "z": 3,
      "name": "stone_bricks"
    },
    {
      "x": 0,
      "y": 4,
      "z": 4,
      "name": "stone_bricks"
    },
    {
      "x": 6,
      "y": 4,
      "z": 4,
      "name": "stone_bricks"
    },
    {
      "x": 0,
      "y": 4,
      "z": 5,
      "name": "stone_bricks"
    },
    {
      "x": 6,
      "y": 4,
      "z": 5,
      "name": "stone_bricks"
    },
    {
      "x": 0,
      "y": 4,
      "z": 6,
      "name": "spruce_log"
    },
    {
      "x": 1,
      "y": 4,
      "z": 6,
      "name": "stone_bricks"
    },
    {
      "x": 2,
      "y": 4,
      "z": 6,
      "name": "stone_bricks"
    },
    {
      "x": 3,
      "y": 4,
      "z": 6,
      "name": "stone_bricks"
    },
    {
      "x": 4,
      "y": 4,
      "z": 6,
      "name": "stone_bricks"
    },
    {
      "x": 5,
      "y": 4,
      "z": 6,
      "name": "stone_bricks"
    },
    {
      "x": 6,
      "y": 4,
      "z": 6,
      "name": "spruce_log"
    },
    {
      "x": 0,
      "y": 5,
      "z": 0,
      "name": "spruce_log"
    },
    {
      "x": 1,
      "y": 5,
      "z": 0,
      "name": "spruce_planks"
    },
    {
      "x": 2,
      "y": 5,
      "z": 0,
      "name": "spruce_planks"
    },
    {
      "x": 3,
      "y": 5,
      "z": 0,
      "name": "spruce_planks"
    },
    {
      "x": 4,
      "y": 5,
      "z": 0,
      "name": "spruce_planks"
    },
    {
      "x": 5,
      "y": 5,
      "z": 0,
      "name": "spruce_planks"
    },
    {
      "x": 6,
      "y": 5,
      "z": 0,
      "name": "spruce_log"
    },
    {
      "x": 0,
      "y": 5,
      "z": 1,
      "name": "spruce_planks"
    },
    {
      "x": 6,
      "y": 5,
      "z": 1,
      "name": "spruce_planks"
    },
    {
      "x": 0,
      "y": 5,
      "z": 2,
      "name": "spruce_planks"
    },
    {
      "x": 6,
      "y": 5,
      "z": 2,
      "name": "spruce_planks"
    },
    {
      "x": 0,
      "y": 5,
      "z": 3,
      "name": "spruce_planks"
    },
    {
      "x": 6,
      "y": 5,
      "z": 3,
      "name": "spruce_planks"
    },
    {
      "x": 0,
      "y": 5,
      "z": 4,
      "name": "spruce_planks"
    },
    {
      "x": 6,
      "y": 5,
      "z": 4,
      "name": "spruce_planks"
    },
    {
      "x": 0,
      "y": 5,
      "z": 5,
      "name": "spruce_planks"
    },
    {
      "x": 6,
      "y": 5,
      "z": 5,
      "name": "spruce_planks"
    },
    {
      "x": 0,
      "y": 5,
      "z": 6,
      "name": "spruce_log"
    },
    {
      "x": 1,
      "y": 5,
      "z": 6,
      "name": "spruce_planks"
    },
    {
      "x": 2,
      "y": 5,
      "z": 6,
      "name": "spruce_planks"
    },
    {
      "x": 3,
      "y": 5,
      "z": 6,
      "name": "spruce_planks"
    },
    {
      "x": 4,
      "y": 5,
      "z": 6,
      "name": "spruce_planks"
    },
    {
      "x": 5,
      "y": 5,
      "z": 6,
      "name": "spruce_planks"
    },
    {
      "x": 6,
      "y": 5,
      "z": 6,
      "name": "spruce_log"
    },
    {
      "x": 0,
      "y": 6,
      "z": 0,
      "name": "spruce_log"
    },
    {
      "x": 1,
      "y": 6,
      "z": 0,
      "name": "spruce_planks"
    },
    {
      "x": 2,
      "y": 6,
      "z": 0,
      "name": "spruce_planks"
    },
    {
      "x": 3,
      "y": 6,
      "z": 0,
      "name": "spruce_planks"
    },
    {
      "x": 4,
      "y": 6,
      "z": 0,
      "name": "spruce_planks"
    },
    {
      "x": 5,
      "y": 6,
      "z": 0,
      "name": "spruce_planks"
    },
    {
      "x": 6,
      "y": 6,
      "z": 0,
      "name": "spruce_log"
    },
    {
      "x": 0,
      "y": 6,
      "z": 1,
      "name": "spruce_planks"
    },
    {
      "x": 6,
      "y": 6,
      "z": 1,
      "name": "spruce_planks"
    },
    {
      "x": 0,
      "y": 6,
      "z": 2,
      "name": "spruce_planks"
    },
    {
      "x": 6,
      "y": 6,
      "z": 2,
      "name": "spruce_planks"
    },
    {
      "x": 0,
      "y": 6,
      "z": 3,
      "name": "glass"
    },
    {
      "x": 6,
      "y": 6,
      "z": 3,
      "name": "glass"
    },
    {
      "x": 0,
      "y": 6,
      "z": 4,
      "name": "spruce_planks"
    },
    {
      "x": 6,
      "y": 6,
      "z": 4,
      "name": "spruce_planks"
    },
    {
      "x": 0,
      "y": 6,
      "z": 5,
      "name": "spruce_planks"
    },
    {
      "x": 6,
      "y": 6,
      "z": 5,
      "name": "spruce_planks"
    },
    {
      "x": 0,
      "y": 6,
      "z": 6,
      "name": "spruce_log"
    },
    {
      "x": 1,
      "y": 6,
      "z": 6,
      "name": "spruce_planks"
    },
    {
      "x": 2,
      "y": 6,
      "z": 6,
      "name": "spruce_planks"
    },
    {
      "x": 3,
      "y": 6,
      "z": 6,
      "name": "glass"
    },
    {
      "x": 4,
      "y": 6,
      "z": 6,
      "name": "spruce_planks"
    },
    {
      "x": 5,
      "y": 6,
      "z": 6,
      "name": "spruce_planks"
    },
    {
      "x": 6,
      "y": 6,
      "z": 6,
      "name": "spruce_log"
    },
    {
      "x": 0,
      "y": 7,
      "z": 0,
      "name": "spruce_log"
    },
    {
      "x": 1,
      "y": 7,
      "z": 0,
      "name": "spruce_planks"
    },
    {
      "x": 2,
      "y": 7,
      "z": 0,
      "name": "spruce_planks"
    },
    {
      "x": 3,
      "y": 7,
      "z": 0,
      "name": "spruce_planks"
    },
    {
      "x": 4,
      "y": 7,
      "z": 0,
      "name": "spruce_planks"
    },
    {
      "x": 5,
      "y": 7,
      "z": 0,
      "name": "spruce_planks"
    },
    {
      "x": 6,
      "y": 7,
      "z": 0,
      "name": "spruce_log"
    },
    {
      "x": 0,
      "y": 7,
      "z": 1,
      "name": "spruce_planks"
    },
    {
      "x": 6,
      "y": 7,
      "z": 1,
      "name": "spruce_planks"
    },
    {
      "x": 0,
      "y": 7,
      "z": 2,
      "name": "spruce_planks"
    },
    {
      "x": 6,
      "y": 7,
      "z": 2,
      "name": "spruce_planks"
    },
    {
      "x": 0,
      "y": 7,
      "z": 3,
      "name": "spruce_planks"
    },
    {
      "x": 6,
      "y": 7,
      "z": 3,
      "name": "spruce_planks"
    },
    {
      "x": 0,
      "y": 7,
      "z": 4,
      "name": "spruce_planks"
    },
    {
      "x": 6,
      "y": 7,
      "z": 4,
      "name": "spruce_planks"
    },
    {
      "x": 0,
      "y": 7,
      "z": 5,
      "name": "spruce_planks"
    },
    {
      "x": 6,
      "y": 7,
      "z": 5,
      "name": "spruce_planks"
    },
    {
      "x": 0,
      "y": 7,
      "z": 6,
      "name": "spruce_log"
    },
    {
      "x": 1,
      "y": 7,
      "z": 6,
      "name": "spruce_planks"
    },
    {
      "x": 2,
      "y": 7,
      "z": 6,
      "name": "spruce_planks"
    },
    {
      "x": 3,
      "y": 7,
      "z": 6,
      "name": "spruce_planks"
    },
    {
      "x": 4,
      "y": 7,
      "z": 6,
      "name": "spruce_planks"
    },
    {
      "x": 5,
      "y": 7,
      "z": 6,
      "name": "spruce_planks"
    },
    {
      "x": 6,
      "y": 7,
      "z": 6,
      "name": "spruce_log"
    },
    {
      "x": 0,
      "y": 8,
      "z": 0,
      "name": "spruce_log"
    },
    {
      "x": 1,
      "y": 8,
      "z": 0,
      "name": "spruce_planks"
    },
    {
      "x": 2,
      "y": 8,
      "z": 0,
      "name": "spruce_planks"
    },
    {
      "x": 3,
      "y": 8,
      "z": 0,
      "name": "spruce_planks"
    },
    {
      "x": 4,
      "y": 8,
      "z": 0,
      "name": "spruce_planks"
    },
    {
      "x": 5,
      "y": 8,
      "z": 0,
      "name": "spruce_planks"
    },
    {
      "x": 6,
      "y": 8,
      "z": 0,
      "name": "spruce_log"
    },
    {
      "x": 0,
      "y": 8,
      "z": 1,
      "name": "spruce_planks"
    },
    {
      "x": 6,
      "y": 8,
      "z": 1,
      "name": "spruce_planks"
    },
    {
      "x": 0,
      "y": 8,
      "z": 2,
      "name": "spruce_planks"
    },
    {
      "x": 6,
      "y": 8,
      "z": 2,
      "name": "spruce_planks"
    },
    {
      "x": 0,
      "y": 8,
      "z": 3,
      "name": "spruce_planks"
    },
    {
      "x": 6,
      "y": 8,
      "z": 3,
      "name": "spruce_planks"
    },
    {
      "x": 0,
      "y": 8,
      "z": 4,
      "name": "spruce_planks"
    },
    {
      "x": 6,
      "y": 8,
      "z": 4,
      "name": "spruce_planks"
    },
    {
      "x": 0,
      "y": 8,
      "z": 5,
      "name": "spruce_planks"
    },
    {
      "x": 6,
      "y": 8,
      "z": 5,
      "name": "spruce_planks"
    },
    {
      "x": 0,
      "y": 8,
      "z": 6,
      "name": "spruce_log"
    },
    {
      "x": 1,
      "y": 8,
      "z": 6,
      "name": "spruce_planks"
    },
    {
      "x": 2,
      "y": 8,
      "z": 6,
      "name": "spruce_planks"
    },
    {
      "x": 3,
      "y": 8,
      "z": 6,
      "name": "spruce_planks"
    },
    {
      "x": 4,
      "y": 8,
      "z": 6,
      "name": "spruce_planks"
    },
    {
      "x": 5,
      "y": 8,
      "z": 6,
      "name": "spruce_planks"
    },
    {
      "x": 6,
      "y": 8,
      "z": 6,
      "name": "spruce_log"
    },
    {
      "x": 0,
      "y": 9,
      "z": 0,
      "name": "dark_oak_planks"
    },
    {
      "x": 1,
      "y": 9,
      "z": 0,
      "name": "dark_oak_planks"
    },
    {
      "x": 2,
      "y": 9,
      "z": 0,
      "name": "dark_oak_planks"
    },
    {
      "x": 3,
      "y": 9,
      "z": 0,
      "name": "dark_oak_planks"
    },
    {
      "x": 4,
      "y": 9,
      "z": 0,
      "name": "dark_oak_planks"
    },
    {
      "x": 5,
      "y": 9,
      "z": 0,
      "name": "dark_oak_planks"
    },
    {
      "x": 6,
      "y": 9,
      "z": 0,
      "name": "dark_oak_planks"
    },
    {
      "x": 0,
      "y": 9,
      "z": 1,
      "name": "dark_oak_planks"
    },
    {
      "x": 1,
      "y": 9,
      "z": 1,
      "name": "dark_oak_planks"
    },
    {
      "x": 2,
      "y": 9,
      "z": 1,
      "name": "dark_oak_planks"
    },
    {
      "x": 3,
      "y": 9,
      "z": 1,
      "name": "dark_oak_planks"
    },
    {
      "x": 4,
      "y": 9,
      "z": 1,
      "name": "dark_oak_planks"
    },
    {
      "x": 5,
      "y": 9,
      "z": 1,
      "name": "dark_oak_planks"
    },
    {
      "x": 6,
      "y": 9,
      "z": 1,
      "name": "dark_oak_planks"
    },
    {
      "x": 0,
      "y": 9,
      "z": 2,
      "name": "dark_oak_planks"
    },
    {
      "x": 1,
      "y": 9,
      "z": 2,
      "name": "dark_oak_planks"
    },
    {
      "x": 2,
      "y": 9,
      "z": 2,
      "name": "dark_oak_planks"
    },
    {
      "x": 3,
      "y": 9,
      "z": 2,
      "name": "dark_oak_planks"
    },
    {
      "x": 4,
      "y": 9,
      "z": 2,
      "name": "dark_oak_planks"
    },
    {
      "x": 5,
      "y": 9,
      "z": 2,
      "name": "dark_oak_planks"
    },
    {
      "x": 6,
      "y": 9,
      "z": 2,
      "name": "dark_oak_planks"
    },
    {
      "x": 0,
      "y": 9,
      "z": 3,
      "name": "dark_oak_planks"
    },
    {
      "x": 1,
      "y": 9,
      "z": 3,
      "name": "dark_oak_planks"
    },
    {
      "x": 2,
      "y": 9,
      "z": 3,
      "name": "dark_oak_planks"
    },
    {
      "x": 3,
      "y": 9,
      "z": 3,
      "name": "dark_oak_planks"
    },
    {
      "x": 4,
      "y": 9,
      "z": 3,
      "name": "dark_oak_planks"
    },
    {
      "x": 5,
      "y": 9,
      "z": 3,
      "name": "dark_oak_planks"
    },
    {
      "x": 6,
      "y": 9,
      "z": 3,
      "name": "dark_oak_planks"
    },
    {
      "x": 0,
      "y": 9,
      "z": 4,
      "name": "dark_oak_planks"
    },
    {
      "x": 1,
      "y": 9,
      "z": 4,
      "name": "dark_oak_planks"
    },
    {
      "x": 2,
      "y": 9,
      "z": 4,
      "name": "dark_oak_planks"
    },
    {
      "x": 3,
      "y": 9,
      "z": 4,
      "name": "dark_oak_planks"
    },
    {
      "x": 4,
      "y": 9,
      "z": 4,
      "name": "dark_oak_planks"
    },
    {
      "x": 5,
      "y": 9,
      "z": 4,
      "name": "dark_oak_planks"
    },
    {
      "x": 6,
      "y": 9,
      "z": 4,
      "name": "dark_oak_planks"
    },
    {
      "x": 0,
      "y": 9,
      "z": 5,
      "name": "dark_oak_planks"
    },
    {
      "x": 1,
      "y": 9,
      "z": 5,
      "name": "dark_oak_planks"
    },
    {
      "x": 2,
      "y": 9,
      "z": 5,
      "name": "dark_oak_planks"
    },
    {
      "x": 3,
      "y": 9,
      "z": 5,
      "name": "dark_oak_planks"
    },
    {
      "x": 4,
      "y": 9,
      "z": 5,
      "name": "dark_oak_planks"
    },
    {
      "x": 5,
      "y": 9,
      "z": 5,
      "name": "dark_oak_planks"
    },
    {
      "x": 6,
      "y": 9,
      "z": 5,
      "name": "dark_oak_planks"
    },
    {
      "x": 0,
      "y": 9,
      "z": 6,
      "name": "dark_oak_planks"
    },
    {
      "x": 1,
      "y": 9,
      "z": 6,
      "name": "dark_oak_planks"
    },
    {
      "x": 2,
      "y": 9,
      "z": 6,
      "name": "dark_oak_planks"
    },
    {
      "x": 3,
      "y": 9,
      "z": 6,
      "name": "dark_oak_planks"
    },
    {
      "x": 4,
      "y": 9,
      "z": 6,
      "name": "dark_oak_planks"
    },
    {
      "x": 5,
      "y": 9,
      "z": 6,
      "name": "dark_oak_planks"
    },
    {
      "x": 6,
      "y": 9,
      "z": 6,
      "name": "dark_oak_planks"
    },
    {
      "x": 0,
      "y": 10,
      "z": 0,
      "name": "stone_bricks"
    },
    {
      "x": 1,
      "y": 10,
      "z": 0,
      "name": "stone_bricks"
    },
    {
      "x": 2,
      "y": 10,
      "z": 0,
      "name": "stone_bricks"
    },
    {
      "x": 3,
      "y": 10,
      "z": 0,
      "name": "stone_bricks"
    },
    {
      "x": 4,
      "y": 10,
      "z": 0,
      "name": "stone_bricks"
    },
    {
      "x": 5,
      "y": 10,
      "z": 0,
      "name": "stone_bricks"
    },
    {
      "x": 6,
      "y": 10,
      "z": 0,
      "name": "stone_bricks"
    },
    {
      "x": 0,
      "y": 10,
      "z": 1,
      "name": "stone_bricks"
    },
    {
      "x": 6,
      "y": 10,
      "z": 1,
      "name": "stone_bricks"
    },
    {
      "x": 0,
      "y": 10,
      "z": 2,
      "name": "stone_bricks"
    },
    {
      "x": 6,
      "y": 10,
      "z": 2,
      "name": "stone_bricks"
    },
    {
      "x": 0,
      "y": 10,
      "z": 3,
      "name": "stone_bricks"
    },
    {
      "x": 6,
      "y": 10,
      "z": 3,
      "name": "stone_bricks"
    },
    {
      "x": 0,
      "y": 10,
      "z": 4,
      "name": "stone_bricks"
    },
    {
      "x": 6,
      "y": 10,
      "z": 4,
      "name": "stone_bricks"
    },
    {
      "x": 0,
      "y": 10,
      "z": 5,
      "name": "stone_bricks"
    },
    {
      "x": 6,
      "y": 10,
      "z": 5,
      "name": "stone_bricks"
    },
    {
      "x": 0,
      "y": 10,
      "z": 6,
      "name": "stone_bricks"
    },
    {
      "x": 1,
      "y": 10,
      "z": 6,
      "name": "stone_bricks"
    },
    {
      "x": 2,
      "y": 10,
      "z": 6,
      "name": "stone_bricks"
    },
    {
      "x": 3,
      "y": 10,
      "z": 6,
      "name": "stone_bricks"
    },
    {
      "x": 4,
      "y": 10,
      "z": 6,
      "name": "stone_bricks"
    },
    {
      "x": 5,
      "y": 10,
      "z": 6,
      "name": "stone_bricks"
    },
    {
      "x": 6,
      "y": 10,
      "z": 6,
      "name": "stone_bricks"
    },
    {
      "x": 0,
      "y": 11,
      "z": 0,
      "name": "stone_bricks"
    },
    {
      "x": 2,
      "y": 11,
      "z": 0,
      "name": "stone_bricks"
    },
    {
      "x": 4,
      "y": 11,
      "z": 0,
      "name": "stone_bricks"
    },
    {
      "x": 6,
      "y": 11,
      "z": 0,
      "name": "stone_bricks"
    },
    {
      "x": 0,
      "y": 11,
      "z": 2,
      "name": "stone_bricks"
    },
    {
      "x": 6,
      "y": 11,
      "z": 2,
      "name": "stone_bricks"
    },
    {
      "x": 0,
      "y": 11,
      "z": 4,
      "name": "stone_bricks"
    },
    {
      "x": 6,
      "y": 11,
      "z": 4,
      "name": "stone_bricks"
    },
    {
      "x": 0,
      "y": 11,
      "z": 6,
      "name": "stone_bricks"
    },
    {
      "x": 2,
      "y": 11,
      "z": 6,
      "name": "stone_bricks"
    },
    {
      "x": 4,
      "y": 11,
      "z": 6,
      "name": "stone_bricks"
    },
    {
      "x": 6,
      "y": 11,
      "z": 6,
      "name": "stone_bricks"
    }
  ]
}
