{
  "_opis": "Masivna srednjeveska mestna vrata z dvema straznima stolpoma.",
  "_category": "medieval",
  "_kind": "building",
  "_aliases": [
    "mestna vrata",
    "gatehouse",
    "grajska vrata"
  ],
  "size": [
    15,
    12,
    7
  ],
  "blocks": [
    {
      "x": 0,
      "y": 0,
      "z": 0,
      "name": "stone_bricks"
    },
    {
      "x": 1,
      "y": 0,
      "z": 0,
      "name": "stone_bricks"
    },
    {
      "x": 2,
      "y": 0,
      "z": 0,
      "name": "stone_bricks"
    },
    {
      "x": 3,
      "y": 0,
      "z": 0,
      "name": "stone_bricks"
    },
    {
      "x": 4,
      "y": 0,
      "z": 0,
      "name": "stone_bricks"
    },
    {
      "x": 5,
      "y": 0,
      "z": 0,
      "name": "stone_bricks"
    },
    {
      "x": 6,
      "y": 0,
      "z": 0,
      "name": "stone_bricks"
    },
    {
      "x": 7,
      "y": 0,
      "z": 0,
      "name": "stone_bricks"
    },
    {
      "x": 8,
      "y": 0,
      "z": 0,
      "name": "stone_bricks"
    },
    {
      "x": 9,
      "y": 0,
      "z": 0,
      "name": "stone_bricks"
    },
    {
      "x": 10,
      "y": 0,
      "z": 0,
      "name": "stone_bricks"
    },
    {
      "x": 11,
      "y": 0,
      "z": 0,
      "name": "stone_bricks"
    },
    {
      "x": 12,
      "y": 0,
      "z": 0,
      "name": "stone_bricks"
    },
    {
      "x": 13,
      "y": 0,
      "z": 0,
      "name": "stone_bricks"
    },
    {
      "x": 14,
      "y": 0,
      "z": 0,
      "name": "stone_bricks"
    },
    {
      "x": 0,
      "y": 0,
      "z": 1,
      "name": "stone_bricks"
    },
    {
      "x": 1,
      "y": 0,
      "z": 1,
      "name": "stone_bricks"
    },
    {
      "x": 2,
      "y": 0,
      "z": 1,
      "name": "stone_bricks"
    },
    {
      "x": 3,
      "y": 0,
      "z": 1,
      "name": "stone_bricks"
    },
    {
      "x": 4,
      "y": 0,
      "z": 1,
      "name": "stone_bricks"
    },
    {
      "x": 5,
      "y": 0,
      "z": 1,
      "name": "stone_bricks"
    },
    {
      "x": 6,
      "y": 0,
      "z": 1,
      "name": "stone_bricks"
    },
    {
      "x": 7,
      "y": 0,
      "z": 1,
      "name": "stone_bricks"
    },
    {
      "x": 8,
      "y": 0,
      "z": 1,
      "name": "stone_bricks"
    },
    {
      "x": 9,
      "y": 0,
      "z": 1,
      "name": "stone_bricks"
    },
    {
      "x": 10,
      "y": 0,
      "z": 1,
      "name": "stone_bricks"
    },
    {
      "x": 11,
      "y": 0,
      "z": 1,
      "name": "stone_bricks"
    },
    {
      "x": 12,
      "y": 0,
      "z": 1,
      "name": "stone_bricks"
    },
    {
      "x": 13,
      "y": 0,
      "z": 1,
      "name": "stone_bricks"
    },
    {
      "x": 14,
      "y": 0,
      "z": 1,
      "name": "stone_bricks"
    },
    {
      "x": 0,
      "y": 0,
      "z": 2,
      "name": "stone_bricks"
    },
    {
      "x": 1,
      "y": 0,
      "z": 2,
      "name": "stone_bricks"
    },
    {
      "x": 2,
      "y": 0,
      "z": 2,
      "name": "stone_bricks"
    },
    {
      "x": 3,
      "y": 0,
      "z": 2,
      "name": "stone_bricks"
    },
    {
      "x": 4,
      "y": 0,
      "z": 2,
      "name": "stone_bricks"
    },
    {
      "x": 5,
      "y": 0,
      "z": 2,
      "name": "stone_bricks"
    },
    {
      "x": 6,
      "y": 0,
      "z": 2,
      "name": "stone_bricks"
    },
    {
      "x": 7,
      "y": 0,
      "z": 2,
      "name": "stone_bricks"
    },
    {
      "x": 8,
      "y": 0,
      "z": 2,
      "name": "stone_bricks"
    },
    {
      "x": 9,
      "y": 0,
      "z": 2,
      "name": "stone_bricks"
    },
    {
      "x": 10,
      "y": 0,
      "z": 2,
      "name": "stone_bricks"
    },
    {
      "x": 11,
      "y": 0,
      "z": 2,
      "name": "stone_bricks"
    },
    {
      "x": 12,
      "y": 0,
      "z": 2,
      "name": "stone_bricks"
    },
    {
      "x": 13,
      "y": 0,
      "z": 2,
      "name": "stone_bricks"
    },
    {
      "x": 14,
      "y": 0,
      "z": 2,
      "name": "stone_bricks"
    },
    {
      "x": 0,
      "y": 0,
      "z": 3,
      "name": "stone_bricks"
    },
    {
      "x": 1,
      "y": 0,
      "z": 3,
      "name": "stone_bricks"
    },
    {
      "x": 2,
      "y": 0,
      "z": 3,
      "name": "stone_bricks"
    },
    {
      "x": 3,
      "y": 0,
      "z": 3,
      "name": "stone_bricks"
    },
    {
      "x": 4,
      "y": 0,
      "z": 3,
      "name": "stone_bricks"
    },
    {
      "x": 5,
      "y": 0,
      "z": 3,
      "name": "stone_bricks"
    },
    {
      "x": 6,
      "y": 0,
      "z": 3,
      "name": "stone_bricks"
    },
    {
      "x": 7,
      "y": 0,
      "z": 3,
      "name": "stone_bricks"
    },
    {
      "x": 8,
      "y": 0,
      "z": 3,
      "name": "stone_bricks"
    },
    {
      "x": 9,
      "y": 0,
      "z": 3,
      "name": "stone_bricks"
    },
    {
      "x": 10,
      "y": 0,
      "z": 3,
      "name": "stone_bricks"
    },
    {
      "x": 11,
      "y": 0,
      "z": 3,
      "name": "stone_bricks"
    },
    {
      "x": 12,
      "y": 0,
      "z": 3,
      "name": "stone_bricks"
    },
    {
      "x": 13,
      "y": 0,
      "z": 3,
      "name": "stone_bricks"
    },
    {
      "x": 14,
      "y": 0,
      "z": 3,
      "name": "stone_bricks"
    },
    {
      "x": 0,
      "y": 0,
      "z": 4,
      "name": "stone_bricks"
    },
    {
      "x": 1,
      "y": 0,
      "z": 4,
      "name": "stone_bricks"
    },
    {
      "x": 2,
      "y": 0,
      "z": 4,
      "name": "stone_bricks"
    },
    {
      "x": 3,
      "y": 0,
      "z": 4,
      "name": "stone_bricks"
    },
    {
      "x": 4,
      "y": 0,
      "z": 4,
      "name": "stone_bricks"
    },
    {
      "x": 5,
      "y": 0,
      "z": 4,
      "name": "stone_bricks"
    },
    {
      "x": 6,
      "y": 0,
      "z": 4,
      "name": "stone_bricks"
    },
    {
      "x": 7,
      "y": 0,
      "z": 4,
      "name": "stone_bricks"
    },
    {
      "x": 8,
      "y": 0,
      "z": 4,
      "name": "stone_bricks"
    },
    {
      "x": 9,
      "y": 0,
      "z": 4,
      "name": "stone_bricks"
    },
    {
      "x": 10,
      "y": 0,
      "z": 4,
      "name": "stone_bricks"
    },
    {
      "x": 11,
      "y": 0,
      "z": 4,
      "name": "stone_bricks"
    },
    {
      "x": 12,
      "y": 0,
      "z": 4,
      "name": "stone_bricks"
    },
    {
      "x": 13,
      "y": 0,
      "z": 4,
      "name": "stone_bricks"
    },
    {
      "x": 14,
      "y": 0,
      "z": 4,
      "name": "stone_bricks"
    },
    {
      "x": 0,
      "y": 0,
      "z": 5,
      "name": "stone_bricks"
    },
    {
      "x": 1,
      "y": 0,
      "z": 5,
      "name": "stone_bricks"
    },
    {
      "x": 2,
      "y": 0,
      "z": 5,
      "name": "stone_bricks"
    },
    {
      "x": 3,
      "y": 0,
      "z": 5,
      "name": "stone_bricks"
    },
    {
      "x": 4,
      "y": 0,
      "z": 5,
      "name": "stone_bricks"
    },
    {
      "x": 5,
      "y": 0,
      "z": 5,
      "name": "stone_bricks"
    },
    {
      "x": 6,
      "y": 0,
      "z": 5,
      "name": "stone_bricks"
    },
    {
      "x": 7,
      "y": 0,
      "z": 5,
      "name": "stone_bricks"
    },
    {
      "x": 8,
      "y": 0,
      "z": 5,
      "name": "stone_bricks"
    },
    {
      "x": 9,
      "y": 0,
      "z": 5,
      "name": "stone_bricks"
    },
    {
      "x": 10,
      "y": 0,
      "z": 5,
      "name": "stone_bricks"
    },
    {
      "x": 11,
      "y": 0,
      "z": 5,
      "name": "stone_bricks"
    },
    {
      "x": 12,
      "y": 0,
      "z": 5,
      "name": "stone_bricks"
    },
    {
      "x": 13,
      "y": 0,
      "z": 5,
      "name": "stone_bricks"
    },
    {
      "x": 14,
      "y": 0,
      "z": 5,
      "name": "stone_bricks"
    },
    {
      "x": 0,
      "y": 0,
      "z": 6,
      "name": "stone_bricks"
    },
    {
      "x": 1,
      "y": 0,
      "z": 6,
      "name": "stone_bricks"
    },
    {
      "x": 2,
      "y": 0,
      "z": 6,
      "name": "stone_bricks"
    },
    {
      "x": 3,
      "y": 0,
      "z": 6,
      "name": "stone_bricks"
    },
    {
      "x": 4,
      "y": 0,
      "z": 6,
      "name": "stone_bricks"
    },
    {
      "x": 5,
      "y": 0,
      "z": 6,
      "name": "stone_bricks"
    },
    {
      "x": 6,
      "y": 0,
      "z": 6,
      "name": "stone_bricks"
    },
    {
      "x": 7,
      "y": 0,
      "z": 6,
      "name": "stone_bricks"
    },
    {
      "x": 8,
      "y": 0,
      "z": 6,
      "name": "stone_bricks"
    },
    {
      "x": 9,
      "y": 0,
      "z": 6,
      "name": "stone_bricks"
    },
    {
      "x": 10,
      "y": 0,
      "z": 6,
      "name": "stone_bricks"
    },
    {
      "x": 11,
      "y": 0,
      "z": 6,
      "name": "stone_bricks"
    },
    {
      "x": 12,
      "y": 0,
      "z": 6,
      "name": "stone_bricks"
    },
    {
      "x": 13,
      "y": 0,
      "z": 6,
      "name": "stone_bricks"
    },
    {
      "x": 14,
      "y": 0,
      "z": 6,
      "name": "stone_bricks"
    },
    {
      "x": 0,
      "y": 1,
      "z": 0,
      "name": "cobblestone"
    },
    {
      "x": 1,
      "y": 1,
      "z": 0,
      "name": "cobblestone"
    },
    {
      "x": 2,
      "y": 1,
      "z": 0,
      "name": "cobblestone"
    },
    {
      "x": 3,
      "y": 1,
      "z": 0,
      "name": "cobblestone"
    },
    {
      "x": 4,
      "y": 1,
      "z": 0,
      "name": "cobblestone"
    },
    {
      "x": 10,
      "y": 1,
      "z": 0,
      "name": "cobblestone"
    },
    {
      "x": 11,
      "y": 1,
      "z": 0,
      "name": "cobblestone"
    },
    {
      "x": 12,
      "y": 1,
      "z": 0,
      "name": "cobblestone"
    },
    {
      "x": 13,
      "y": 1,
      "z": 0,
      "name": "cobblestone"
    },
    {
      "x": 14,
      "y": 1,
      "z": 0,
      "name": "cobblestone"
    },
    {
      "x": 0,
      "y": 1,
      "z": 1,
      "name": "cobblestone"
    },
    {
      "x": 4,
      "y": 1,
      "z": 1,
      "name": "cobblestone"
    },
    {
      "x": 10,
      "y": 1,
      "z": 1,
      "name": "cobblestone"
    },
    {
      "x": 14,
      "y": 1,
      "z": 1,
      "name": "cobblestone"
    },
    {
      "x": 0,
      "y": 1,
      "z": 2,
      "name": "cobblestone"
    },
    {
      "x": 4,
      "y": 1,
      "z": 2,
      "name": "cobblestone"
    },
    {
      "x": 6,
      "y": 1,
      "z": 2,
      "name": "iron_bars"
    },
    {
      "x": 7,
      "y": 1,
      "z": 2,
      "name": "iron_bars"
    },
    {
      "x": 8,
      "y": 1,
      "z": 2,
      "name": "iron_bars"
    },
    {
      "x": 10,
      "y": 1,
      "z": 2,
      "name": "cobblestone"
    },
    {
      "x": 14,
      "y": 1,
      "z": 2,
      "name": "cobblestone"
    },
    {
      "x": 0,
      "y": 1,
      "z": 3,
      "name": "cobblestone"
    },
    {
      "x": 4,
      "y": 1,
      "z": 3,
      "name": "cobblestone"
    },
    {
      "x": 10,
      "y": 1,
      "z": 3,
      "name": "cobblestone"
    },
    {
      "x": 14,
      "y": 1,
      "z": 3,
      "name": "cobblestone"
    },
    {
      "x": 0,
      "y": 1,
      "z": 4,
      "name": "cobblestone"
    },
    {
      "x": 4,
      "y": 1,
      "z": 4,
      "name": "cobblestone"
    },
    {
      "x": 10,
      "y": 1,
      "z": 4,
      "name": "cobblestone"
    },
    {
      "x": 14,
      "y": 1,
      "z": 4,
      "name": "cobblestone"
    },
    {
      "x": 0,
      "y": 1,
      "z": 5,
      "name": "cobblestone"
    },
    {
      "x": 4,
      "y": 1,
      "z": 5,
      "name": "cobblestone"
    },
    {
      "x": 10,
      "y": 1,
      "z": 5,
      "name": "cobblestone"
    },
    {
      "x": 14,
      "y": 1,
      "z": 5,
      "name": "cobblestone"
    },
    {
      "x": 0,
      "y": 1,
      "z": 6,
      "name": "cobblestone"
    },
    {
      "x": 1,
      "y": 1,
      "z": 6,
      "name": "cobblestone"
    },
    {
      "x": 2,
      "y": 1,
      "z": 6,
      "name": "cobblestone"
    },
    {
      "x": 3,
      "y": 1,
      "z": 6,
      "name": "cobblestone"
    },
    {
      "x": 4,
      "y": 1,
      "z": 6,
      "name": "cobblestone"
    },
    {
      "x": 10,
      "y": 1,
      "z": 6,
      "name": "cobblestone"
    },
    {
      "x": 11,
      "y": 1,
      "z": 6,
      "name": "cobblestone"
    },
    {
      "x": 12,
      "y": 1,
      "z": 6,
      "name": "cobblestone"
    },
    {
      "x": 13,
      "y": 1,
      "z": 6,
      "name": "cobblestone"
    },
    {
      "x": 14,
      "y": 1,
      "z": 6,
      "name": "cobblestone"
    },
    {
      "x": 0,
      "y": 2,
      "z": 0,
      "name": "cobblestone"
    },
    {
      "x": 1,
      "y": 2,
      "z": 0,
      "name": "cobblestone"
    },
    {
      "x": 2,
      "y": 2,
      "z": 0,
      "name": "cobblestone"
    },
    {
      "x": 3,
      "y": 2,
      "z": 0,
      "name": "cobblestone"
    },
    {
      "x": 4,
      "y": 2,
      "z": 0,
      "name": "cobblestone"
    },
    {
      "x": 10,
      "y": 2,
      "z": 0,
      "name": "cobblestone"
    },
    {
      "x": 11,
      "y": 2,
      "z": 0,
      "name": "cobblestone"
    },
    {
      "x": 12,
      "y": 2,
      "z": 0,
      "name": "cobblestone"
    },
    {
      "x": 13,
      "y": 2,
      "z": 0,
      "name": "cobblestone"
    },
    {
      "x": 14,
      "y": 2,
      "z": 0,
      "name": "cobblestone"
    },
    {
      "x": 0,
      "y": 2,
      "z": 1,
      "name": "cobblestone"
    },
    {
      "x": 4,
      "y": 2,
      "z": 1,
      "name": "cobblestone"
    },
    {
      "x": 10,
      "y": 2,
      "z": 1,
      "name": "cobblestone"
    },
    {
      "x": 14,
      "y": 2,
      "z": 1,
      "name": "cobblestone"
    },
    {
      "x": 0,
      "y": 2,
      "z": 2,
      "name": "cobblestone"
    },
    {
      "x": 4,
      "y": 2,
      "z": 2,
      "name": "cobblestone"
    },
    {
      "x": 6,
      "y": 2,
      "z": 2,
      "name": "iron_bars"
    },
    {
      "x": 7,
      "y": 2,
      "z": 2,
      "name": "iron_bars"
    },
    {
      "x": 8,
      "y": 2,
      "z": 2,
      "name": "iron_bars"
    },
    {
      "x": 10,
      "y": 2,
      "z": 2,
      "name": "cobblestone"
    },
    {
      "x": 14,
      "y": 2,
      "z": 2,
      "name": "cobblestone"
    },
    {
      "x": 0,
      "y": 2,
      "z": 3,
      "name": "cobblestone"
    },
    {
      "x": 4,
      "y": 2,
      "z": 3,
      "name": "cobblestone"
    },
    {
      "x": 10,
      "y": 2,
      "z": 3,
      "name": "cobblestone"
    },
    {
      "x": 14,
      "y": 2,
      "z": 3,
      "name": "cobblestone"
    },
    {
      "x": 0,
      "y": 2,
      "z": 4,
      "name": "cobblestone"
    },
    {
      "x": 4,
      "y": 2,
      "z": 4,
      "name": "cobblestone"
    },
    {
      "x": 10,
      "y": 2,
      "z": 4,
      "name": "cobblestone"
    },
    {
      "x": 14,
      "y": 2,
      "z": 4,
      "name": "cobblestone"
    },
    {
      "x": 0,
      "y": 2,
      "z": 5,
      "name": "cobblestone"
    },
    {
      "x": 4,
      "y": 2,
      "z": 5,
      "name": "cobblestone"
    },
    {
      "x": 10,
      "y": 2,
      "z": 5,
      "name": "cobblestone"
    },
    {
      "x": 14,
      "y": 2,
      "z": 5,
      "name": "cobblestone"
    },
    {
      "x": 0,
      "y": 2,
      "z": 6,
      "name": "cobblestone"
    },
    {
      "x": 1,
      "y": 2,
      "z": 6,
      "name": "cobblestone"
    },
    {
      "x": 2,
      "y": 2,
      "z": 6,
      "name": "cobblestone"
    },
    {
      "x": 3,
      "y": 2,
      "z": 6,
      "name": "cobblestone"
    },
    {
      "x": 4,
      "y": 2,
      "z": 6,
      "name": "cobblestone"
    },
    {
      "x": 10,
      "y": 2,
      "z": 6,
      "name": "cobblestone"
    },
    {
      "x": 11,
      "y": 2,
      "z": 6,
      "name": "cobblestone"
    },
    {
      "x": 12,
      "y": 2,
      "z": 6,
      "name": "cobblestone"
    },
    {
      "x": 13,
      "y": 2,
      "z": 6,
      "name": "cobblestone"
    },
    {
      "x": 14,
      "y": 2,
      "z": 6,
      "name": "cobblestone"
    },
    {
      "x": 0,
      "y": 3,
      "z": 0,
      "name": "cobblestone"
    },
    {
      "x": 1,
      "y": 3,
      "z": 0,
      "name": "cobblestone"
    },
    {
      "x": 2,
      "y": 3,
      "z": 0,
      "name": "cobblestone"
    },
    {
      "x": 3,
      "y": 3,
      "z": 0,
      "name": "cobblestone"
    },
    {
      "x": 4,
      "y": 3,
      "z": 0,
      "name": "cobblestone"
    },
    {
      "x": 10,
      "y": 3,
      "z": 0,
      "name": "cobblestone"
    },
    {
      "x": 11,
      "y": 3,
      "z": 0,
      "name": "cobblestone"
    },
    {
      "x": 12,
      "y": 3,
      "z": 0,
      "name": "cobblestone"
    },
    {
      "x": 13,
      "y": 3,
      "z": 0,
      "name": "cobblestone"
    },
    {
      "x": 14,
      "y": 3,
      "z": 0,
      "name": "cobblestone"
    },
    {
      "x": 0,
      "y": 3,
      "z": 1,
      "name": "cobblestone"
    },
    {
      "x": 4,
      "y": 3,
      "z": 1,
      "name": "cobblestone"
    },
    {
      "x": 10,
      "y": 3,
      "z": 1,
      "name": "cobblestone"
    },
    {
      "x": 14,
      "y": 3,
      "z": 1,
      "name": "cobblestone"
    },
    {
      "x": 0,
      "y": 3,
      "z": 2,
      "name": "cobblestone"
    },
    {
      "x": 4,
      "y": 3,
      "z": 2,
      "name": "cobblestone"
    },
    {
      "x": 6,
      "y": 3,
      "z": 2,
      "name": "iron_bars"
    },
    {
      "x": 7,
      "y": 3,
      "z": 2,
      "name": "iron_bars"
    },
    {
      "x": 8,
      "y": 3,
      "z": 2,
      "name": "iron_bars"
    },
    {
      "x": 10,
      "y": 3,
      "z": 2,
      "name": "cobblestone"
    },
    {
      "x": 14,
      "y": 3,
      "z": 2,
      "name": "cobblestone"
    },
    {
      "x": 0,
      "y": 3,
      "z": 3,
      "name": "cobblestone"
    },
    {
      "x": 4,
      "y": 3,
      "z": 3,
      "name": "cobblestone"
    },
    {
      "x": 10,
      "y": 3,
      "z": 3,
      "name": "cobblestone"
    },
    {
      "x": 14,
      "y": 3,
      "z": 3,
      "name": "cobblestone"
    },
    {
      "x": 0,
      "y": 3,
      "z": 4,
      "name": "cobblestone"
    },
    {
      "x": 4,
      "y": 3,
      "z": 4,
      "name": "cobblestone"
    },
    {
      "x": 10,
      "y": 3,
      "z": 4,
      "name": "cobblestone"
    },
    {
      "x": 14,
      "y": 3,
      "z": 4,
      "name": "cobblestone"
    },
    {
      "x": 0,
      "y": 3,
      "z": 5,
      "name": "cobblestone"
    },
    {
      "x": 4,
      "y": 3,
      "z": 5,
      "name": "cobblestone"
    },
    {
      "x": 10,
      "y": 3,
      "z": 5,
      "name": "cobblestone"
    },
    {
      "x": 14,
      "y": 3,
      "z": 5,
      "name": "cobblestone"
    },
    {
      "x": 0,
      "y": 3,
      "z": 6,
      "name": "cobblestone"
    },
    {
      "x": 1,
      "y": 3,
      "z": 6,
      "name": "cobblestone"
    },
    {
      "x": 2,
      "y": 3,
      "z": 6,
      "name": "cobblestone"
    },
    {
      "x": 3,
      "y": 3,
      "z": 6,
      "name": "cobblestone"
    },
    {
      "x": 4,
      "y": 3,
      "z": 6,
      "name": "cobblestone"
    },
    {
      "x": 10,
      "y": 3,
      "z": 6,
      "name": "cobblestone"
    },
    {
      "x": 11,
      "y": 3,
      "z": 6,
      "name": "cobblestone"
    },
    {
      "x": 12,
      "y": 3,
      "z": 6,
      "name": "cobblestone"
    },
    {
      "x": 13,
      "y": 3,
      "z": 6,
      "name": "cobblestone"
    },
    {
      "x": 14,
      "y": 3,
      "z": 6,
      "name": "cobblestone"
    },
    {
      "x": 0,
      "y": 4,
      "z": 0,
      "name": "stone_bricks"
    },
    {
      "x": 1,
      "y": 4,
      "z": 0,
      "name": "stone_bricks"
    },
    {
      "x": 2,
      "y": 4,
      "z": 0,
      "name": "stone_bricks"
    },
    {
      "x": 3,
      "y": 4,
      "z": 0,
      "name": "stone_bricks"
    },
    {
      "x": 4,
      "y": 4,
      "z": 0,
      "name": "stone_bricks"
    },
    {
      "x": 10,
      "y": 4,
      "z": 0,
      "name": "stone_bricks"
    },
    {
      "x": 11,
      "y": 4,
      "z": 0,
      "name": "stone_bricks"
    },
    {
      "x": 12,
      "y": 4,
      "z": 0,
      "name": "stone_bricks"
    },
    {
      "x": 13,
      "y": 4,
      "z": 0,
      "name": "stone_bricks"
    },
    {
      "x": 14,
      "y": 4,
      "z": 0,
      "name": "stone_bricks"
    },
    {
      "x": 0,
      "y": 4,
      "z": 1,
      "name": "stone_bricks"
    },
    {
      "x": 4,
      "y": 4,
      "z": 1,
      "name": "stone_bricks"
    },
    {
      "x": 10,
      "y": 4,
      "z": 1,
      "name": "stone_bricks"
    },
    {
      "x": 14,
      "y": 4,
      "z": 1,
      "name": "stone_bricks"
    },
    {
      "x": 0,
      "y": 4,
      "z": 2,
      "name": "stone_bricks"
    },
    {
      "x": 4,
      "y": 4,
      "z": 2,
      "name": "stone_bricks"
    },
    {
      "x": 6,
      "y": 4,
      "z": 2,
      "name": "iron_bars"
    },
    {
      "x": 7,
      "y": 4,
      "z": 2,
      "name": "iron_bars"
    },
    {
      "x": 8,
      "y": 4,
      "z": 2,
      "name": "iron_bars"
    },
    {
      "x": 10,
      "y": 4,
      "z": 2,
      "name": "stone_bricks"
    },
    {
      "x": 14,
      "y": 4,
      "z": 2,
      "name": "stone_bricks"
    },
    {
      "x": 0,
      "y": 4,
      "z": 3,
      "name": "stone_bricks"
    },
    {
      "x": 4,
      "y": 4,
      "z": 3,
      "name": "stone_bricks"
    },
    {
      "x": 10,
      "y": 4,
      "z": 3,
      "name": "stone_bricks"
    },
    {
      "x": 14,
      "y": 4,
      "z": 3,
      "name": "stone_bricks"
    },
    {
      "x": 0,
      "y": 4,
      "z": 4,
      "name": "stone_bricks"
    },
    {
      "x": 4,
      "y": 4,
      "z": 4,
      "name": "stone_bricks"
    },
    {
      "x": 10,
      "y": 4,
      "z": 4,
      "name": "stone_bricks"
    },
    {
      "x": 14,
      "y": 4,
      "z": 4,
      "name": "stone_bricks"
    },
    {
      "x": 0,
      "y": 4,
      "z": 5,
      "name": "stone_bricks"
    },
    {
      "x": 4,
      "y": 4,
      "z": 5,
      "name": "stone_bricks"
    },
    {
      "x": 10,
      "y": 4,
      "z": 5,
      "name": "stone_bricks"
    },
    {
      "x": 14,
      "y": 4,
      "z": 5,
      "name": "stone_bricks"
    },
    {
      "x": 0,
      "y": 4,
      "z": 6,
      "name": "stone_bricks"
    },
    {
      "x": 1,
      "y": 4,
      "z": 6,
      "name": "stone_bricks"
    },
    {
      "x": 2,
      "y": 4,
      "z": 6,
      "name": "stone_bricks"
    },
    {
      "x": 3,
      "y": 4,
      "z": 6,
      "name": "stone_bricks"
    },
    {
      "x": 4,
      "y": 4,
      "z": 6,
      "name": "stone_bricks"
    },
    {
      "x": 10,
      "y": 4,
      "z": 6,
      "name": "stone_bricks"
    },
    {
      "x": 11,
      "y": 4,
      "z": 6,
      "name": "stone_bricks"
    },
    {
      "x": 12,
      "y": 4,
      "z": 6,
      "name": "stone_bricks"
    },
    {
      "x": 13,
      "y": 4,
      "z": 6,
      "name": "stone_bricks"
    },
    {
      "x": 14,
      "y": 4,
      "z": 6,
      "name": "stone_bricks"
    },
    {
      "x": 0,
      "y": 5,
      "z": 0,
      "name": "stone_bricks"
    },
    {
      "x": 1,
      "y": 5,
      "z": 0,
      "name": "stone_bricks"
    },
    {
      "x": 2,
      "y": 5,
      "z": 0,
      "name": "stone_bricks"
    },
    {
      "x": 3,
      "y": 5,
      "z": 0,
      "name": "stone_bricks"
    },
    {
      "x": 4,
      "y": 5,
      "z": 0,
      "name": "stone_bricks"
    },
    {
      "x": 5,
      "y": 5,
      "z": 0,
      "name": "stone_bricks"
    },
    {
      "x": 6,
      "y": 5,
      "z": 0,
      "name": "stone_bricks"
    },
    {
      "x": 7,
      "y": 5,
      "z": 0,
      "name": "stone_bricks"
    },
    {
      "x": 8,
      "y": 5,
      "z": 0,
      "name": "stone_bricks"
    },
    {
      "x": 9,
      "y": 5,
      "z": 0,
      "name": "stone_bricks"
    },
    {
      "x": 10,
      "y": 5,
      "z": 0,
      "name": "stone_bricks"
    },
    {
      "x": 11,
      "y": 5,
      "z": 0,
      "name": "stone_bricks"
    },
    {
      "x": 12,
      "y": 5,
      "z": 0,
      "name": "stone_bricks"
    },
    {
      "x": 13,
      "y": 5,
      "z": 0,
      "name": "stone_bricks"
    },
    {
      "x": 14,
      "y": 5,
      "z": 0,
      "name": "stone_bricks"
    },
    {
      "x": 0,
      "y": 5,
      "z": 1,
      "name": "stone_bricks"
    },
    {
      "x": 4,
      "y": 5,
      "z": 1,
      "name": "stone_bricks"
    },
    {
      "x": 5,
      "y": 5,
      "z": 1,
      "name": "stone_bricks"
    },
    {
      "x": 6,
      "y": 5,
      "z": 1,
      "name": "stone_bricks"
    },
    {
      "x": 7,
      "y": 5,
      "z": 1,
      "name": "stone_bricks"
    },
    {
      "x": 8,
      "y": 5,
      "z": 1,
      "name": "stone_bricks"
    },
    {
      "x": 9,
      "y": 5,
      "z": 1,
      "name": "stone_bricks"
    },
    {
      "x": 10,
      "y": 5,
      "z": 1,
      "name": "stone_bricks"
    },
    {
      "x": 14,
      "y": 5,
      "z": 1,
      "name": "stone_bricks"
    },
    {
      "x": 0,
      "y": 5,
      "z": 2,
      "name": "stone_bricks"
    },
    {
      "x": 4,
      "y": 5,
      "z": 2,
      "name": "stone_bricks"
    },
    {
      "x": 5,
      "y": 5,
      "z": 2,
      "name": "stone_bricks"
    },
    {
      "x": 6,
      "y": 5,
      "z": 2,
      "name": "stone_bricks"
    },
    {
      "x": 7,
      "y": 5,
      "z": 2,
      "name": "stone_bricks"
    },
    {
      "x": 8,
      "y": 5,
      "z": 2,
      "name": "stone_bricks"
    },
    {
      "x": 9,
      "y": 5,
      "z": 2,
      "name": "stone_bricks"
    },
    {
      "x": 10,
      "y": 5,
      "z": 2,
      "name": "stone_bricks"
    },
    {
      "x": 14,
      "y": 5,
      "z": 2,
      "name": "stone_bricks"
    },
    {
      "x": 0,
      "y": 5,
      "z": 3,
      "name": "stone_bricks"
    },
    {
      "x": 4,
      "y": 5,
      "z": 3,
      "name": "stone_bricks"
    },
    {
      "x": 5,
      "y": 5,
      "z": 3,
      "name": "stone_bricks"
    },
    {
      "x": 6,
      "y": 5,
      "z": 3,
      "name": "stone_bricks"
    },
    {
      "x": 7,
      "y": 5,
      "z": 3,
      "name": "stone_bricks"
    },
    {
      "x": 8,
      "y": 5,
      "z": 3,
      "name": "stone_bricks"
    },
    {
      "x": 9,
      "y": 5,
      "z": 3,
      "name": "stone_bricks"
    },
    {
      "x": 10,
      "y": 5,
      "z": 3,
      "name": "stone_bricks"
    },
    {
      "x": 14,
      "y": 5,
      "z": 3,
      "name": "stone_bricks"
    },
    {
      "x": 0,
      "y": 5,
      "z": 4,
      "name": "stone_bricks"
    },
    {
      "x": 4,
      "y": 5,
      "z": 4,
      "name": "stone_bricks"
    },
    {
      "x": 5,
      "y": 5,
      "z": 4,
      "name": "stone_bricks"
    },
    {
      "x": 6,
      "y": 5,
      "z": 4,
      "name": "stone_bricks"
    },
    {
      "x": 7,
      "y": 5,
      "z": 4,
      "name": "stone_bricks"
    },
    {
      "x": 8,
      "y": 5,
      "z": 4,
      "name": "stone_bricks"
    },
    {
      "x": 9,
      "y": 5,
      "z": 4,
      "name": "stone_bricks"
    },
    {
      "x": 10,
      "y": 5,
      "z": 4,
      "name": "stone_bricks"
    },
    {
      "x": 14,
      "y": 5,
      "z": 4,
      "name": "stone_bricks"
    },
    {
      "x": 0,
      "y": 5,
      "z": 5,
      "name": "stone_bricks"
    },
    {
      "x": 4,
      "y": 5,
      "z": 5,
      "name": "stone_bricks"
    },
    {
      "x": 5,
      "y": 5,
      "z": 5,
      "name": "stone_bricks"
    },
    {
      "x": 6,
      "y": 5,
      "z": 5,
      "name": "stone_bricks"
    },
    {
      "x": 7,
      "y": 5,
      "z": 5,
      "name": "stone_bricks"
    },
    {
      "x": 8,
      "y": 5,
      "z": 5,
      "name": "stone_bricks"
    },
    {
      "x": 9,
      "y": 5,
      "z": 5,
      "name": "stone_bricks"
    },
    {
      "x": 10,
      "y": 5,
      "z": 5,
      "name": "stone_bricks"
    },
    {
      "x": 14,
      "y": 5,
      "z": 5,
      "name": "stone_bricks"
    },
    {
      "x": 0,
      "y": 5,
      "z": 6,
      "name": "stone_bricks"
    },
    {
      "x": 1,
      "y": 5,
      "z": 6,
      "name": "stone_bricks"
    },
    {
      "x": 2,
      "y": 5,
      "z": 6,
      "name": "stone_bricks"
    },
    {
      "x": 3,
      "y": 5,
      "z": 6,
      "name": "stone_bricks"
    },
    {
      "x": 4,
      "y": 5,
      "z": 6,
      "name": "stone_bricks"
    },
    {
      "x": 5,
      "y": 5,
      "z": 6,
      "name": "stone_bricks"
    },
    {
      "x": 6,
      "y": 5,
      "z": 6,
      "name": "stone_bricks"
    },
    {
      "x": 7,
      "y": 5,
      "z": 6,
      "name": "stone_bricks"
    },
    {
      "x": 8,
      "y": 5,
      "z": 6,
      "name": "stone_bricks"
    },
    {
      "x": 9,
      "y": 5,
      "z": 6,
      "name": "stone_bricks"
    },
    {
      "x": 10,
      "y": 5,
      "z": 6,
      "name": "stone_bricks"
    },
    {
      "x": 11,
      "y": 5,
      "z": 6,
      "name": "stone_bricks"
    },
    {
      "x": 12,
      "y": 5,
      "z": 6,
      "name": "stone_bricks"
    },
    {
      "x": 13,
      "y": 5,
      "z": 6,
      "name": "stone_bricks"
    },
    {
      "x": 14,
      "y": 5,
      "z": 6,
      "name": "stone_bricks"
    },
    {
      "x": 0,
      "y": 6,
      "z": 0,
      "name": "stone_bricks"
    },
    {
      "x": 1,
      "y": 6,
      "z": 0,
      "name": "stone_bricks"
    },
    {
      "x": 2,
      "y": 6,
      "z": 0,
      "name": "iron_bars"
    },
    {
      "x": 3,
      "y": 6,
      "z": 0,
      "name": "stone_bricks"
    },
    {
      "x": 4,
      "y": 6,
      "z": 0,
      "name": "stone_bricks"
    },
    {
      "x": 5,
      "y": 6,
      "z": 0,
      "name": "stone_bricks"
    },
    {
      "x": 6,
      "y": 6,
      "z": 0,
      "name": "stone_bricks"
    },
    {
      "x": 7,
      "y": 6,
      "z": 0,
      "name": "stone_bricks"
    },
    {
      "x": 8,
      "y": 6,
      "z": 0,
      "name": "stone_bricks"
    },
    {
      "x": 9,
      "y": 6,
      "z": 0,
      "name": "stone_bricks"
    },
    {
      "x": 10,
      "y": 6,
      "z": 0,
      "name": "stone_bricks"
    },
    {
      "x": 11,
      "y": 6,
      "z": 0,
      "name": "stone_bricks"
    },
    {
      "x": 12,
      "y": 6,
      "z": 0,
      "name": "iron_bars"
    },
    {
      "x": 13,
      "y": 6,
      "z": 0,
      "name": "stone_bricks"
    },
    {
      "x": 14,
      "y": 6,
      "z": 0,
      "name": "stone_bricks"
    },
    {
      "x": 0,
      "y": 6,
      "z": 1,
      "name": "stone_bricks"
    },
    {
      "x": 4,
      "y": 6,
      "z": 1,
      "name": "stone_bricks"
    },
    {
      "x": 5,
      "y": 6,
      "z": 1,
      "name": "stone_bricks"
    },
    {
      "x": 6,
      "y": 6,
      "z": 1,
      "name": "stone_bricks"
    },
    {
      "x": 7,
      "y": 6,
      "z": 1,
      "name": "stone_bricks"
    },
    {
      "x": 8,
      "y": 6,
      "z": 1,
      "name": "stone_bricks"
    },
    {
      "x": 9,
      "y": 6,
      "z": 1,
      "name": "stone_bricks"
    },
    {
      "x": 10,
      "y": 6,
      "z": 1,
      "name": "stone_bricks"
    },
    {
      "x": 14,
      "y": 6,
      "z": 1,
      "name": "stone_bricks"
    },
    {
      "x": 0,
      "y": 6,
      "z": 2,
      "name": "stone_bricks"
    },
    {
      "x": 4,
      "y": 6,
      "z": 2,
      "name": "stone_bricks"
    },
    {
      "x": 5,
      "y": 6,
      "z": 2,
      "name": "stone_bricks"
    },
    {
      "x": 6,
      "y": 6,
      "z": 2,
      "name": "stone_bricks"
    },
    {
      "x": 7,
      "y": 6,
      "z": 2,
      "name": "stone_bricks"
    },
    {
      "x": 8,
      "y": 6,
      "z": 2,
      "name": "stone_bricks"
    },
    {
      "x": 9,
      "y": 6,
      "z": 2,
      "name": "stone_bricks"
    },
    {
      "x": 10,
      "y": 6,
      "z": 2,
      "name": "stone_bricks"
    },
    {
      "x": 14,
      "y": 6,
      "z": 2,
      "name": "stone_bricks"
    },
    {
      "x": 0,
      "y": 6,
      "z": 3,
      "name": "stone_bricks"
    },
    {
      "x": 4,
      "y": 6,
      "z": 3,
      "name": "stone_bricks"
    },
    {
      "x": 5,
      "y": 6,
      "z": 3,
      "name": "stone_bricks"
    },
    {
      "x": 6,
      "y": 6,
      "z": 3,
      "name": "stone_bricks"
    },
    {
      "x": 7,
      "y": 6,
      "z": 3,
      "name": "stone_bricks"
    },
    {
      "x": 8,
      "y": 6,
      "z": 3,
      "name": "stone_bricks"
    },
    {
      "x": 9,
      "y": 6,
      "z": 3,
      "name": "stone_bricks"
    },
    {
      "x": 10,
      "y": 6,
      "z": 3,
      "name": "stone_bricks"
    },
    {
      "x": 14,
      "y": 6,
      "z": 3,
      "name": "stone_bricks"
    },
    {
      "x": 0,
      "y": 6,
      "z": 4,
      "name": "stone_bricks"
    },
    {
      "x": 4,
      "y": 6,
      "z": 4,
      "name": "stone_bricks"
    },
    {
      "x": 5,
      "y": 6,
      "z": 4,
      "name": "stone_bricks"
    },
    {
      "x": 6,
      "y": 6,
      "z": 4,
      "name": "stone_bricks"
    },
    {
      "x": 7,
      "y": 6,
      "z": 4,
      "name": "stone_bricks"
    },
    {
      "x": 8,
      "y": 6,
      "z": 4,
      "name": "stone_bricks"
    },
    {
      "x": 9,
      "y": 6,
      "z": 4,
      "name": "stone_bricks"
    },
    {
      "x": 10,
      "y": 6,
      "z": 4,
      "name": "stone_bricks"
    },
    {
      "x": 14,
      "y": 6,
      "z": 4,
      "name": "stone_bricks"
    },
    {
      "x": 0,
      "y": 6,
      "z": 5,
      "name": "stone_bricks"
    },
    {
      "x": 4,
      "y": 6,
      "z": 5,
      "name": "stone_bricks"
    },
    {
      "x": 5,
      "y": 6,
      "z": 5,
      "name": "stone_bricks"
    },
    {
      "x": 6,
      "y": 6,
      "z": 5,
      "name": "stone_bricks"
    },
    {
      "x": 7,
      "y": 6,
      "z": 5,
      "name": "stone_bricks"
    },
    {
      "x": 8,
      "y": 6,
      "z": 5,
      "name": "stone_bricks"
    },
    {
      "x": 9,
      "y": 6,
      "z": 5,
      "name": "stone_bricks"
    },
    {
      "x": 10,
      "y": 6,
      "z": 5,
      "name": "stone_bricks"
    },
    {
      "x": 14,
      "y": 6,
      "z": 5,
      "name": "stone_bricks"
    },
    {
      "x": 0,
      "y": 6,
      "z": 6,
      "name": "stone_bricks"
    },
    {
      "x": 1,
      "y": 6,
      "z": 6,
      "name": "stone_bricks"
    },
    {
      "x": 2,
      "y": 6,
      "z": 6,
      "name": "stone_bricks"
    },
    {
      "x": 3,
      "y": 6,
      "z": 6,
      "name": "stone_bricks"
    },
    {
      "x": 4,
      "y": 6,
      "z": 6,
      "name": "stone_bricks"
    },
    {
      "x": 5,
      "y": 6,
      "z": 6,
      "name": "stone_bricks"
    },
    {
      "x": 6,
      "y": 6,
      "z": 6,
      "name": "stone_bricks"
    },
    {
      "x": 7,
      "y": 6,
      "z": 6,
      "name": "stone_bricks"
    },
    {
      "x": 8,
      "y": 6,
      "z": 6,
      "name": "stone_bricks"
    },
    {
      "x": 9,
      "y": 6,
      "z": 6,
      "name": "stone_bricks"
    },
    {
      "x": 10,
      "y": 6,
      "z": 6,
      "name": "stone_bricks"
    },
    {
      "x": 11,
      "y": 6,
      "z": 6,
      "name": "stone_bricks"
    },
    {
      "x": 12,
      "y": 6,
      "z": 6,
      "name": "stone_bricks"
    },
    {
      "x": 13,
      "y": 6,
      "z": 6,
      "name": "stone_bricks"
    },
    {
      "x": 14,
      "y": 6,
      "z": 6,
      "name": "stone_bricks"
    },
    {
      "x": 0,
      "y": 7,
      "z": 0,
      "name": "stone_bricks"
    },
    {
      "x": 1,
      "y": 7,
      "z": 0,
      "name": "stone_bricks"
    },
    {
      "x": 2,
      "y": 7,
      "z": 0,
      "name": "stone_bricks"
    },
    {
      "x": 3,
      "y": 7,
      "z": 0,
      "name": "stone_bricks"
    },
    {
      "x": 4,
      "y": 7,
      "z": 0,
      "name": "stone_bricks"
    },
    {
      "x": 5,
      "y": 7,
      "z": 0,
      "name": "stone_bricks"
    },
    {
      "x": 6,
      "y": 7,
      "z": 0,
      "name": "stone_bricks"
    },
    {
      "x": 7,
      "y": 7,
      "z": 0,
      "name": "stone_bricks"
    },
    {
      "x": 8,
      "y": 7,
      "z": 0,
      "name": "stone_bricks"
    },
    {
      "x": 9,
      "y": 7,
      "z": 0,
      "name": "stone_bricks"
    },
    {
      "x": 10,
      "y": 7,
      "z": 0,
      "name": "stone_bricks"
    },
    {
      "x": 11,
      "y": 7,
      "z": 0,
      "name": "stone_bricks"
    },
    {
      "x": 12,
      "y": 7,
      "z": 0,
      "name": "stone_bricks"
    },
    {
      "x": 13,
      "y": 7,
      "z": 0,
      "name": "stone_bricks"
    },
    {
      "x": 14,
      "y": 7,
      "z": 0,
      "name": "stone_bricks"
    },
    {
      "x": 0,
      "y": 7,
      "z": 1,
      "name": "stone_bricks"
    },
    {
      "x": 4,
      "y": 7,
      "z": 1,
      "name": "stone_bricks"
    },
    {
      "x": 5,
      "y": 7,
      "z": 1,
      "name": "stone_bricks"
    },
    {
      "x": 6,
      "y": 7,
      "z": 1,
      "name": "stone_bricks"
    },
    {
      "x": 7,
      "y": 7,
      "z": 1,
      "name": "lantern"
    },
    {
      "x": 8,
      "y": 7,
      "z": 1,
      "name": "stone_bricks"
    },
    {
      "x": 9,
      "y": 7,
      "z": 1,
      "name": "stone_bricks"
    },
    {
      "x": 10,
      "y": 7,
      "z": 1,
      "name": "stone_bricks"
    },
    {
      "x": 14,
      "y": 7,
      "z": 1,
      "name": "stone_bricks"
    },
    {
      "x": 0,
      "y": 7,
      "z": 2,
      "name": "stone_bricks"
    },
    {
      "x": 4,
      "y": 7,
      "z": 2,
      "name": "stone_bricks"
    },
    {
      "x": 5,
      "y": 7,
      "z": 2,
      "name": "stone_bricks"
    },
    {
      "x": 6,
      "y": 7,
      "z": 2,
      "name": "stone_bricks"
    },
    {
      "x": 7,
      "y": 7,
      "z": 2,
      "name": "stone_bricks"
    },
    {
      "x": 8,
      "y": 7,
      "z": 2,
      "name": "stone_bricks"
    },
    {
      "x": 9,
      "y": 7,
      "z": 2,
      "name": "stone_bricks"
    },
    {
      "x": 10,
      "y": 7,
      "z": 2,
      "name": "stone_bricks"
    },
    {
      "x": 14,
      "y": 7,
      "z": 2,
      "name": "stone_bricks"
    },
    {
      "x": 0,
      "y": 7,
      "z": 3,
      "name": "stone_bricks"
    },
    {
      "x": 4,
      "y": 7,
      "z": 3,
      "name": "stone_bricks"
    },
    {
      "x": 5,
      "y": 7,
      "z": 3,
      "name": "stone_bricks"
    },
    {
      "x": 6,
      "y": 7,
      "z": 3,
      "name": "stone_bricks"
    },
    {
      "x": 7,
      "y": 7,
      "z": 3,
      "name": "stone_bricks"
    },
    {
      "x": 8,
      "y": 7,
      "z": 3,
      "name": "stone_bricks"
    },
    {
      "x": 9,
      "y": 7,
      "z": 3,
      "name": "stone_bricks"
    },
    {
      "x": 10,
      "y": 7,
      "z": 3,
      "name": "stone_bricks"
    },
    {
      "x": 14,
      "y": 7,
      "z": 3,
      "name": "stone_bricks"
    },
    {
      "x": 0,
      "y": 7,
      "z": 4,
      "name": "stone_bricks"
    },
    {
      "x": 4,
      "y": 7,
      "z": 4,
      "name": "stone_bricks"
    },
    {
      "x": 5,
      "y": 7,
      "z": 4,
      "name": "stone_bricks"
    },
    {
      "x": 6,
      "y": 7,
      "z": 4,
      "name": "stone_bricks"
    },
    {
      "x": 7,
      "y": 7,
      "z": 4,
      "name": "stone_bricks"
    },
    {
      "x": 8,
      "y": 7,
      "z": 4,
      "name": "stone_bricks"
    },
    {
      "x": 9,
      "y": 7,
      "z": 4,
      "name": "stone_bricks"
    },
    {
      "x": 10,
      "y": 7,
      "z": 4,
      "name": "stone_bricks"
    },
    {
      "x": 14,
      "y": 7,
      "z": 4,
      "name": "stone_bricks"
    },
    {
      "x": 0,
      "y": 7,
      "z": 5,
      "name": "stone_bricks"
    },
    {
      "x": 4,
      "y": 7,
      "z": 5,
      "name": "stone_bricks"
    },
    {
      "x": 5,
      "y": 7,
      "z": 5,
      "name": "stone_bricks"
    },
    {
      "x": 6,
      "y": 7,
      "z": 5,
      "name": "stone_bricks"
    },
    {
      "x": 7,
      "y": 7,
      "z": 5,
      "name": "stone_bricks"
    },
    {
      "x": 8,
      "y": 7,
      "z": 5,
      "name": "stone_bricks"
    },
    {
      "x": 9,
      "y": 7,
      "z": 5,
      "name": "stone_bricks"
    },
    {
      "x": 10,
      "y": 7,
      "z": 5,
      "name": "stone_bricks"
    },
    {
      "x": 14,
      "y": 7,
      "z": 5,
      "name": "stone_bricks"
    },
    {
      "x": 0,
      "y": 7,
      "z": 6,
      "name": "stone_bricks"
    },
    {
      "x": 1,
      "y": 7,
      "z": 6,
      "name": "stone_bricks"
    },
    {
      "x": 2,
      "y": 7,
      "z": 6,
      "name": "stone_bricks"
    },
    {
      "x": 3,
      "y": 7,
      "z": 6,
      "name": "stone_bricks"
    },
    {
      "x": 4,
      "y": 7,
      "z": 6,
      "name": "stone_bricks"
    },
    {
      "x": 5,
      "y": 7,
      "z": 6,
      "name": "stone_bricks"
    },
    {
      "x": 6,
      "y": 7,
      "z": 6,
      "name": "stone_bricks"
    },
    {
      "x": 7,
      "y": 7,
      "z": 6,
      "name": "stone_bricks"
    },
    {
      "x": 8,
      "y": 7,
      "z": 6,
      "name": "stone_bricks"
    },
    {
      "x": 9,
      "y": 7,
      "z": 6,
      "name": "stone_bricks"
    },
    {
      "x": 10,
      "y": 7,
      "z": 6,
      "name": "stone_bricks"
    },
    {
      "x": 11,
      "y": 7,
      "z": 6,
      "name": "stone_bricks"
    },
    {
      "x": 12,
      "y": 7,
      "z": 6,
      "name": "stone_bricks"
    },
    {
      "x": 13,
      "y": 7,
      "z": 6,
      "name": "stone_bricks"
    },
    {
      "x": 14,
      "y": 7,
      "z": 6,
      "name": "stone_bricks"
    },
    {
      "x": 0,
      "y": 8,
      "z": 0,
      "name": "stone_bricks"
    },
    {
      "x": 1,
      "y": 8,
      "z": 0,
      "name": "stone_bricks"
    },
    {
      "x": 2,
      "y": 8,
      "z": 0,
      "name": "stone_bricks"
    },
    {
      "x": 3,
      "y": 8,
      "z": 0,
      "name": "stone_bricks"
    },
    {
      "x": 4,
      "y": 8,
      "z": 0,
      "name": "stone_bricks"
    },
    {
      "x": 5,
      "y": 8,
      "z": 0,
      "name": "stone_bricks"
    },
    {
      "x": 6,
      "y": 8,
      "z": 0,
      "name": "stone_bricks"
    },
    {
      "x": 7,
      "y": 8,
      "z": 0,
      "name": "stone_bricks"
    },
    {
      "x": 8,
      "y": 8,
      "z": 0,
      "name": "stone_bricks"
    },
    {
      "x": 9,
      "y": 8,
      "z": 0,
      "name": "stone_bricks"
    },
    {
      "x": 10,
      "y": 8,
      "z": 0,
      "name": "stone_bricks"
    },
    {
      "x": 11,
      "y": 8,
      "z": 0,
      "name": "stone_bricks"
    },
    {
      "x": 12,
      "y": 8,
      "z": 0,
      "name": "stone_bricks"
    },
    {
      "x": 13,
      "y": 8,
      "z": 0,
      "name": "stone_bricks"
    },
    {
      "x": 14,
      "y": 8,
      "z": 0,
      "name": "stone_bricks"
    },
    {
      "x": 0,
      "y": 8,
      "z": 1,
      "name": "stone_bricks"
    },
    {
      "x": 1,
      "y": 8,
      "z": 1,
      "name": "stone_bricks"
    },
    {
      "x": 2,
      "y": 8,
      "z": 1,
      "name": "stone_bricks"
    },
    {
      "x": 3,
      "y": 8,
      "z": 1,
      "name": "stone_bricks"
    },
    {
      "x": 4,
      "y": 8,
      "z": 1,
      "name": "stone_bricks"
    },
    {
      "x": 5,
      "y": 8,
      "z": 1,
      "name": "stone_bricks"
    },
    {
      "x": 6,
      "y": 8,
      "z": 1,
      "name": "stone_bricks"
    },
    {
      "x": 7,
      "y": 8,
      "z": 1,
      "name": "stone_bricks"
    },
    {
      "x": 8,
      "y": 8,
      "z": 1,
      "name": "stone_bricks"
    },
    {
      "x": 9,
      "y": 8,
      "z": 1,
      "name": "stone_bricks"
    },
    {
      "x": 10,
      "y": 8,
      "z": 1,
      "name": "stone_bricks"
    },
    {
      "x": 11,
      "y": 8,
      "z": 1,
      "name": "stone_bricks"
    },
    {
      "x": 12,
      "y": 8,
      "z": 1,
      "name": "stone_bricks"
    },
    {
      "x": 13,
      "y": 8,
      "z": 1,
      "name": "stone_bricks"
    },
    {
      "x": 14,
      "y": 8,
      "z": 1,
      "name": "stone_bricks"
    },
    {
      "x": 0,
      "y": 8,
      "z": 2,
      "name": "stone_bricks"
    },
    {
      "x": 1,
      "y": 8,
      "z": 2,
      "name": "stone_bricks"
    },
    {
      "x": 2,
      "y": 8,
      "z": 2,
      "name": "stone_bricks"
    },
    {
      "x": 3,
      "y": 8,
      "z": 2,
      "name": "stone_bricks"
    },
    {
      "x": 4,
      "y": 8,
      "z": 2,
      "name": "stone_bricks"
    },
    {
      "x": 5,
      "y": 8,
      "z": 2,
      "name": "stone_bricks"
    },
    {
      "x": 6,
      "y": 8,
      "z": 2,
      "name": "stone_bricks"
    },
    {
      "x": 7,
      "y": 8,
      "z": 2,
      "name": "stone_bricks"
    },
    {
      "x": 8,
      "y": 8,
      "z": 2,
      "name": "stone_bricks"
    },
    {
      "x": 9,
      "y": 8,
      "z": 2,
      "name": "stone_bricks"
    },
    {
      "x": 10,
      "y": 8,
      "z": 2,
      "name": "stone_bricks"
    },
    {
      "x": 11,
      "y": 8,
      "z": 2,
      "name": "stone_bricks"
    },
    {
      "x": 12,
      "y": 8,
      "z": 2,
      "name": "stone_bricks"
    },
    {
      "x": 13,
      "y": 8,
      "z": 2,
      "name": "stone_bricks"
    },
    {
      "x": 14,
      "y": 8,
      "z": 2,
      "name": "stone_bricks"
    },
    {
      "x": 0,
      "y": 8,
      "z": 3,
      "name": "stone_bricks"
    },
    {
      "x": 1,
      "y": 8,
      "z": 3,
      "name": "stone_bricks"
    },
    {
      "x": 2,
      "y": 8,
      "z": 3,
      "name": "stone_bricks"
    },
    {
      "x": 3,
      "y": 8,
      "z": 3,
      "name": "stone_bricks"
    },
    {
      "x": 4,
      "y": 8,
      "z": 3,
      "name": "stone_bricks"
    },
    {
      "x": 5,
      "y": 8,
      "z": 3,
      "name": "stone_bricks"
    },
    {
      "x": 6,
      "y": 8,
      "z": 3,
      "name": "stone_bricks"
    },
    {
      "x": 7,
      "y": 8,
      "z": 3,
      "name": "stone_bricks"
    },
    {
      "x": 8,
      "y": 8,
      "z": 3,
      "name": "stone_bricks"
    },
    {
      "x": 9,
      "y": 8,
      "z": 3,
      "name": "stone_bricks"
    },
    {
      "x": 10,
      "y": 8,
      "z": 3,
      "name": "stone_bricks"
    },
    {
      "x": 11,
      "y": 8,
      "z": 3,
      "name": "stone_bricks"
    },
    {
      "x": 12,
      "y": 8,
      "z": 3,
      "name": "stone_bricks"
    },
    {
      "x": 13,
      "y": 8,
      "z": 3,
      "name": "stone_bricks"
    },
    {
      "x": 14,
      "y": 8,
      "z": 3,
      "name": "stone_bricks"
    },
    {
      "x": 0,
      "y": 8,
      "z": 4,
      "name": "stone_bricks"
    },
    {
      "x": 1,
      "y": 8,
      "z": 4,
      "name": "stone_bricks"
    },
    {
      "x": 2,
      "y": 8,
      "z": 4,
      "name": "stone_bricks"
    },
    {
      "x": 3,
      "y": 8,
      "z": 4,
      "name": "stone_bricks"
    },
    {
      "x": 4,
      "y": 8,
      "z": 4,
      "name": "stone_bricks"
    },
    {
      "x": 5,
      "y": 8,
      "z": 4,
      "name": "stone_bricks"
    },
    {
      "x": 6,
      "y": 8,
      "z": 4,
      "name": "stone_bricks"
    },
    {
      "x": 7,
      "y": 8,
      "z": 4,
      "name": "stone_bricks"
    },
    {
      "x": 8,
      "y": 8,
      "z": 4,
      "name": "stone_bricks"
    },
    {
      "x": 9,
      "y": 8,
      "z": 4,
      "name": "stone_bricks"
    },
    {
      "x": 10,
      "y": 8,
      "z": 4,
      "name": "stone_bricks"
    },
    {
      "x": 11,
      "y": 8,
      "z": 4,
      "name": "stone_bricks"
    },
    {
      "x": 12,
      "y": 8,
      "z": 4,
      "name": "stone_bricks"
    },
    {
      "x": 13,
      "y": 8,
      "z": 4,
      "name": "stone_bricks"
    },
    {
      "x": 14,
      "y": 8,
      "z": 4,
      "name": "stone_bricks"
    },
    {
      "x": 0,
      "y": 8,
      "z": 5,
      "name": "stone_bricks"
    },
    {
      "x": 1,
      "y": 8,
      "z": 5,
      "name": "stone_bricks"
    },
    {
      "x": 2,
      "y": 8,
      "z": 5,
      "name": "stone_bricks"
    },
    {
      "x": 3,
      "y": 8,
      "z": 5,
      "name": "stone_bricks"
    },
    {
      "x": 4,
      "y": 8,
      "z": 5,
      "name": "stone_bricks"
    },
    {
      "x": 5,
      "y": 8,
      "z": 5,
      "name": "stone_bricks"
    },
    {
      "x": 6,
      "y": 8,
      "z": 5,
      "name": "stone_bricks"
    },
    {
      "x": 7,
      "y": 8,
      "z": 5,
      "name": "stone_bricks"
    },
    {
      "x": 8,
      "y": 8,
      "z": 5,
      "name": "stone_bricks"
    },
    {
      "x": 9,
      "y": 8,
      "z": 5,
      "name": "stone_bricks"
    },
    {
      "x": 10,
      "y": 8,
      "z": 5,
      "name": "stone_bricks"
    },
    {
      "x": 11,
      "y": 8,
      "z": 5,
      "name": "stone_bricks"
    },
    {
      "x": 12,
      "y": 8,
      "z": 5,
      "name": "stone_bricks"
    },
    {
      "x": 13,
      "y": 8,
      "z": 5,
      "name": "stone_bricks"
    },
    {
      "x": 14,
      "y": 8,
      "z": 5,
      "name": "stone_bricks"
    },
    {
      "x": 0,
      "y": 8,
      "z": 6,
      "name": "stone_bricks"
    },
    {
      "x": 1,
      "y": 8,
      "z": 6,
      "name": "stone_bricks"
    },
    {
      "x": 2,
      "y": 8,
      "z": 6,
      "name": "stone_bricks"
    },
    {
      "x": 3,
      "y": 8,
      "z": 6,
      "name": "stone_bricks"
    },
    {
      "x": 4,
      "y": 8,
      "z": 6,
      "name": "stone_bricks"
    },
    {
      "x": 5,
      "y": 8,
      "z": 6,
      "name": "stone_bricks"
    },
    {
      "x": 6,
      "y": 8,
      "z": 6,
      "name": "stone_bricks"
    },
    {
      "x": 7,
      "y": 8,
      "z": 6,
      "name": "stone_bricks"
    },
    {
      "x": 8,
      "y": 8,
      "z": 6,
      "name": "stone_bricks"
    },
    {
      "x": 9,
      "y": 8,
      "z": 6,
      "name": "stone_bricks"
    },
    {
      "x": 10,
      "y": 8,
      "z": 6,
      "name": "stone_bricks"
    },
    {
      "x": 11,
      "y": 8,
      "z": 6,
      "name": "stone_bricks"
    },
    {
      "x": 12,
      "y": 8,
      "z": 6,
      "name": "stone_bricks"
    },
    {
      "x": 13,
      "y": 8,
      "z": 6,
      "name": "stone_bricks"
    },
    {
      "x": 14,
      "y": 8,
      "z": 6,
      "name": "stone_bricks"
    },
    {
      "x": 0,
      "y": 9,
      "z": 0,
      "name": "stone_bricks"
    },
    {
      "x": 1,
      "y": 9,
      "z": 0,
      "name": "stone_bricks"
    },
    {
      "x": 2,
      "y": 9,
      "z": 0,
      "name": "stone_bricks"
    },
    {
      "x": 3,
      "y": 9,
      "z": 0,
      "name": "stone_bricks"
    },
    {
      "x": 4,
      "y": 9,
      "z": 0,
      "name": "stone_bricks"
    },
    {
      "x": 5,
      "y": 9,
      "z": 0,
      "name": "dark_oak_planks"
    },
    {
      "x": 6,
      "y": 9,
      "z": 0,
      "name": "dark_oak_planks"
    },
    {
      "x": 7,
      "y": 9,
      "z": 0,
      "name": "dark_oak_planks"
    },
    {
      "x": 8,
      "y": 9,
      "z": 0,
      "name": "dark_oak_planks"
    },
    {
      "x": 9,
      "y": 9,
      "z": 0,
      "name": "dark_oak_planks"
    },
    {
      "x": 10,
      "y": 9,
      "z": 0,
      "name": "stone_bricks"
    },
    {
      "x": 11,
      "y": 9,
      "z": 0,
      "name": "stone_bricks"
    },
    {
      "x": 12,
      "y": 9,
      "z": 0,
      "name": "stone_bricks"
    },
    {
      "x": 13,
      "y": 9,
      "z": 0,
      "name": "stone_bricks"
    },
    {
      "x": 14,
      "y": 9,
      "z": 0,
      "name": "stone_bricks"
    },
    {
      "x": 0,
      "y": 9,
      "z": 1,
      "name": "stone_bricks"
    },
    {
      "x": 4,
      "y": 9,
      "z": 1,
      "name": "stone_bricks"
    },
    {
      "x": 5,
      "y": 9,
      "z": 1,
      "name": "dark_oak_planks"
    },
    {
      "x": 6,
      "y": 9,
      "z": 1,
      "name": "dark_oak_planks"
    },
    {
      "x": 7,
      "y": 9,
      "z": 1,
      "name": "dark_oak_planks"
    },
    {
      "x": 8,
      "y": 9,
      "z": 1,
      "name": "dark_oak_planks"
    },
    {
      "x": 9,
      "y": 9,
      "z": 1,
      "name": "dark_oak_planks"
    },
    {
      "x": 10,
      "y": 9,
      "z": 1,
      "name": "stone_bricks"
    },
    {
      "x": 14,
      "y": 9,
      "z": 1,
      "name": "stone_bricks"
    },
    {
      "x": 0,
      "y": 9,
      "z": 2,
      "name": "stone_bricks"
    },
    {
      "x": 4,
      "y": 9,
      "z": 2,
      "name": "stone_bricks"
    },
    {
      "x": 5,
      "y": 9,
      "z": 2,
      "name": "dark_oak_planks"
    },
    {
      "x": 6,
      "y": 9,
      "z": 2,
      "name": "dark_oak_planks"
    },
    {
      "x": 7,
      "y": 9,
      "z": 2,
      "name": "dark_oak_planks"
    },
    {
      "x": 8,
      "y": 9,
      "z": 2,
      "name": "dark_oak_planks"
    },
    {
      "x": 9,
      "y": 9,
      "z": 2,
      "name": "dark_oak_planks"
    },
    {
      "x": 10,
      "y": 9,
      "z": 2,
      "name": "stone_bricks"
    },
    {
      "x": 14,
      "y": 9,
      "z": 2,
      "name": "stone_bricks"
    },
    {
      "x": 0,
      "y": 9,
      "z": 3,
      "name": "stone_bricks"
    },
    {
      "x": 4,
      "y": 9,
      "z": 3,
      "name": "stone_bricks"
    },
    {
      "x": 5,
      "y": 9,
      "z": 3,
      "name": "dark_oak_planks"
    },
    {
      "x": 6,
      "y": 9,
      "z": 3,
      "name": "dark_oak_planks"
    },
    {
      "x": 7,
      "y": 9,
      "z": 3,
      "name": "dark_oak_planks"
    },
    {
      "x": 8,
      "y": 9,
      "z": 3,
      "name": "dark_oak_planks"
    },
    {
      "x": 9,
      "y": 9,
      "z": 3,
      "name": "dark_oak_planks"
    },
    {
      "x": 10,
      "y": 9,
      "z": 3,
      "name": "stone_bricks"
    },
    {
      "x": 14,
      "y": 9,
      "z": 3,
      "name": "stone_bricks"
    },
    {
      "x": 0,
      "y": 9,
      "z": 4,
      "name": "stone_bricks"
    },
    {
      "x": 4,
      "y": 9,
      "z": 4,
      "name": "stone_bricks"
    },
    {
      "x": 5,
      "y": 9,
      "z": 4,
      "name": "dark_oak_planks"
    },
    {
      "x": 6,
      "y": 9,
      "z": 4,
      "name": "dark_oak_planks"
    },
    {
      "x": 7,
      "y": 9,
      "z": 4,
      "name": "dark_oak_planks"
    },
    {
      "x": 8,
      "y": 9,
      "z": 4,
      "name": "dark_oak_planks"
    },
    {
      "x": 9,
      "y": 9,
      "z": 4,
      "name": "dark_oak_planks"
    },
    {
      "x": 10,
      "y": 9,
      "z": 4,
      "name": "stone_bricks"
    },
    {
      "x": 14,
      "y": 9,
      "z": 4,
      "name": "stone_bricks"
    },
    {
      "x": 0,
      "y": 9,
      "z": 5,
      "name": "stone_bricks"
    },
    {
      "x": 4,
      "y": 9,
      "z": 5,
      "name": "stone_bricks"
    },
    {
      "x": 5,
      "y": 9,
      "z": 5,
      "name": "dark_oak_planks"
    },
    {
      "x": 6,
      "y": 9,
      "z": 5,
      "name": "dark_oak_planks"
    },
    {
      "x": 7,
      "y": 9,
      "z": 5,
      "name": "dark_oak_planks"
    },
    {
      "x": 8,
      "y": 9,
      "z": 5,
      "name": "dark_oak_planks"
    },
    {
      "x": 9,
      "y": 9,
      "z": 5,
      "name": "dark_oak_planks"
    },
    {
      "x": 10,
      "y": 9,
      "z": 5,
      "name": "stone_bricks"
    },
    {
      "x": 14,
      "y": 9,
      "z": 5,
      "name": "stone_bricks"
    },
    {
      "x": 0,
      "y": 9,
      "z": 6,
      "name": "stone_bricks"
    },
    {
      "x": 1,
      "y": 9,
      "z": 6,
      "name": "stone_bricks"
    },
    {
      "x": 2,
      "y": 9,
      "z": 6,
      "name": "stone_bricks"
    },
    {
      "x": 3,
      "y": 9,
      "z": 6,
      "name": "stone_bricks"
    },
    {
      "x": 4,
      "y": 9,
      "z": 6,
      "name": "stone_bricks"
    },
    {
      "x": 5,
      "y": 9,
      "z": 6,
      "name": "dark_oak_planks"
    },
    {
      "x": 6,
      "y": 9,
      "z": 6,
      "name": "dark_oak_planks"
    },
    {
      "x": 7,
      "y": 9,
      "z": 6,
      "name": "dark_oak_planks"
    },
    {
      "x": 8,
      "y": 9,
      "z": 6,
      "name": "dark_oak_planks"
    },
    {
      "x": 9,
      "y": 9,
      "z": 6,
      "name": "dark_oak_planks"
    },
    {
      "x": 10,
      "y": 9,
      "z": 6,
      "name": "stone_bricks"
    },
    {
      "x": 11,
      "y": 9,
      "z": 6,
      "name": "stone_bricks"
    },
    {
      "x": 12,
      "y": 9,
      "z": 6,
      "name": "stone_bricks"
    },
    {
      "x": 13,
      "y": 9,
      "z": 6,
      "name": "stone_bricks"
    },
    {
      "x": 14,
      "y": 9,
      "z": 6,
      "name": "stone_bricks"
    },
    {
      "x": 0,
      "y": 10,
      "z": 0,
      "name": "stone_bricks"
    },
    {
      "x": 2,
      "y": 10,
      "z": 0,
      "name": "stone_bricks"
    },
    {
      "x": 4,
      "y": 10,
      "z": 0,
      "name": "stone_bricks"
    },
    {
      "x": 5,
      "y": 10,
      "z": 0,
      "name": "stone_bricks"
    },
    {
      "x": 7,
      "y": 10,
      "z": 0,
      "name": "stone_bricks"
    },
    {
      "x": 9,
      "y": 10,
      "z": 0,
      "name": "stone_bricks"
    },
    {
      "x": 10,
      "y": 10,
      "z": 0,
      "name": "stone_bricks"
    },
    {
      "x": 12,
      "y": 10,
      "z": 0,
      "name": "stone_bricks"
    },
    {
      "x": 14,
      "y": 10,
      "z": 0,
      "name": "stone_bricks"
    },
    {
      "x": 0,
      "y": 10,
      "z": 6,
      "name": "stone_bricks"
    },
    {
      "x": 2,
      "y": 10,
      "z": 6,
      "name": "stone_bricks"
    },
    {
      "x": 4,
      "y": 10,
      "z": 6,
      "name": "stone_bricks"
    },
    {
      "x": 5,
      "y": 10,
      "z": 6,
      "name": "stone_bricks"
    },
    {
      "x": 7,
      "y": 10,
      "z": 6,
      "name": "stone_bricks"
    },
    {
      "x": 9,
      "y": 10,
      "z": 6,
      "name": "stone_bricks"
    },
    {
      "x": 10,
      "y": 10,
      "z": 6,
      "name": "stone_bricks"
    },
    {
      "x": 12,
      "y": 10,
      "z": 6,
      "name": "stone_bricks"
    },
    {
      "x": 14,
      "y": 10,
      "z": 6,
      "name": "stone_bricks"
    }
  ]
}
