{
  "_opis": "Majhna srednjeveska koca iz kamna in temnega lesa.",
  "_category": "medieval",
  "_kind": "building",
  "_aliases": [
    "srednjeveska koca"
  ],
  "size": [
    9,
    11,
    8
  ],
  "blocks": [
    {
      "x": 0,
      "y": 0,
      "z": 0,
      "name": "spruce_planks"
    },
    {
      "x": 1,
      "y": 0,
      "z": 0,
      "name": "spruce_planks"
    },
    {
      "x": 2,
      "y": 0,
      "z": 0,
      "name": "spruce_planks"
    },
    {
      "x": 3,
      "y": 0,
      "z": 0,
      "name": "spruce_planks"
    },
    {
      "x": 4,
      "y": 0,
      "z": 0,
      "name": "spruce_planks"
    },
    {
      "x": 5,
      "y": 0,
      "z": 0,
      "name": "spruce_planks"
    },
    {
      "x": 6,
      "y": 0,
      "z": 0,
      "name": "spruce_planks"
    },
    {
      "x": 7,
      "y": 0,
      "z": 0,
      "name": "spruce_planks"
    },
    {
      "x": 8,
      "y": 0,
      "z": 0,
      "name": "spruce_planks"
    },
    {
      "x": 0,
      "y": 0,
      "z": 1,
      "name": "spruce_planks"
    },
    {
      "x": 1,
      "y": 0,
      "z": 1,
      "name": "spruce_planks"
    },
    {
      "x": 2,
      "y": 0,
      "z": 1,
      "name": "spruce_planks"
    },
    {
      "x": 3,
      "y": 0,
      "z": 1,
      "name": "spruce_planks"
    },
    {
      "x": 4,
      "y": 0,
      "z": 1,
      "name": "spruce_planks"
    },
    {
      "x": 5,
      "y": 0,
      "z": 1,
      "name": "spruce_planks"
    },
    {
      "x": 6,
      "y": 0,
      "z": 1,
      "name": "spruce_planks"
    },
    {
      "x": 7,
      "y": 0,
      "z": 1,
      "name": "spruce_planks"
    },
    {
      "x": 8,
      "y": 0,
      "z": 1,
      "name": "spruce_planks"
    },
    {
      "x": 0,
      "y": 0,
      "z": 2,
      "name": "spruce_planks"
    },
    {
      "x": 1,
      "y": 0,
      "z": 2,
      "name": "spruce_planks"
    },
    {
      "x": 2,
      "y": 0,
      "z": 2,
      "name": "spruce_planks"
    },
    {
      "x": 3,
      "y": 0,
      "z": 2,
      "name": "spruce_planks"
    },
    {
      "x": 4,
      "y": 0,
      "z": 2,
      "name": "spruce_planks"
    },
    {
      "x": 5,
      "y": 0,
      "z": 2,
      "name": "spruce_planks"
    },
    {
      "x": 6,
      "y": 0,
      "z": 2,
      "name": "spruce_planks"
    },
    {
      "x": 7,
      "y": 0,
      "z": 2,
      "name": "spruce_planks"
    },
    {
      "x": 8,
      "y": 0,
      "z": 2,
      "name": "spruce_planks"
    },
    {
      "x": 0,
      "y": 0,
      "z": 3,
      "name": "spruce_planks"
    },
    {
      "x": 1,
      "y": 0,
      "z": 3,
      "name": "spruce_planks"
    },
    {
      "x": 2,
      "y": 0,
      "z": 3,
      "name": "spruce_planks"
    },
    {
      "x": 3,
      "y": 0,
      "z": 3,
      "name": "spruce_planks"
    },
    {
      "x": 4,
      "y": 0,
      "z": 3,
      "name": "spruce_planks"
    },
    {
      "x": 5,
      "y": 0,
      "z": 3,
      "name": "spruce_planks"
    },
    {
      "x": 6,
      "y": 0,
      "z": 3,
      "name": "spruce_planks"
    },
    {
      "x": 7,
      "y": 0,
      "z": 3,
      "name": "spruce_planks"
    },
    {
      "x": 8,
      "y": 0,
      "z": 3,
      "name": "spruce_planks"
    },
    {
      "x": 0,
      "y": 0,
      "z": 4,
      "name": "spruce_planks"
    },
    {
      "x": 1,
      "y": 0,
      "z": 4,
      "name": "spruce_planks"
    },
    {
      "x": 2,
      "y": 0,
      "z": 4,
      "name": "spruce_planks"
    },
    {
      "x": 3,
      "y": 0,
      "z": 4,
      "name": "spruce_planks"
    },
    {
      "x": 4,
      "y": 0,
      "z": 4,
      "name": "spruce_planks"
    },
    {
      "x": 5,
      "y": 0,
      "z": 4,
      "name": "spruce_planks"
    },
    {
      "x": 6,
      "y": 0,
      "z": 4,
      "name": "spruce_planks"
    },
    {
      "x": 7,
      "y": 0,
      "z": 4,
      "name": "spruce_planks"
    },
    {
      "x": 8,
      "y": 0,
      "z": 4,
      "name": "spruce_planks"
    },
    {
      "x": 0,
      "y": 0,
      "z": 5,
      "name": "spruce_planks"
    },
    {
      "x": 1,
      "y": 0,
      "z": 5,
      "name": "spruce_planks"
    },
    {
      "x": 2,
      "y": 0,
      "z": 5,
      "name": "spruce_planks"
    },
    {
      "x": 3,
      "y": 0,
      "z": 5,
      "name": "spruce_planks"
    },
    {
      "x": 4,
      "y": 0,
      "z": 5,
      "name": "spruce_planks"
    },
    {
      "x": 5,
      "y": 0,
      "z": 5,
      "name": "spruce_planks"
    },
    {
      "x": 6,
      "y": 0,
      "z": 5,
      "name": "spruce_planks"
    },
    {
      "x": 7,
      "y": 0,
      "z": 5,
      "name": "spruce_planks"
    },
    {
      "x": 8,
      "y": 0,
      "z": 5,
      "name": "spruce_planks"
    },
    {
      "x": 0,
      "y": 0,
      "z": 6,
      "name": "spruce_planks"
    },
    {
      "x": 1,
      "y": 0,
      "z": 6,
      "name": "spruce_planks"
    },
    {
      "x": 2,
      "y": 0,
      "z": 6,
      "name": "spruce_planks"
    },
    {
      "x": 3,
      "y": 0,
      "z": 6,
      "name": "spruce_planks"
    },
    {
      "x": 4,
      "y": 0,
      "z": 6,
      "name": "spruce_planks"
    },
    {
      "x": 5,
      "y": 0,
      "z": 6,
      "name": "spruce_planks"
    },
    {
      "x": 6,
      "y": 0,
      "z": 6,
      "name": "spruce_planks"
    },
    {
      "x": 7,
      "y": 0,
      "z": 6,
      "name": "spruce_planks"
    },
    {
      "x": 8,
      "y": 0,
      "z": 6,
      "name": "spruce_planks"
    },
    {
      "x": 0,
      "y": 0,
      "z": 7,
      "name": "spruce_planks"
    },
    {
      "x": 1,
      "y": 0,
      "z": 7,
      "name": "spruce_planks"
    },
    {
      "x": 2,
      "y": 0,
      "z": 7,
      "name": "spruce_planks"
    },
    {
      "x": 3,
      "y": 0,
      "z": 7,
      "name": "spruce_planks"
    },
    {
      "x": 4,
      "y": 0,
      "z": 7,
      "name": "spruce_planks"
    },
    {
      "x": 5,
      "y": 0,
      "z": 7,
      "name": "spruce_planks"
    },
    {
      "x": 6,
      "y": 0,
      "z": 7,
      "name": "spruce_planks"
    },
    {
      "x": 7,
      "y": 0,
      "z": 7,
      "name": "spruce_planks"
    },
    {
      "x": 8,
      "y": 0,
      "z": 7,
      "name": "spruce_planks"
    },
    {
      "x": 0,
      "y": 1,
      "z": 0,
      "name": "dark_oak_log"
    },
    {
      "x": 1,
      "y": 1,
      "z": 0,
      "name": "cobblestone"
    },
    {
      "x": 2,
      "y": 1,
      "z": 0,
      "name": "cobblestone"
    },
    {
      "x": 3,
      "y": 1,
      "z": 0,
      "name": "cobblestone"
    },
    {
      "x": 4,
      "y": 1,
      "z": 0,
      "name": "spruce_door"
    },
    {
      "x": 5,
      "y": 1,
      "z": 0,
      "name": "cobblestone"
    },
    {
      "x": 6,
      "y": 1,
      "z": 0,
      "name": "cobblestone"
    },
    {
      "x": 7,
      "y": 1,
      "z": 0,
      "name": "cobblestone"
    },
    {
      "x": 8,
      "y": 1,
      "z": 0,
      "name": "dark_oak_log"
    },
    {
      "x": 0,
      "y": 1,
      "z": 1,
      "name": "cobblestone"
    },
    {
      "x": 1,
      "y": 1,
      "z": 1,
      "name": "crafting_table"
    },
    {
      "x": 7,
      "y": 1,
      "z": 1,
      "name": "furnace"
    },
    {
      "x": 8,
      "y": 1,
      "z": 1,
      "name": "cobblestone"
    },
    {
      "x": 0,
      "y": 1,
      "z": 2,
      "name": "cobblestone"
    },
    {
      "x": 8,
      "y": 1,
      "z": 2,
      "name": "cobblestone"
    },
    {
      "x": 0,
      "y": 1,
      "z": 3,
      "name": "cobblestone"
    },
    {
      "x": 8,
      "y": 1,
      "z": 3,
      "name": "cobblestone"
    },
    {
      "x": 0,
      "y": 1,
      "z": 4,
      "name": "cobblestone"
    },
    {
      "x": 8,
      "y": 1,
      "z": 4,
      "name": "cobblestone"
    },
    {
      "x": 0,
      "y": 1,
      "z": 5,
      "name": "cobblestone"
    },
    {
      "x": 8,
      "y": 1,
      "z": 5,
      "name": "cobblestone"
    },
    {
      "x": 0,
      "y": 1,
      "z": 6,
      "name": "cobblestone"
    },
    {
      "x": 7,
      "y": 1,
      "z": 6,
      "name": "chest"
    },
    {
      "x": 8,
      "y": 1,
      "z": 6,
      "name": "cobblestone"
    },
    {
      "x": 0,
      "y": 1,
      "z": 7,
      "name": "dark_oak_log"
    },
    {
      "x": 1,
      "y": 1,
      "z": 7,
      "name": "cobblestone"
    },
    {
      "x": 2,
      "y": 1,
      "z": 7,
      "name": "cobblestone"
    },
    {
      "x": 3,
      "y": 1,
      "z": 7,
      "name": "cobblestone"
    },
    {
      "x": 4,
      "y": 1,
      "z": 7,
      "name": "cobblestone"
    },
    {
      "x": 5,
      "y": 1,
      "z": 7,
      "name": "cobblestone"
    },
    {
      "x": 6,
      "y": 1,
      "z": 7,
      "name": "cobblestone"
    },
    {
      "x": 7,
      "y": 1,
      "z": 7,
      "name": "cobblestone"
    },
    {
      "x": 8,
      "y": 1,
      "z": 7,
      "name": "dark_oak_log"
    },
    {
      "x": 0,
      "y": 2,
      "z": 0,
      "name": "dark_oak_log"
    },
    {
      "x": 1,
      "y": 2,
      "z": 0,
      "name": "cobblestone"
    },
    {
      "x": 2,
      "y": 2,
      "z": 0,
      "name": "glass"
    },
    {
      "x": 3,
      "y": 2,
      "z": 0,
      "name": "cobblestone"
    },
    {
      "x": 5,
      "y": 2,
      "z": 0,
      "name": "cobblestone"
    },
    {
      "x": 6,
      "y": 2,
      "z": 0,
      "name": "glass"
    },
    {
      "x": 7,
      "y": 2,
      "z": 0,
      "name": "cobblestone"
    },
    {
      "x": 8,
      "y": 2,
      "z": 0,
      "name": "dark_oak_log"
    },
    {
      "x": 0,
      "y": 2,
      "z": 1,
      "name": "cobblestone"
    },
    {
      "x": 8,
      "y": 2,
      "z": 1,
      "name": "cobblestone"
    },
    {
      "x": 0,
      "y": 2,
      "z": 2,
      "name": "glass"
    },
    {
      "x": 8,
      "y": 2,
      "z": 2,
      "name": "glass"
    },
    {
      "x": 0,
      "y": 2,
      "z": 3,
      "name": "cobblestone"
    },
    {
      "x": 8,
      "y": 2,
      "z": 3,
      "name": "cobblestone"
    },
    {
      "x": 0,
      "y": 2,
      "z": 4,
      "name": "cobblestone"
    },
    {
      "x": 8,
      "y": 2,
      "z": 4,
      "name": "cobblestone"
    },
    {
      "x": 0,
      "y": 2,
      "z": 5,
      "name": "glass"
    },
    {
      "x": 8,
      "y": 2,
      "z": 5,
      "name": "glass"
    },
    {
      "x": 0,
      "y": 2,
      "z": 6,
      "name": "cobblestone"
    },
    {
      "x": 8,
      "y": 2,
      "z": 6,
      "name": "cobblestone"
    },
    {
      "x": 0,
      "y": 2,
      "z": 7,
      "name": "dark_oak_log"
    },
    {
      "x": 1,
      "y": 2,
      "z": 7,
      "name": "cobblestone"
    },
    {
      "x": 2,
      "y": 2,
      "z": 7,
      "name": "glass"
    },
    {
      "x": 3,
      "y": 2,
      "z": 7,
      "name": "cobblestone"
    },
    {
      "x": 4,
      "y": 2,
      "z": 7,
      "name": "cobblestone"
    },
    {
      "x": 5,
      "y": 2,
      "z": 7,
      "name": "cobblestone"
    },
    {
      "x": 6,
      "y": 2,
      "z": 7,
      "name": "glass"
    },
    {
      "x": 7,
      "y": 2,
      "z": 7,
      "name": "cobblestone"
    },
    {
      "x": 8,
      "y": 2,
      "z": 7,
      "name": "dark_oak_log"
    },
    {
      "x": 0,
      "y": 3,
      "z": 0,
      "name": "dark_oak_log"
    },
    {
      "x": 1,
      "y": 3,
      "z": 0,
      "name": "cobblestone"
    },
    {
      "x": 2,
      "y": 3,
      "z": 0,
      "name": "cobblestone"
    },
    {
      "x": 3,
      "y": 3,
      "z": 0,
      "name": "cobblestone"
    },
    {
      "x": 4,
      "y": 3,
      "z": 0,
      "name": "cobblestone"
    },
    {
      "x": 5,
      "y": 3,
      "z": 0,
      "name": "cobblestone"
    },
    {
      "x": 6,
      "y": 3,
      "z": 0,
      "name": "cobblestone"
    },
    {
      "x": 7,
      "y": 3,
      "z": 0,
      "name": "cobblestone"
    },
    {
      "x": 8,
      "y": 3,
      "z": 0,
      "name": "dark_oak_log"
    },
    {
      "x": 0,
      "y": 3,
      "z": 1,
      "name": "cobblestone"
    },
    {
      "x": 8,
      "y": 3,
      "z": 1,
      "name": "cobblestone"
    },
    {
      "x": 0,
      "y": 3,
      "z": 2,
      "name": "cobblestone"
    },
    {
      "x": 8,
      "y": 3,
      "z": 2,
      "name": "cobblestone"
    },
    {
      "x": 0,
      "y": 3,
      "z": 3,
      "name": "cobblestone"
    },
    {
      "x": 8,
      "y": 3,
      "z": 3,
      "name": "cobblestone"
    },
    {
      "x": 0,
      "y": 3,
      "z": 4,
      "name": "cobblestone"
    },
    {
      "x": 8,
      "y": 3,
      "z": 4,
      "name": "cobblestone"
    },
    {
      "x": 0,
      "y": 3,
      "z": 5,
      "name": "cobblestone"
    },
    {
      "x": 8,
      "y": 3,
      "z": 5,
      "name": "cobblestone"
    },
    {
      "x": 0,
      "y": 3,
      "z": 6,
      "name": "cobblestone"
    },
    {
      "x": 8,
      "y": 3,
      "z": 6,
      "name": "cobblestone"
    },
    {
      "x": 0,
      "y": 3,
      "z": 7,
      "name": "dark_oak_log"
    },
    {
      "x": 1,
      "y": 3,
      "z": 7,
      "name": "cobblestone"
    },
    {
      "x": 2,
      "y": 3,
      "z": 7,
      "name": "cobblestone"
    },
    {
      "x": 3,
      "y": 3,
      "z": 7,
      "name": "cobblestone"
    },
    {
      "x": 4,
      "y": 3,
      "z": 7,
      "name": "cobblestone"
    },
    {
      "x": 5,
      "y": 3,
      "z": 7,
      "name": "cobblestone"
    },
    {
      "x": 6,
      "y": 3,
      "z": 7,
      "name": "cobblestone"
    },
    {
      "x": 7,
      "y": 3,
      "z": 7,
      "name": "cobblestone"
    },
    {
      "x": 8,
      "y": 3,
      "z": 7,
      "name": "dark_oak_log"
    },
    {
      "x": 0,
      "y": 4,
      "z": 0,
      "name": "dark_oak_log"
    },
    {
      "x": 1,
      "y": 4,
      "z": 0,
      "name": "cobblestone"
    },
    {
      "x": 2,
      "y": 4,
      "z": 0,
      "name": "cobblestone"
    },
    {
      "x": 3,
      "y": 4,
      "z": 0,
      "name": "cobblestone"
    },
    {
      "x": 4,
      "y": 4,
      "z": 0,
      "name": "cobblestone"
    },
    {
      "x": 5,
      "y": 4,
      "z": 0,
      "name": "cobblestone"
    },
    {
      "x": 6,
      "y": 4,
      "z": 0,
      "name": "cobblestone"
    },
    {
      "x": 7,
      "y": 4,
      "z": 0,
      "name": "cobblestone"
    },
    {
      "x": 8,
      "y": 4,
      "z": 0,
      "name": "dark_oak_log"
    },
    {
      "x": 0,
      "y": 4,
      "z": 1,
      "name": "cobblestone"
    },
    {
      "x": 8,
      "y": 4,
      "z": 1,
      "name": "cobblestone"
    },
    {
      "x": 0,
      "y": 4,
      "z": 2,
      "name": "cobblestone"
    },
    {
      "x": 8,
      "y": 4,
      "z": 2,
      "name": "cobblestone"
    },
    {
      "x": 0,
      "y": 4,
      "z": 3,
      "name": "cobblestone"
    },
    {
      "x": 8,
      "y": 4,
      "z": 3,
      "name": "cobblestone"
    },
    {
      "x": 0,
      "y": 4,
      "z": 4,
      "name": "cobblestone"
    },
    {
      "x": 8,
      "y": 4,
      "z": 4,
      "name": "cobblestone"
    },
    {
      "x": 0,
      "y": 4,
      "z": 5,
      "name": "cobblestone"
    },
    {
      "x": 8,
      "y": 4,
      "z": 5,
      "name": "cobblestone"
    },
    {
      "x": 0,
      "y": 4,
      "z": 6,
      "name": "cobblestone"
    },
    {
      "x": 8,
      "y": 4,
      "z": 6,
      "name": "cobblestone"
    },
    {
      "x": 0,
      "y": 4,
      "z": 7,
      "name": "dark_oak_log"
    },
    {
      "x": 1,
      "y": 4,
      "z": 7,
      "name": "cobblestone"
    },
    {
      "x": 2,
      "y": 4,
      "z": 7,
      "name": "cobblestone"
    },
    {
      "x": 3,
      "y": 4,
      "z": 7,
      "name": "cobblestone"
    },
    {
      "x": 4,
      "y": 4,
      "z": 7,
      "name": "cobblestone"
    },
    {
      "x": 5,
      "y": 4,
      "z": 7,
      "name": "cobblestone"
    },
    {
      "x": 6,
      "y": 4,
      "z": 7,
      "name": "cobblestone"
    },
    {
      "x": 7,
      "y": 4,
      "z": 7,
      "name": "cobblestone"
    },
    {
      "x": 8,
      "y": 4,
      "z": 7,
      "name": "dark_oak_log"
    },
    {
      "x": 0,
      "y": 5,
      "z": 0,
      "name": "dark_oak_log"
    },
    {
      "x": 1,
      "y": 5,
      "z": 0,
      "name": "cobblestone"
    },
    {
      "x": 2,
      "y": 5,
      "z": 0,
      "name": "cobblestone"
    },
    {
      "x": 3,
      "y": 5,
      "z": 0,
      "name": "cobblestone"
    },
    {
      "x": 4,
      "y": 5,
      "z": 0,
      "name": "cobblestone"
    },
    {
      "x": 5,
      "y": 5,
      "z": 0,
      "name": "cobblestone"
    },
    {
      "x": 6,
      "y": 5,
      "z": 0,
      "name": "cobblestone"
    },
    {
      "x": 7,
      "y": 5,
      "z": 0,
      "name": "cobblestone"
    },
    {
      "x": 8,
      "y": 5,
      "z": 0,
      "name": "dark_oak_log"
    },
    {
      "x": 0,
      "y": 5,
      "z": 1,
      "name": "cobblestone"
    },
    {
      "x": 8,
      "y": 5,
      "z": 1,
      "name": "cobblestone"
    },
    {
      "x": 0,
      "y": 5,
      "z": 2,
      "name": "cobblestone"
    },
    {
      "x": 8,
      "y": 5,
      "z": 2,
      "name": "cobblestone"
    },
    {
      "x": 0,
      "y": 5,
      "z": 3,
      "name": "cobblestone"
    },
    {
      "x": 8,
      "y": 5,
      "z": 3,
      "name": "cobblestone"
    },
    {
      "x": 0,
      "y": 5,
      "z": 4,
      "name": "cobblestone"
    },
    {
      "x": 8,
      "y": 5,
      "z": 4,
      "name": "cobblestone"
    },
    {
      "x": 0,
      "y": 5,
      "z": 5,
      "name": "cobblestone"
    },
    {
      "x": 8,
      "y": 5,
      "z": 5,
      "name": "cobblestone"
    },
    {
      "x": 0,
      "y": 5,
      "z": 6,
      "name": "cobblestone"
    },
    {
      "x": 8,
      "y": 5,
      "z": 6,
      "name": "cobblestone"
    },
    {
      "x": 0,
      "y": 5,
      "z": 7,
      "name": "dark_oak_log"
    },
    {
      "x": 1,
      "y": 5,
      "z": 7,
      "name": "cobblestone"
    },
    {
      "x": 2,
      "y": 5,
      "z": 7,
      "name": "cobblestone"
    },
    {
      "x": 3,
      "y": 5,
      "z": 7,
      "name": "cobblestone"
    },
    {
      "x": 4,
      "y": 5,
      "z": 7,
      "name": "cobblestone"
    },
    {
      "x": 5,
      "y": 5,
      "z": 7,
      "name": "cobblestone"
    },
    {
      "x": 6,
      "y": 5,
      "z": 7,
      "name": "cobblestone"
    },
    {
      "x": 7,
      "y": 5,
      "z": 7,
      "name": "cobblestone"
    },
    {
      "x": 8,
      "y": 5,
      "z": 7,
      "name": "dark_oak_log"
    },
    {
      "x": 0,
      "y": 6,
      "z": 0,
      "name": "dark_oak_planks"
    },
    {
      "x": 1,
      "y": 6,
      "z": 0,
      "name": "dark_oak_planks"
    },
    {
      "x": 2,
      "y": 6,
      "z": 0,
      "name": "dark_oak_planks"
    },
    {
      "x": 3,
      "y": 6,
      "z": 0,
      "name": "dark_oak_planks"
    },
    {
      "x": 4,
      "y": 6,
      "z": 0,
      "name": "dark_oak_planks"
    },
    {
      "x": 5,
      "y": 6,
      "z": 0,
      "name": "dark_oak_planks"
    },
    {
      "x": 6,
      "y": 6,
      "z": 0,
      "name": "dark_oak_planks"
    },
    {
      "x": 7,
      "y": 6,
      "z": 0,
      "name": "dark_oak_planks"
    },
    {
      "x": 8,
      "y": 6,
      "z": 0,
      "name": "dark_oak_planks"
    },
    {
      "x": 7,
      "y": 6,
      "z": 6,
      "name": "bricks"
    },
    {
      "x": 0,
      "y": 6,
      "z": 7,
      "name": "dark_oak_planks"
    },
    {
      "x": 1,
      "y": 6,
      "z": 7,
      "name": "dark_oak_planks"
    },
    {
      "x": 2,
      "y": 6,
      "z": 7,
      "name": "dark_oak_planks"
    },
    {
      "x": 3,
      "y": 6,
      "z": 7,
      "name": "dark_oak_planks"
    },
    {
      "x": 4,
      "y": 6,
      "z": 7,
      "name": "dark_oak_planks"
    },
    {
      "x": 5,
      "y": 6,
      "z": 7,
      "name": "dark_oak_planks"
    },
    {
      "x": 6,
      "y": 6,
      "z": 7,
      "name": "dark_oak_planks"
    },
    {
      "x": 7,
      "y": 6,
      "z": 7,
      "name": "dark_oak_planks"
    },
    {
      "x": 8,
      "y": 6,
      "z": 7,
      "name": "dark_oak_planks"
    },
    {
      "x": 0,
      "y": 7,
      "z": 1,
      "name": "dark_oak_planks"
    },
    {
      "x": 1,
      "y": 7,
      "z": 1,
      "name": "dark_oak_planks"
    },
    {
      "x": 2,
      "y": 7,
      "z": 1,
      "name": "dark_oak_planks"
    },
    {
      "x": 3,
      "y": 7,
      "z": 1,
      "name": "dark_oak_planks"
    },
    {
      "x": 4,
      "y": 7,
      "z": 1,
      "name": "dark_oak_planks"
    },
    {
      "x": 5,
      "y": 7,
      "z": 1,
      "name": "dark_oak_planks"
    },
    {
      "x": 6,
      "y": 7,
      "z": 1,
      "name": "dark_oak_planks"
    },
    {
      "x": 7,
      "y": 7,
      "z": 1,
      "name": "dark_oak_planks"
    },
    {
      "x": 8,
      "y": 7,
      "z": 1,
      "name": "dark_oak_planks"
    },
    {
      "x": 0,
      "y": 7,
      "z": 6,
      "name": "dark_oak_planks"
    },
    {
      "x": 1,
      "y": 7,
      "z": 6,
      "name": "dark_oak_planks"
    },
    {
      "x": 2,
      "y": 7,
      "z": 6,
      "name": "dark_oak_planks"
    },
    {
      "x": 3,
      "y": 7,
      "z": 6,
      "name": "dark_oak_planks"
    },
    {
      "x": 4,
      "y": 7,
      "z": 6,
      "name": "dark_oak_planks"
    },
    {
      "x": 5,
      "y": 7,
      "z": 6,
      "name": "dark_oak_planks"
    },
    {
      "x": 6,
      "y": 7,
      "z": 6,
      "name": "dark_oak_planks"
    },
    {
      "x": 7,
      "y": 7,
      "z": 6,
      "name": "bricks"
    },
    {
      "x": 8,
      "y": 7,
      "z": 6,
      "name": "dark_oak_planks"
    },
    {
      "x": 0,
      "y": 8,
      "z": 2,
      "name": "dark_oak_planks"
    },
    {
      "x": 1,
      "y": 8,
      "z": 2,
      "name": "dark_oak_planks"
    },
    {
      "x": 2,
      "y": 8,
      "z": 2,
      "name": "dark_oak_planks"
    },
    {
      "x": 3,
      "y": 8,
      "z": 2,
      "name": "dark_oak_planks"
    },
    {
      "x": 4,
      "y": 8,
      "z": 2,
      "name": "dark_oak_planks"
    },
    {
      "x": 5,
      "y": 8,
      "z": 2,
      "name": "dark_oak_planks"
    },
    {
      "x": 6,
      "y": 8,
      "z": 2,
      "name": "dark_oak_planks"
    },
    {
      "x": 7,
      "y": 8,
      "z": 2,
      "name": "dark_oak_planks"
    },
    {
      "x": 8,
      "y": 8,
      "z": 2,
      "name": "dark_oak_planks"
    },
    {
      "x": 0,
      "y": 8,
      "z": 5,
      "name": "dark_oak_planks"
    },
    {
      "x": 1,
      "y": 8,
      "z": 5,
      "name": "dark_oak_planks"
    },
    {
      "x": 2,
      "y": 8,
      "z": 5,
      "name": "dark_oak_planks"
    },
    {
      "x": 3,
      "y": 8,
      "z": 5,
      "name": "dark_oak_planks"
    },
    {
      "x": 4,
      "y": 8,
      "z": 5,
      "name": "dark_oak_planks"
    },
    {
      "x": 5,
      "y": 8,
      "z": 5,
      "name": "dark_oak_planks"
    },
    {
      "x": 6,
      "y": 8,
      "z": 5,
      "name": "dark_oak_planks"
    },
    {
      "x": 7,
      "y": 8,
      "z": 5,
      "name": "dark_oak_planks"
    },
    {
      "x": 8,
      "y": 8,
      "z": 5,
      "name": "dark_oak_planks"
    },
    {
      "x": 7,
      "y": 8,
      "z": 6,
      "name": "bricks"
    },
    {
      "x": 0,
      "y": 9,
      "z": 3,
      "name": "dark_oak_planks"
    },
    {
      "x": 1,
      "y": 9,
      "z": 3,
      "name": "dark_oak_planks"
    },
    {
      "x": 2,
      "y": 9,
      "z": 3,
      "name": "dark_oak_planks"
    },
    {
      "x": 3,
      "y": 9,
      "z": 3,
      "name": "dark_oak_planks"
    },
    {
      "x": 4,
      "y": 9,
      "z": 3,
      "name": "dark_oak_planks"
    },
    {
      "x": 5,
      "y": 9,
      "z": 3,
      "name": "dark_oak_planks"
    },
    {
      "x": 6,
      "y": 9,
      "z": 3,
      "name": "dark_oak_planks"
    },
    {
      "x": 7,
      "y": 9,
      "z": 3,
      "name": "dark_oak_planks"
    },
    {
      "x": 8,
      "y": 9,
      "z": 3,
      "name": "dark_oak_planks"
    },
    {
      "x": 0,
      "y": 9,
      "z": 4,
      "name": "dark_oak_planks"
    },
    {
      "x": 1,
      "y": 9,
      "z": 4,
      "name": "dark_oak_planks"
    },
    {
      "x": 2,
      "y": 9,
      "z": 4,
      "name": "dark_oak_planks"
    },
    {
      "x": 3,
      "y": 9,
      "z": 4,
      "name": "dark_oak_planks"
    },
    {
      "x": 4,
      "y": 9,
      "z": 4,
      "name": "dark_oak_planks"
    },
    {
      "x": 5,
      "y": 9,
      "z": 4,
      "name": "dark_oak_planks"
    },
    {
      "x": 6,
      "y": 9,
      "z": 4,
      "name": "dark_oak_planks"
    },
    {
      "x": 7,
      "y": 9,
      "z": 4,
      "name": "dark_oak_planks"
    },
    {
      "x": 8,
      "y": 9,
      "z": 4,
      "name": "dark_oak_planks"
    },
    {
      "x": 7,
      "y": 9,
      "z": 6,
      "name": "bricks"
    },
    {
      "x": 7,
      "y": 10,
      "z": 6,
      "name": "bricks"
    }
  ]
}
