{
  "_opis": "Odprta moderna hisa z veliko stekla in ravno streho.",
  "_category": "modern",
  "_kind": "building",
  "_aliases": [
    "steklena hisa",
    "glass house"
  ],
  "size": [
    11,
    7,
    8
  ],
  "blocks": [
    {
      "x": 0,
      "y": 0,
      "z": 0,
      "name": "smooth_stone"
    },
    {
      "x": 1,
      "y": 0,
      "z": 0,
      "name": "smooth_stone"
    },
    {
      "x": 2,
      "y": 0,
      "z": 0,
      "name": "smooth_stone"
    },
    {
      "x": 3,
      "y": 0,
      "z": 0,
      "name": "smooth_stone"
    },
    {
      "x": 4,
      "y": 0,
      "z": 0,
      "name": "smooth_stone"
    },
    {
      "x": 5,
      "y": 0,
      "z": 0,
      "name": "smooth_stone"
    },
    {
      "x": 6,
      "y": 0,
      "z": 0,
      "name": "smooth_stone"
    },
    {
      "x": 7,
      "y": 0,
      "z": 0,
      "name": "smooth_stone"
    },
    {
      "x": 8,
      "y": 0,
      "z": 0,
      "name": "smooth_stone"
    },
    {
      "x": 9,
      "y": 0,
      "z": 0,
      "name": "smooth_stone"
    },
    {
      "x": 10,
      "y": 0,
      "z": 0,
      "name": "smooth_stone"
    },
    {
      "x": 0,
      "y": 0,
      "z": 1,
      "name": "smooth_stone"
    },
    {
      "x": 1,
      "y": 0,
      "z": 1,
      "name": "smooth_stone"
    },
    {
      "x": 2,
      "y": 0,
      "z": 1,
      "name": "smooth_stone"
    },
    {
      "x": 3,
      "y": 0,
      "z": 1,
      "name": "smooth_stone"
    },
    {
      "x": 4,
      "y": 0,
      "z": 1,
      "name": "smooth_stone"
    },
    {
      "x": 5,
      "y": 0,
      "z": 1,
      "name": "smooth_stone"
    },
    {
      "x": 6,
      "y": 0,
      "z": 1,
      "name": "smooth_stone"
    },
    {
      "x": 7,
      "y": 0,
      "z": 1,
      "name": "smooth_stone"
    },
    {
      "x": 8,
      "y": 0,
      "z": 1,
      "name": "smooth_stone"
    },
    {
      "x": 9,
      "y": 0,
      "z": 1,
      "name": "smooth_stone"
    },
    {
      "x": 10,
      "y": 0,
      "z": 1,
      "name": "smooth_stone"
    },
    {
      "x": 0,
      "y": 0,
      "z": 2,
      "name": "smooth_stone"
    },
    {
      "x": 1,
      "y": 0,
      "z": 2,
      "name": "smooth_stone"
    },
    {
      "x": 2,
      "y": 0,
      "z": 2,
      "name": "smooth_stone"
    },
    {
      "x": 3,
      "y": 0,
      "z": 2,
      "name": "smooth_stone"
    },
    {
      "x": 4,
      "y": 0,
      "z": 2,
      "name": "smooth_stone"
    },
    {
      "x": 5,
      "y": 0,
      "z": 2,
      "name": "smooth_stone"
    },
    {
      "x": 6,
      "y": 0,
      "z": 2,
      "name": "smooth_stone"
    },
    {
      "x": 7,
      "y": 0,
      "z": 2,
      "name": "smooth_stone"
    },
    {
      "x": 8,
      "y": 0,
      "z": 2,
      "name": "smooth_stone"
    },
    {
      "x": 9,
      "y": 0,
      "z": 2,
      "name": "smooth_stone"
    },
    {
      "x": 10,
      "y": 0,
      "z": 2,
      "name": "smooth_stone"
    },
    {
      "x": 0,
      "y": 0,
      "z": 3,
      "name": "smooth_stone"
    },
    {
      "x": 1,
      "y": 0,
      "z": 3,
      "name": "smooth_stone"
    },
    {
      "x": 2,
      "y": 0,
      "z": 3,
      "name": "smooth_stone"
    },
    {
      "x": 3,
      "y": 0,
      "z": 3,
      "name": "smooth_stone"
    },
    {
      "x": 4,
      "y": 0,
      "z": 3,
      "name": "smooth_stone"
    },
    {
      "x": 5,
      "y": 0,
      "z": 3,
      "name": "smooth_stone"
    },
    {
      "x": 6,
      "y": 0,
      "z": 3,
      "name": "smooth_stone"
    },
    {
      "x": 7,
      "y": 0,
      "z": 3,
      "name": "smooth_stone"
    },
    {
      "x": 8,
      "y": 0,
      "z": 3,
      "name": "smooth_stone"
    },
    {
      "x": 9,
      "y": 0,
      "z": 3,
      "name": "smooth_stone"
    },
    {
      "x": 10,
      "y": 0,
      "z": 3,
      "name": "smooth_stone"
    },
    {
      "x": 0,
      "y": 0,
      "z": 4,
      "name": "smooth_stone"
    },
    {
      "x": 1,
      "y": 0,
      "z": 4,
      "name": "smooth_stone"
    },
    {
      "x": 2,
      "y": 0,
      "z": 4,
      "name": "smooth_stone"
    },
    {
      "x": 3,
      "y": 0,
      "z": 4,
      "name": "smooth_stone"
    },
    {
      "x": 4,
      "y": 0,
      "z": 4,
      "name": "smooth_stone"
    },
    {
      "x": 5,
      "y": 0,
      "z": 4,
      "name": "smooth_stone"
    },
    {
      "x": 6,
      "y": 0,
      "z": 4,
      "name": "smooth_stone"
    },
    {
      "x": 7,
      "y": 0,
      "z": 4,
      "name": "smooth_stone"
    },
    {
      "x": 8,
      "y": 0,
      "z": 4,
      "name": "smooth_stone"
    },
    {
      "x": 9,
      "y": 0,
      "z": 4,
      "name": "smooth_stone"
    },
    {
      "x": 10,
      "y": 0,
      "z": 4,
      "name": "smooth_stone"
    },
    {
      "x": 0,
      "y": 0,
      "z": 5,
      "name": "smooth_stone"
    },
    {
      "x": 1,
      "y": 0,
      "z": 5,
      "name": "smooth_stone"
    },
    {
      "x": 2,
      "y": 0,
      "z": 5,
      "name": "smooth_stone"
    },
    {
      "x": 3,
      "y": 0,
      "z": 5,
      "name": "smooth_stone"
    },
    {
      "x": 4,
      "y": 0,
      "z": 5,
      "name": "smooth_stone"
    },
    {
      "x": 5,
      "y": 0,
      "z": 5,
      "name": "smooth_stone"
    },
    {
      "x": 6,
      "y": 0,
      "z": 5,
      "name": "smooth_stone"
    },
    {
      "x": 7,
      "y": 0,
      "z": 5,
      "name": "smooth_stone"
    },
    {
      "x": 8,
      "y": 0,
      "z": 5,
      "name": "smooth_stone"
    },
    {
      "x": 9,
      "y": 0,
      "z": 5,
      "name": "smooth_stone"
    },
    {
      "x": 10,
      "y": 0,
      "z": 5,
      "name": "smooth_stone"
    },
    {
      "x": 0,
      "y": 0,
      "z": 6,
      "name": "smooth_stone"
    },
    {
      "x": 1,
      "y": 0,
      "z": 6,
      "name": "smooth_stone"
    },
    {
      "x": 2,
      "y": 0,
      "z": 6,
      "name": "smooth_stone"
    },
    {
      "x": 3,
      "y": 0,
      "z": 6,
      "name": "smooth_stone"
    },
    {
      "x": 4,
      "y": 0,
      "z": 6,
      "name": "smooth_stone"
    },
    {
      "x": 5,
      "y": 0,
      "z": 6,
      "name": "smooth_stone"
    },
    {
      "x": 6,
      "y": 0,
      "z": 6,
      "name": "smooth_stone"
    },
    {
      "x": 7,
      "y": 0,
      "z": 6,
      "name": "smooth_stone"
    },
    {
      "x": 8,
      "y": 0,
      "z": 6,
      "name": "smooth_stone"
    },
    {
      "x": 9,
      "y": 0,
      "z": 6,
      "name": "smooth_stone"
    },
    {
      "x": 10,
      "y": 0,
      "z": 6,
      "name": "smooth_stone"
    },
    {
      "x": 0,
      "y": 0,
      "z": 7,
      "name": "smooth_stone"
    },
    {
      "x": 1,
      "y": 0,
      "z": 7,
      "name": "smooth_stone"
    },
    {
      "x": 2,
      "y": 0,
      "z": 7,
      "name": "smooth_stone"
    },
    {
      "x": 3,
      "y": 0,
      "z": 7,
      "name": "smooth_stone"
    },
    {
      "x": 4,
      "y": 0,
      "z": 7,
      "name": "smooth_stone"
    },
    {
      "x": 5,
      "y": 0,
      "z": 7,
      "name": "smooth_stone"
    },
    {
      "x": 6,
      "y": 0,
      "z": 7,
      "name": "smooth_stone"
    },
    {
      "x": 7,
      "y": 0,
      "z": 7,
      "name": "smooth_stone"
    },
    {
      "x": 8,
      "y": 0,
      "z": 7,
      "name": "smooth_stone"
    },
    {
      "x": 9,
      "y": 0,
      "z": 7,
      "name": "smooth_stone"
    },
    {
      "x": 10,
      "y": 0,
      "z": 7,
      "name": "smooth_stone"
    },
    {
      "x": 0,
      "y": 1,
      "z": 0,
      "name": "black_concrete"
    },
    {
      "x": 1,
      "y": 1,
      "z": 0,
      "name": "white_concrete"
    },
    {
      "x": 2,
      "y": 1,
      "z": 0,
      "name": "white_concrete"
    },
    {
      "x": 3,
      "y": 1,
      "z": 0,
      "name": "white_concrete"
    },
    {
      "x": 4,
      "y": 1,
      "z": 0,
      "name": "white_concrete"
    },
    {
      "x": 5,
      "y": 1,
      "z": 0,
      "name": "birch_door"
    },
    {
      "x": 6,
      "y": 1,
      "z": 0,
      "name": "white_concrete"
    },
    {
      "x": 7,
      "y": 1,
      "z": 0,
      "name": "white_concrete"
    },
    {
      "x": 8,
      "y": 1,
      "z": 0,
      "name": "white_concrete"
    },
    {
      "x": 9,
      "y": 1,
      "z": 0,
      "name": "white_concrete"
    },
    {
      "x": 10,
      "y": 1,
      "z": 0,
      "name": "black_concrete"
    },
    {
      "x": 0,
      "y": 1,
      "z": 1,
      "name": "white_concrete"
    },
    {
      "x": 1,
      "y": 1,
      "z": 1,
      "name": "crafting_table"
    },
    {
      "x": 9,
      "y": 1,
      "z": 1,
      "name": "furnace"
    },
    {
      "x": 10,
      "y": 1,
      "z": 1,
      "name": "white_concrete"
    },
    {
      "x": 0,
      "y": 1,
      "z": 2,
      "name": "white_concrete"
    },
    {
      "x": 10,
      "y": 1,
      "z": 2,
      "name": "white_concrete"
    },
    {
      "x": 0,
      "y": 1,
      "z": 3,
      "name": "white_concrete"
    },
    {
      "x": 10,
      "y": 1,
      "z": 3,
      "name": "white_concrete"
    },
    {
      "x": 0,
      "y": 1,
      "z": 4,
      "name": "white_concrete"
    },
    {
      "x": 10,
      "y": 1,
      "z": 4,
      "name": "white_concrete"
    },
    {
      "x": 0,
      "y": 1,
      "z": 5,
      "name": "white_concrete"
    },
    {
      "x": 10,
      "y": 1,
      "z": 5,
      "name": "white_concrete"
    },
    {
      "x": 0,
      "y": 1,
      "z": 6,
      "name": "white_concrete"
    },
    {
      "x": 9,
      "y": 1,
      "z": 6,
      "name": "chest"
    },
    {
      "x": 10,
      "y": 1,
      "z": 6,
      "name": "white_concrete"
    },
    {
      "x": 0,
      "y": 1,
      "z": 7,
      "name": "black_concrete"
    },
    {
      "x": 1,
      "y": 1,
      "z": 7,
      "name": "white_concrete"
    },
    {
      "x": 2,
      "y": 1,
      "z": 7,
      "name": "white_concrete"
    },
    {
      "x": 3,
      "y": 1,
      "z": 7,
      "name": "white_concrete"
    },
    {
      "x": 4,
      "y": 1,
      "z": 7,
      "name": "white_concrete"
    },
    {
      "x": 5,
      "y": 1,
      "z": 7,
      "name": "white_concrete"
    },
    {
      "x": 6,
      "y": 1,
      "z": 7,
      "name": "white_concrete"
    },
    {
      "x": 7,
      "y": 1,
      "z": 7,
      "name": "white_concrete"
    },
    {
      "x": 8,
      "y": 1,
      "z": 7,
      "name": "white_concrete"
    },
    {
      "x": 9,
      "y": 1,
      "z": 7,
      "name": "white_concrete"
    },
    {
      "x": 10,
      "y": 1,
      "z": 7,
      "name": "black_concrete"
    },
    {
      "x": 0,
      "y": 2,
      "z": 0,
      "name": "black_concrete"
    },
    {
      "x": 1,
      "y": 2,
      "z": 0,
      "name": "white_concrete"
    },
    {
      "x": 2,
      "y": 2,
      "z": 0,
      "name": "light_blue_stained_glass"
    },
    {
      "x": 3,
      "y": 2,
      "z": 0,
      "name": "light_blue_stained_glass"
    },
    {
      "x": 4,
      "y": 2,
      "z": 0,
      "name": "light_blue_stained_glass"
    },
    {
      "x": 6,
      "y": 2,
      "z": 0,
      "name": "light_blue_stained_glass"
    },
    {
      "x": 7,
      "y": 2,
      "z": 0,
      "name": "light_blue_stained_glass"
    },
    {
      "x": 8,
      "y": 2,
      "z": 0,
      "name": "light_blue_stained_glass"
    },
    {
      "x": 9,
      "y": 2,
      "z": 0,
      "name": "white_concrete"
    },
    {
      "x": 10,
      "y": 2,
      "z": 0,
      "name": "black_concrete"
    },
    {
      "x": 0,
      "y": 2,
      "z": 1,
      "name": "white_concrete"
    },
    {
      "x": 10,
      "y": 2,
      "z": 1,
      "name": "white_concrete"
    },
    {
      "x": 0,
      "y": 2,
      "z": 2,
      "name": "light_blue_stained_glass"
    },
    {
      "x": 10,
      "y": 2,
      "z": 2,
      "name": "light_blue_stained_glass"
    },
    {
      "x": 0,
      "y": 2,
      "z": 3,
      "name": "white_concrete"
    },
    {
      "x": 10,
      "y": 2,
      "z": 3,
      "name": "white_concrete"
    },
    {
      "x": 0,
      "y": 2,
      "z": 4,
      "name": "white_concrete"
    },
    {
      "x": 10,
      "y": 2,
      "z": 4,
      "name": "white_concrete"
    },
    {
      "x": 0,
      "y": 2,
      "z": 5,
      "name": "light_blue_stained_glass"
    },
    {
      "x": 10,
      "y": 2,
      "z": 5,
      "name": "light_blue_stained_glass"
    },
    {
      "x": 0,
      "y": 2,
      "z": 6,
      "name": "white_concrete"
    },
    {
      "x": 10,
      "y": 2,
      "z": 6,
      "name": "white_concrete"
    },
    {
      "x": 0,
      "y": 2,
      "z": 7,
      "name": "black_concrete"
    },
    {
      "x": 1,
      "y": 2,
      "z": 7,
      "name": "light_blue_stained_glass"
    },
    {
      "x": 2,
      "y": 2,
      "z": 7,
      "name": "light_blue_stained_glass"
    },
    {
      "x": 3,
      "y": 2,
      "z": 7,
      "name": "light_blue_stained_glass"
    },
    {
      "x": 4,
      "y": 2,
      "z": 7,
      "name": "light_blue_stained_glass"
    },
    {
      "x": 5,
      "y": 2,
      "z": 7,
      "name": "light_blue_stained_glass"
    },
    {
      "x": 6,
      "y": 2,
      "z": 7,
      "name": "light_blue_stained_glass"
    },
    {
      "x": 7,
      "y": 2,
      "z": 7,
      "name": "light_blue_stained_glass"
    },
    {
      "x": 8,
      "y": 2,
      "z": 7,
      "name": "light_blue_stained_glass"
    },
    {
      "x": 9,
      "y": 2,
      "z": 7,
      "name": "light_blue_stained_glass"
    },
    {
      "x": 10,
      "y": 2,
      "z": 7,
      "name": "black_concrete"
    },
    {
      "x": 0,
      "y": 3,
      "z": 0,
      "name": "black_concrete"
    },
    {
      "x": 1,
      "y": 3,
      "z": 0,
      "name": "white_concrete"
    },
    {
      "x": 2,
      "y": 3,
      "z": 0,
      "name": "light_blue_stained_glass"
    },
    {
      "x": 3,
      "y": 3,
      "z": 0,
      "name": "light_blue_stained_glass"
    },
    {
      "x": 4,
      "y": 3,
      "z": 0,
      "name": "light_blue_stained_glass"
    },
    {
      "x": 5,
      "y": 3,
      "z": 0,
      "name": "light_blue_stained_glass"
    },
    {
      "x": 6,
      "y": 3,
      "z": 0,
      "name": "light_blue_stained_glass"
    },
    {
      "x": 7,
      "y": 3,
      "z": 0,
      "name": "light_blue_stained_glass"
    },
    {
      "x": 8,
      "y": 3,
      "z": 0,
      "name": "light_blue_stained_glass"
    },
    {
      "x": 9,
      "y": 3,
      "z": 0,
      "name": "white_concrete"
    },
    {
      "x": 10,
      "y": 3,
      "z": 0,
      "name": "black_concrete"
    },
    {
      "x": 0,
      "y": 3,
      "z": 1,
      "name": "white_concrete"
    },
    {
      "x": 10,
      "y": 3,
      "z": 1,
      "name": "white_concrete"
    },
    {
      "x": 0,
      "y": 3,
      "z": 2,
      "name": "white_concrete"
    },
    {
      "x": 10,
      "y": 3,
      "z": 2,
      "name": "white_concrete"
    },
    {
      "x": 0,
      "y": 3,
      "z": 3,
      "name": "white_concrete"
    },
    {
      "x": 10,
      "y": 3,
      "z": 3,
      "name": "white_concrete"
    },
    {
      "x": 0,
      "y": 3,
      "z": 4,
      "name": "white_concrete"
    },
    {
      "x": 10,
      "y": 3,
      "z": 4,
      "name": "white_concrete"
    },
    {
      "x": 0,
      "y": 3,
      "z": 5,
      "name": "white_concrete"
    },
    {
      "x": 10,
      "y": 3,
      "z": 5,
      "name": "white_concrete"
    },
    {
      "x": 0,
      "y": 3,
      "z": 6,
      "name": "white_concrete"
    },
    {
      "x": 10,
      "y": 3,
      "z": 6,
      "name": "white_concrete"
    },
    {
      "x": 0,
      "y": 3,
      "z": 7,
      "name": "black_concrete"
    },
    {
      "x": 1,
      "y": 3,
      "z": 7,
      "name": "light_blue_stained_glass"
    },
    {
      "x": 2,
      "y": 3,
      "z": 7,
      "name": "light_blue_stained_glass"
    },
    {
      "x": 3,
      "y": 3,
      "z": 7,
      "name": "light_blue_stained_glass"
    },
    {
      "x": 4,
      "y": 3,
      "z": 7,
      "name": "light_blue_stained_glass"
    },
    {
      "x": 5,
      "y": 3,
      "z": 7,
      "name": "light_blue_stained_glass"
    },
    {
      "x": 6,
      "y": 3,
      "z": 7,
      "name": "light_blue_stained_glass"
    },
    {
      "x": 7,
      "y": 3,
      "z": 7,
      "name": "light_blue_stained_glass"
    },
    {
      "x": 8,
      "y": 3,
      "z": 7,
      "name": "light_blue_stained_glass"
    },
    {
      "x": 9,
      "y": 3,
      "z": 7,
      "name": "light_blue_stained_glass"
    },
    {
      "x": 10,
      "y": 3,
      "z": 7,
      "name": "black_concrete"
    },
    {
      "x": 0,
      "y": 4,
      "z": 0,
      "name": "black_concrete"
    },
    {
      "x": 1,
      "y": 4,
      "z": 0,
      "name": "white_concrete"
    },
    {
      "x": 2,
      "y": 4,
      "z": 0,
      "name": "white_concrete"
    },
    {
      "x": 3,
      "y": 4,
      "z": 0,
      "name": "white_concrete"
    },
    {
      "x": 4,
      "y": 4,
      "z": 0,
      "name": "white_concrete"
    },
    {
      "x": 5,
      "y": 4,
      "z": 0,
      "name": "white_concrete"
    },
    {
      "x": 6,
      "y": 4,
      "z": 0,
      "name": "white_concrete"
    },
    {
      "x": 7,
      "y": 4,
      "z": 0,
      "name": "white_concrete"
    },
    {
      "x": 8,
      "y": 4,
      "z": 0,
      "name": "white_concrete"
    },
    {
      "x": 9,
      "y": 4,
      "z": 0,
      "name": "white_concrete"
    },
    {
      "x": 10,
      "y": 4,
      "z": 0,
      "name": "black_concrete"
    },
    {
      "x": 0,
      "y": 4,
      "z": 1,
      "name": "white_concrete"
    },
    {
      "x": 10,
      "y": 4,
      "z": 1,
      "name": "white_concrete"
    },
    {
      "x": 0,
      "y": 4,
      "z": 2,
      "name": "white_concrete"
    },
    {
      "x": 10,
      "y": 4,
      "z": 2,
      "name": "white_concrete"
    },
    {
      "x": 0,
      "y": 4,
      "z": 3,
      "name": "white_concrete"
    },
    {
      "x": 10,
      "y": 4,
      "z": 3,
      "name": "white_concrete"
    },
    {
      "x": 0,
      "y": 4,
      "z": 4,
      "name": "white_concrete"
    },
    {
      "x": 10,
      "y": 4,
      "z": 4,
      "name": "white_concrete"
    },
    {
      "x": 0,
      "y": 4,
      "z": 5,
      "name": "white_concrete"
    },
    {
      "x": 10,
      "y": 4,
      "z": 5,
      "name": "white_concrete"
    },
    {
      "x": 0,
      "y": 4,
      "z": 6,
      "name": "white_concrete"
    },
    {
      "x": 10,
      "y": 4,
      "z": 6,
      "name": "white_concrete"
    },
    {
      "x": 0,
      "y": 4,
      "z": 7,
      "name": "black_concrete"
    },
    {
      "x": 1,
      "y": 4,
      "z": 7,
      "name": "white_concrete"
    },
    {
      "x": 2,
      "y": 4,
      "z": 7,
      "name": "white_concrete"
    },
    {
      "x": 3,
      "y": 4,
      "z": 7,
      "name": "white_concrete"
    },
    {
      "x": 4,
      "y": 4,
      "z": 7,
      "name": "white_concrete"
    },
    {
      "x": 5,
      "y": 4,
      "z": 7,
      "name": "white_concrete"
    },
    {
      "x": 6,
      "y": 4,
      "z": 7,
      "name": "white_concrete"
    },
    {
      "x": 7,
      "y": 4,
      "z": 7,
      "name": "white_concrete"
    },
    {
      "x": 8,
      "y": 4,
      "z": 7,
      "name": "white_concrete"
    },
    {
      "x": 9,
      "y": 4,
      "z": 7,
      "name": "white_concrete"
    },
    {
      "x": 10,
      "y": 4,
      "z": 7,
      "name": "black_concrete"
    },
    {
      "x": 0,
      "y": 5,
      "z": 0,
      "name": "smooth_quartz"
    },
    {
      "x": 1,
      "y": 5,
      "z": 0,
      "name": "smooth_quartz"
    },
    {
      "x": 2,
      "y": 5,
      "z": 0,
      "name": "smooth_quartz"
    },
    {
      "x": 3,
      "y": 5,
      "z": 0,
      "name": "smooth_quartz"
    },
    {
      "x": 4,
      "y": 5,
      "z": 0,
      "name": "smooth_quartz"
    },
    {
      "x": 5,
      "y": 5,
      "z": 0,
      "name": "smooth_quartz"
    },
    {
      "x": 6,
      "y": 5,
      "z": 0,
      "name": "smooth_quartz"
    },
    {
      "x": 7,
      "y": 5,
      "z": 0,
      "name": "smooth_quartz"
    },
    {
      "x": 8,
      "y": 5,
      "z": 0,
      "name": "smooth_quartz"
    },
    {
      "x": 9,
      "y": 5,
      "z": 0,
      "name": "smooth_quartz"
    },
    {
      "x": 10,
      "y": 5,
      "z": 0,
      "name": "smooth_quartz"
    },
    {
      "x": 0,
      "y": 5,
      "z": 1,
      "name": "smooth_quartz"
    },
    {
      "x": 1,
      "y": 5,
      "z": 1,
      "name": "smooth_quartz"
    },
    {
      "x": 2,
      "y": 5,
      "z": 1,
      "name": "smooth_quartz"
    },
    {
      "x": 3,
      "y": 5,
      "z": 1,
      "name": "smooth_quartz"
    },
    {
      "x": 4,
      "y": 5,
      "z": 1,
      "name": "smooth_quartz"
    },
    {
      "x": 5,
      "y": 5,
      "z": 1,
      "name": "smooth_quartz"
    },
    {
      "x": 6,
      "y": 5,
      "z": 1,
      "name": "smooth_quartz"
    },
    {
      "x": 7,
      "y": 5,
      "z": 1,
      "name": "smooth_quartz"
    },
    {
      "x": 8,
      "y": 5,
      "z": 1,
      "name": "smooth_quartz"
    },
    {
      "x": 9,
      "y": 5,
      "z": 1,
      "name": "smooth_quartz"
    },
    {
      "x": 10,
      "y": 5,
      "z": 1,
      "name": "smooth_quartz"
    },
    {
      "x": 0,
      "y": 5,
      "z": 2,
      "name": "smooth_quartz"
    },
    {
      "x": 1,
      "y": 5,
      "z": 2,
      "name": "smooth_quartz"
    },
    {
      "x": 2,
      "y": 5,
      "z": 2,
      "name": "smooth_quartz"
    },
    {
      "x": 3,
      "y": 5,
      "z": 2,
      "name": "smooth_quartz"
    },
    {
      "x": 4,
      "y": 5,
      "z": 2,
      "name": "smooth_quartz"
    },
    {
      "x": 5,
      "y": 5,
      "z": 2,
      "name": "smooth_quartz"
    },
    {
      "x": 6,
      "y": 5,
      "z": 2,
      "name": "smooth_quartz"
    },
    {
      "x": 7,
      "y": 5,
      "z": 2,
      "name": "smooth_quartz"
    },
    {
      "x": 8,
      "y": 5,
      "z": 2,
      "name": "smooth_quartz"
    },
    {
      "x": 9,
      "y": 5,
      "z": 2,
      "name": "smooth_quartz"
    },
    {
      "x": 10,
      "y": 5,
      "z": 2,
      "name": "smooth_quartz"
    },
    {
      "x": 0,
      "y": 5,
      "z": 3,
      "name": "smooth_quartz"
    },
    {
      "x": 1,
      "y": 5,
      "z": 3,
      "name": "smooth_quartz"
    },
    {
      "x": 2,
      "y": 5,
      "z": 3,
      "name": "smooth_quartz"
    },
    {
      "x": 3,
      "y": 5,
      "z": 3,
      "name": "smooth_quartz"
    },
    {
      "x": 4,
      "y": 5,
      "z": 3,
      "name": "smooth_quartz"
    },
    {
      "x": 5,
      "y": 5,
      "z": 3,
      "name": "smooth_quartz"
    },
    {
      "x": 6,
      "y": 5,
      "z": 3,
      "name": "smooth_quartz"
    },
    {
      "x": 7,
      "y": 5,
      "z": 3,
      "name": "smooth_quartz"
    },
    {
      "x": 8,
      "y": 5,
      "z": 3,
      "name": "smooth_quartz"
    },
    {
      "x": 9,
      "y": 5,
      "z": 3,
      "name": "smooth_quartz"
    },
    {
      "x": 10,
      "y": 5,
      "z": 3,
      "name": "smooth_quartz"
    },
    {
      "x": 0,
      "y": 5,
      "z": 4,
      "name": "smooth_quartz"
    },
    {
      "x": 1,
      "y": 5,
      "z": 4,
      "name": "smooth_quartz"
    },
    {
      "x": 2,
      "y": 5,
      "z": 4,
      "name": "smooth_quartz"
    },
    {
      "x": 3,
      "y": 5,
      "z": 4,
      "name": "smooth_quartz"
    },
    {
      "x": 4,
      "y": 5,
      "z": 4,
      "name": "smooth_quartz"
    },
    {
      "x": 5,
      "y": 5,
      "z": 4,
      "name": "smooth_quartz"
    },
    {
      "x": 6,
      "y": 5,
      "z": 4,
      "name": "smooth_quartz"
    },
    {
      "x": 7,
      "y": 5,
      "z": 4,
      "name": "smooth_quartz"
    },
    {
      "x": 8,
      "y": 5,
      "z": 4,
      "name": "smooth_quartz"
    },
    {
      "x": 9,
      "y": 5,
      "z": 4,
      "name": "smooth_quartz"
    },
    {
      "x": 10,
      "y": 5,
      "z": 4,
      "name": "smooth_quartz"
    },
    {
      "x": 0,
      "y": 5,
      "z": 5,
      "name": "smooth_quartz"
    },
    {
      "x": 1,
      "y": 5,
      "z": 5,
      "name": "smooth_quartz"
    },
    {
      "x": 2,
      "y": 5,
      "z": 5,
      "name": "smooth_quartz"
    },
    {
      "x": 3,
      "y": 5,
      "z": 5,
      "name": "smooth_quartz"
    },
    {
      "x": 4,
      "y": 5,
      "z": 5,
      "name": "smooth_quartz"
    },
    {
      "x": 5,
      "y": 5,
      "z": 5,
      "name": "smooth_quartz"
    },
    {
      "x": 6,
      "y": 5,
      "z": 5,
      "name": "smooth_quartz"
    },
    {
      "x": 7,
      "y": 5,
      "z": 5,
      "name": "smooth_quartz"
    },
    {
      "x": 8,
      "y": 5,
      "z": 5,
      "name": "smooth_quartz"
    },
    {
      "x": 9,
      "y": 5,
      "z": 5,
      "name": "smooth_quartz"
    },
    {
      "x": 10,
      "y": 5,
      "z": 5,
      "name": "smooth_quartz"
    },
    {
      "x": 0,
      "y": 5,
      "z": 6,
      "name": "smooth_quartz"
    },
    {
      "x": 1,
      "y": 5,
      "z": 6,
      "name": "smooth_quartz"
    },
    {
      "x": 2,
      "y": 5,
      "z": 6,
      "name": "smooth_quartz"
    },
    {
      "x": 3,
      "y": 5,
      "z": 6,
      "name": "smooth_quartz"
    },
    {
      "x": 4,
      "y": 5,
      "z": 6,
      "name": "smooth_quartz"
    },
    {
      "x": 5,
      "y": 5,
      "z": 6,
      "name": "smooth_quartz"
    },
    {
      "x": 6,
      "y": 5,
      "z": 6,
      "name": "smooth_quartz"
    },
    {
      "x": 7,
      "y": 5,
      "z": 6,
      "name": "smooth_quartz"
    },
    {
      "x": 8,
      "y": 5,
      "z": 6,
      "name": "smooth_quartz"
    },
    {
      "x": 9,
      "y": 5,
      "z": 6,
      "name": "smooth_quartz"
    },
    {
      "x": 10,
      "y": 5,
      "z": 6,
      "name": "smooth_quartz"
    },
    {
      "x": 0,
      "y": 5,
      "z": 7,
      "name": "smooth_quartz"
    },
    {
      "x": 1,
      "y": 5,
      "z": 7,
      "name": "smooth_quartz"
    },
    {
      "x": 2,
      "y": 5,
      "z": 7,
      "name": "smooth_quartz"
    },
    {
      "x": 3,
      "y": 5,
      "z": 7,
      "name": "smooth_quartz"
    },
    {
      "x": 4,
      "y": 5,
      "z": 7,
      "name": "smooth_quartz"
    },
    {
      "x": 5,
      "y": 5,
      "z": 7,
      "name": "smooth_quartz"
    },
    {
      "x": 6,
      "y": 5,
      "z": 7,
      "name": "smooth_quartz"
    },
    {
      "x": 7,
      "y": 5,
      "z": 7,
      "name": "smooth_quartz"
    },
    {
      "x": 8,
      "y": 5,
      "z": 7,
      "name": "smooth_quartz"
    },
    {
      "x": 9,
      "y": 5,
      "z": 7,
      "name": "smooth_quartz"
    },
    {
      "x": 10,
      "y": 5,
      "z": 7,
      "name": "smooth_quartz"
    },
    {
      "x": 0,
      "y": 6,
      "z": 0,
      "name": "black_concrete"
    },
    {
      "x": 1,
      "y": 6,
      "z": 0,
      "name": "black_concrete"
    },
    {
      "x": 2,
      "y": 6,
      "z": 0,
      "name": "black_concrete"
    },
    {
      "x": 3,
      "y": 6,
      "z": 0,
      "name": "black_concrete"
    },
    {
      "x": 4,
      "y": 6,
      "z": 0,
      "name": "black_concrete"
    },
    {
      "x": 5,
      "y": 6,
      "z": 0,
      "name": "black_concrete"
    },
    {
      "x": 6,
      "y": 6,
      "z": 0,
      "name": "black_concrete"
    },
    {
      "x": 7,
      "y": 6,
      "z": 0,
      "name": "black_concrete"
    },
    {
      "x": 8,
      "y": 6,
      "z": 0,
      "name": "black_concrete"
    },
    {
      "x": 9,
      "y": 6,
      "z": 0,
      "name": "black_concrete"
    },
    {
      "x": 10,
      "y": 6,
      "z": 0,
      "name": "black_concrete"
    },
    {
      "x": 0,
      "y": 6,
      "z": 1,
      "name": "black_concrete"
    },
    {
      "x": 10,
      "y": 6,
      "z": 1,
      "name": "black_concrete"
    },
    {
      "x": 0,
      "y": 6,
      "z": 2,
      "name": "black_concrete"
    },
    {
      "x": 10,
      "y": 6,
      "z": 2,
      "name": "black_concrete"
    },
    {
      "x": 0,
      "y": 6,
      "z": 3,
      "name": "black_concrete"
    },
    {
      "x": 10,
      "y": 6,
      "z": 3,
      "name": "black_concrete"
    },
    {
      "x": 0,
      "y": 6,
      "z": 4,
      "name": "black_concrete"
    },
    {
      "x": 10,
      "y": 6,
      "z": 4,
      "name": "black_concrete"
    },
    {
      "x": 0,
      "y": 6,
      "z": 5,
      "name": "black_concrete"
    },
    {
      "x": 10,
      "y": 6,
      "z": 5,
      "name": "black_concrete"
    },
    {
      "x": 0,
      "y": 6,
      "z": 6,
      "name": "black_concrete"
    },
    {
      "x": 10,
      "y": 6,
      "z": 6,
      "name": "black_concrete"
    },
    {
      "x": 0,
      "y": 6,
      "z": 7,
      "name": "black_concrete"
    },
    {
      "x": 1,
      "y": 6,
      "z": 7,
      "name": "black_concrete"
    },
    {
      "x": 2,
      "y": 6,
      "z": 7,
      "name": "black_concrete"
    },
    {
      "x": 3,
      "y": 6,
      "z": 7,
      "name": "black_concrete"
    },
    {
      "x": 4,
      "y": 6,
      "z": 7,
      "name": "black_concrete"
    },
    {
      "x": 5,
      "y": 6,
      "z": 7,
      "name": "black_concrete"
    },
    {
      "x": 6,
      "y": 6,
      "z": 7,
      "name": "black_concrete"
    },
    {
      "x": 7,
      "y": 6,
      "z": 7,
      "name": "black_concrete"
    },
    {
      "x": 8,
      "y": 6,
      "z": 7,
      "name": "black_concrete"
    },
    {
      "x": 9,
      "y": 6,
      "z": 7,
      "name": "black_concrete"
    },
    {
      "x": 10,
      "y": 6,
      "z": 7,
      "name": "black_concrete"
    }
  ]
}
