{
  "_opis": "Prostorna moderna vila z belo fasado in ravno streho.",
  "_category": "modern",
  "_kind": "building",
  "_aliases": [
    "moderna vila",
    "villa"
  ],
  "size": [
    13,
    9,
    10
  ],
  "blocks": [
    {
      "x": 0,
      "y": 0,
      "z": 0,
      "name": "smooth_quartz"
    },
    {
      "x": 1,
      "y": 0,
      "z": 0,
      "name": "smooth_quartz"
    },
    {
      "x": 2,
      "y": 0,
      "z": 0,
      "name": "smooth_quartz"
    },
    {
      "x": 3,
      "y": 0,
      "z": 0,
      "name": "smooth_quartz"
    },
    {
      "x": 4,
      "y": 0,
      "z": 0,
      "name": "smooth_quartz"
    },
    {
      "x": 5,
      "y": 0,
      "z": 0,
      "name": "smooth_quartz"
    },
    {
      "x": 6,
      "y": 0,
      "z": 0,
      "name": "smooth_quartz"
    },
    {
      "x": 7,
      "y": 0,
      "z": 0,
      "name": "smooth_quartz"
    },
    {
      "x": 8,
      "y": 0,
      "z": 0,
      "name": "smooth_quartz"
    },
    {
      "x": 9,
      "y": 0,
      "z": 0,
      "name": "smooth_quartz"
    },
    {
      "x": 10,
      "y": 0,
      "z": 0,
      "name": "smooth_quartz"
    },
    {
      "x": 11,
      "y": 0,
      "z": 0,
      "name": "smooth_quartz"
    },
    {
      "x": 12,
      "y": 0,
      "z": 0,
      "name": "smooth_quartz"
    },
    {
      "x": 0,
      "y": 0,
      "z": 1,
      "name": "smooth_quartz"
    },
    {
      "x": 1,
      "y": 0,
      "z": 1,
      "name": "smooth_quartz"
    },
    {
      "x": 2,
      "y": 0,
      "z": 1,
      "name": "smooth_quartz"
    },
    {
      "x": 3,
      "y": 0,
      "z": 1,
      "name": "smooth_quartz"
    },
    {
      "x": 4,
      "y": 0,
      "z": 1,
      "name": "smooth_quartz"
    },
    {
      "x": 5,
      "y": 0,
      "z": 1,
      "name": "smooth_quartz"
    },
    {
      "x": 6,
      "y": 0,
      "z": 1,
      "name": "smooth_quartz"
    },
    {
      "x": 7,
      "y": 0,
      "z": 1,
      "name": "smooth_quartz"
    },
    {
      "x": 8,
      "y": 0,
      "z": 1,
      "name": "smooth_quartz"
    },
    {
      "x": 9,
      "y": 0,
      "z": 1,
      "name": "smooth_quartz"
    },
    {
      "x": 10,
      "y": 0,
      "z": 1,
      "name": "smooth_quartz"
    },
    {
      "x": 11,
      "y": 0,
      "z": 1,
      "name": "smooth_quartz"
    },
    {
      "x": 12,
      "y": 0,
      "z": 1,
      "name": "smooth_quartz"
    },
    {
      "x": 0,
      "y": 0,
      "z": 2,
      "name": "smooth_quartz"
    },
    {
      "x": 1,
      "y": 0,
      "z": 2,
      "name": "smooth_quartz"
    },
    {
      "x": 2,
      "y": 0,
      "z": 2,
      "name": "smooth_quartz"
    },
    {
      "x": 3,
      "y": 0,
      "z": 2,
      "name": "smooth_quartz"
    },
    {
      "x": 4,
      "y": 0,
      "z": 2,
      "name": "smooth_quartz"
    },
    {
      "x": 5,
      "y": 0,
      "z": 2,
      "name": "smooth_quartz"
    },
    {
      "x": 6,
      "y": 0,
      "z": 2,
      "name": "smooth_quartz"
    },
    {
      "x": 7,
      "y": 0,
      "z": 2,
      "name": "smooth_quartz"
    },
    {
      "x": 8,
      "y": 0,
      "z": 2,
      "name": "smooth_quartz"
    },
    {
      "x": 9,
      "y": 0,
      "z": 2,
      "name": "smooth_quartz"
    },
    {
      "x": 10,
      "y": 0,
      "z": 2,
      "name": "smooth_quartz"
    },
    {
      "x": 11,
      "y": 0,
      "z": 2,
      "name": "smooth_quartz"
    },
    {
      "x": 12,
      "y": 0,
      "z": 2,
      "name": "smooth_quartz"
    },
    {
      "x": 0,
      "y": 0,
      "z": 3,
      "name": "smooth_quartz"
    },
    {
      "x": 1,
      "y": 0,
      "z": 3,
      "name": "smooth_quartz"
    },
    {
      "x": 2,
      "y": 0,
      "z": 3,
      "name": "smooth_quartz"
    },
    {
      "x": 3,
      "y": 0,
      "z": 3,
      "name": "smooth_quartz"
    },
    {
      "x": 4,
      "y": 0,
      "z": 3,
      "name": "smooth_quartz"
    },
    {
      "x": 5,
      "y": 0,
      "z": 3,
      "name": "smooth_quartz"
    },
    {
      "x": 6,
      "y": 0,
      "z": 3,
      "name": "smooth_quartz"
    },
    {
      "x": 7,
      "y": 0,
      "z": 3,
      "name": "smooth_quartz"
    },
    {
      "x": 8,
      "y": 0,
      "z": 3,
      "name": "smooth_quartz"
    },
    {
      "x": 9,
      "y": 0,
      "z": 3,
      "name": "smooth_quartz"
    },
    {
      "x": 10,
      "y": 0,
      "z": 3,
      "name": "smooth_quartz"
    },
    {
      "x": 11,
      "y": 0,
      "z": 3,
      "name": "smooth_quartz"
    },
    {
      "x": 12,
      "y": 0,
      "z": 3,
      "name": "smooth_quartz"
    },
    {
      "x": 0,
      "y": 0,
      "z": 4,
      "name": "smooth_quartz"
    },
    {
      "x": 1,
      "y": 0,
      "z": 4,
      "name": "smooth_quartz"
    },
    {
      "x": 2,
      "y": 0,
      "z": 4,
      "name": "smooth_quartz"
    },
    {
      "x": 3,
      "y": 0,
      "z": 4,
      "name": "smooth_quartz"
    },
    {
      "x": 4,
      "y": 0,
      "z": 4,
      "name": "smooth_quartz"
    },
    {
      "x": 5,
      "y": 0,
      "z": 4,
      "name": "smooth_quartz"
    },
    {
      "x": 6,
      "y": 0,
      "z": 4,
      "name": "smooth_quartz"
    },
    {
      "x": 7,
      "y": 0,
      "z": 4,
      "name": "smooth_quartz"
    },
    {
      "x": 8,
      "y": 0,
      "z": 4,
      "name": "smooth_quartz"
    },
    {
      "x": 9,
      "y": 0,
      "z": 4,
      "name": "smooth_quartz"
    },
    {
      "x": 10,
      "y": 0,
      "z": 4,
      "name": "smooth_quartz"
    },
    {
      "x": 11,
      "y": 0,
      "z": 4,
      "name": "smooth_quartz"
    },
    {
      "x": 12,
      "y": 0,
      "z": 4,
      "name": "smooth_quartz"
    },
    {
      "x": 0,
      "y": 0,
      "z": 5,
      "name": "smooth_quartz"
    },
    {
      "x": 1,
      "y": 0,
      "z": 5,
      "name": "smooth_quartz"
    },
    {
      "x": 2,
      "y": 0,
      "z": 5,
      "name": "smooth_quartz"
    },
    {
      "x": 3,
      "y": 0,
      "z": 5,
      "name": "smooth_quartz"
    },
    {
      "x": 4,
      "y": 0,
      "z": 5,
      "name": "smooth_quartz"
    },
    {
      "x": 5,
      "y": 0,
      "z": 5,
      "name": "smooth_quartz"
    },
    {
      "x": 6,
      "y": 0,
      "z": 5,
      "name": "smooth_quartz"
    },
    {
      "x": 7,
      "y": 0,
      "z": 5,
      "name": "smooth_quartz"
    },
    {
      "x": 8,
      "y": 0,
      "z": 5,
      "name": "smooth_quartz"
    },
    {
      "x": 9,
      "y": 0,
      "z": 5,
      "name": "smooth_quartz"
    },
    {
      "x": 10,
      "y": 0,
      "z": 5,
      "name": "smooth_quartz"
    },
    {
      "x": 11,
      "y": 0,
      "z": 5,
      "name": "smooth_quartz"
    },
    {
      "x": 12,
      "y": 0,
      "z": 5,
      "name": "smooth_quartz"
    },
    {
      "x": 0,
      "y": 0,
      "z": 6,
      "name": "smooth_quartz"
    },
    {
      "x": 1,
      "y": 0,
      "z": 6,
      "name": "smooth_quartz"
    },
    {
      "x": 2,
      "y": 0,
      "z": 6,
      "name": "smooth_quartz"
    },
    {
      "x": 3,
      "y": 0,
      "z": 6,
      "name": "smooth_quartz"
    },
    {
      "x": 4,
      "y": 0,
      "z": 6,
      "name": "smooth_quartz"
    },
    {
      "x": 5,
      "y": 0,
      "z": 6,
      "name": "smooth_quartz"
    },
    {
      "x": 6,
      "y": 0,
      "z": 6,
      "name": "smooth_quartz"
    },
    {
      "x": 7,
      "y": 0,
      "z": 6,
      "name": "smooth_quartz"
    },
    {
      "x": 8,
      "y": 0,
      "z": 6,
      "name": "smooth_quartz"
    },
    {
      "x": 9,
      "y": 0,
      "z": 6,
      "name": "smooth_quartz"
    },
    {
      "x": 10,
      "y": 0,
      "z": 6,
      "name": "smooth_quartz"
    },
    {
      "x": 11,
      "y": 0,
      "z": 6,
      "name": "smooth_quartz"
    },
    {
      "x": 12,
      "y": 0,
      "z": 6,
      "name": "smooth_quartz"
    },
    {
      "x": 0,
      "y": 0,
      "z": 7,
      "name": "smooth_quartz"
    },
    {
      "x": 1,
      "y": 0,
      "z": 7,
      "name": "smooth_quartz"
    },
    {
      "x": 2,
      "y": 0,
      "z": 7,
      "name": "smooth_quartz"
    },
    {
      "x": 3,
      "y": 0,
      "z": 7,
      "name": "smooth_quartz"
    },
    {
      "x": 4,
      "y": 0,
      "z": 7,
      "name": "smooth_quartz"
    },
    {
      "x": 5,
      "y": 0,
      "z": 7,
      "name": "smooth_quartz"
    },
    {
      "x": 6,
      "y": 0,
      "z": 7,
      "name": "smooth_quartz"
    },
    {
      "x": 7,
      "y": 0,
      "z": 7,
      "name": "smooth_quartz"
    },
    {
      "x": 8,
      "y": 0,
      "z": 7,
      "name": "smooth_quartz"
    },
    {
      "x": 9,
      "y": 0,
      "z": 7,
      "name": "smooth_quartz"
    },
    {
      "x": 10,
      "y": 0,
      "z": 7,
      "name": "smooth_quartz"
    },
    {
      "x": 11,
      "y": 0,
      "z": 7,
      "name": "smooth_quartz"
    },
    {
      "x": 12,
      "y": 0,
      "z": 7,
      "name": "smooth_quartz"
    },
    {
      "x": 0,
      "y": 0,
      "z": 8,
      "name": "smooth_quartz"
    },
    {
      "x": 1,
      "y": 0,
      "z": 8,
      "name": "smooth_quartz"
    },
    {
      "x": 2,
      "y": 0,
      "z": 8,
      "name": "smooth_quartz"
    },
    {
      "x": 3,
      "y": 0,
      "z": 8,
      "name": "smooth_quartz"
    },
    {
      "x": 4,
      "y": 0,
      "z": 8,
      "name": "smooth_quartz"
    },
    {
      "x": 5,
      "y": 0,
      "z": 8,
      "name": "smooth_quartz"
    },
    {
      "x": 6,
      "y": 0,
      "z": 8,
      "name": "smooth_quartz"
    },
    {
      "x": 7,
      "y": 0,
      "z": 8,
      "name": "smooth_quartz"
    },
    {
      "x": 8,
      "y": 0,
      "z": 8,
      "name": "smooth_quartz"
    },
    {
      "x": 9,
      "y": 0,
      "z": 8,
      "name": "smooth_quartz"
    },
    {
      "x": 10,
      "y": 0,
      "z": 8,
      "name": "smooth_quartz"
    },
    {
      "x": 11,
      "y": 0,
      "z": 8,
      "name": "smooth_quartz"
    },
    {
      "x": 12,
      "y": 0,
      "z": 8,
      "name": "smooth_quartz"
    },
    {
      "x": 0,
      "y": 0,
      "z": 9,
      "name": "smooth_quartz"
    },
    {
      "x": 1,
      "y": 0,
      "z": 9,
      "name": "smooth_quartz"
    },
    {
      "x": 2,
      "y": 0,
      "z": 9,
      "name": "smooth_quartz"
    },
    {
      "x": 3,
      "y": 0,
      "z": 9,
      "name": "smooth_quartz"
    },
    {
      "x": 4,
      "y": 0,
      "z": 9,
      "name": "smooth_quartz"
    },
    {
      "x": 5,
      "y": 0,
      "z": 9,
      "name": "smooth_quartz"
    },
    {
      "x": 6,
      "y": 0,
      "z": 9,
      "name": "smooth_quartz"
    },
    {
      "x": 7,
      "y": 0,
      "z": 9,
      "name": "smooth_quartz"
    },
    {
      "x": 8,
      "y": 0,
      "z": 9,
      "name": "smooth_quartz"
    },
    {
      "x": 9,
      "y": 0,
      "z": 9,
      "name": "smooth_quartz"
    },
    {
      "x": 10,
      "y": 0,
      "z": 9,
      "name": "smooth_quartz"
    },
    {
      "x": 11,
      "y": 0,
      "z": 9,
      "name": "smooth_quartz"
    },
    {
      "x": 12,
      "y": 0,
      "z": 9,
      "name": "smooth_quartz"
    },
    {
      "x": 0,
      "y": 1,
      "z": 0,
      "name": "gray_concrete"
    },
    {
      "x": 1,
      "y": 1,
      "z": 0,
      "name": "white_concrete"
    },
    {
      "x": 2,
      "y": 1,
      "z": 0,
      "name": "white_concrete"
    },
    {
      "x": 3,
      "y": 1,
      "z": 0,
      "name": "white_concrete"
    },
    {
      "x": 4,
      "y": 1,
      "z": 0,
      "name": "white_concrete"
    },
    {
      "x": 5,
      "y": 1,
      "z": 0,
      "name": "white_concrete"
    },
    {
      "x": 6,
      "y": 1,
      "z": 0,
      "name": "birch_door"
    },
    {
      "x": 7,
      "y": 1,
      "z": 0,
      "name": "white_concrete"
    },
    {
      "x": 8,
      "y": 1,
      "z": 0,
      "name": "white_concrete"
    },
    {
      "x": 9,
      "y": 1,
      "z": 0,
      "name": "white_concrete"
    },
    {
      "x": 10,
      "y": 1,
      "z": 0,
      "name": "white_concrete"
    },
    {
      "x": 11,
      "y": 1,
      "z": 0,
      "name": "white_concrete"
    },
    {
      "x": 12,
      "y": 1,
      "z": 0,
      "name": "gray_concrete"
    },
    {
      "x": 0,
      "y": 1,
      "z": 1,
      "name": "white_concrete"
    },
    {
      "x": 1,
      "y": 1,
      "z": 1,
      "name": "crafting_table"
    },
    {
      "x": 11,
      "y": 1,
      "z": 1,
      "name": "furnace"
    },
    {
      "x": 12,
      "y": 1,
      "z": 1,
      "name": "white_concrete"
    },
    {
      "x": 0,
      "y": 1,
      "z": 2,
      "name": "white_concrete"
    },
    {
      "x": 12,
      "y": 1,
      "z": 2,
      "name": "white_concrete"
    },
    {
      "x": 0,
      "y": 1,
      "z": 3,
      "name": "white_concrete"
    },
    {
      "x": 12,
      "y": 1,
      "z": 3,
      "name": "white_concrete"
    },
    {
      "x": 0,
      "y": 1,
      "z": 4,
      "name": "white_concrete"
    },
    {
      "x": 12,
      "y": 1,
      "z": 4,
      "name": "white_concrete"
    },
    {
      "x": 0,
      "y": 1,
      "z": 5,
      "name": "white_concrete"
    },
    {
      "x": 12,
      "y": 1,
      "z": 5,
      "name": "white_concrete"
    },
    {
      "x": 0,
      "y": 1,
      "z": 6,
      "name": "white_concrete"
    },
    {
      "x": 12,
      "y": 1,
      "z": 6,
      "name": "white_concrete"
    },
    {
      "x": 0,
      "y": 1,
      "z": 7,
      "name": "white_concrete"
    },
    {
      "x": 12,
      "y": 1,
      "z": 7,
      "name": "white_concrete"
    },
    {
      "x": 0,
      "y": 1,
      "z": 8,
      "name": "white_concrete"
    },
    {
      "x": 11,
      "y": 1,
      "z": 8,
      "name": "chest"
    },
    {
      "x": 12,
      "y": 1,
      "z": 8,
      "name": "white_concrete"
    },
    {
      "x": 0,
      "y": 1,
      "z": 9,
      "name": "gray_concrete"
    },
    {
      "x": 1,
      "y": 1,
      "z": 9,
      "name": "white_concrete"
    },
    {
      "x": 2,
      "y": 1,
      "z": 9,
      "name": "white_concrete"
    },
    {
      "x": 3,
      "y": 1,
      "z": 9,
      "name": "white_concrete"
    },
    {
      "x": 4,
      "y": 1,
      "z": 9,
      "name": "white_concrete"
    },
    {
      "x": 5,
      "y": 1,
      "z": 9,
      "name": "white_concrete"
    },
    {
      "x": 6,
      "y": 1,
      "z": 9,
      "name": "white_concrete"
    },
    {
      "x": 7,
      "y": 1,
      "z": 9,
      "name": "white_concrete"
    },
    {
      "x": 8,
      "y": 1,
      "z": 9,
      "name": "white_concrete"
    },
    {
      "x": 9,
      "y": 1,
      "z": 9,
      "name": "white_concrete"
    },
    {
      "x": 10,
      "y": 1,
      "z": 9,
      "name": "white_concrete"
    },
    {
      "x": 11,
      "y": 1,
      "z": 9,
      "name": "white_concrete"
    },
    {
      "x": 12,
      "y": 1,
      "z": 9,
      "name": "gray_concrete"
    },
    {
      "x": 0,
      "y": 2,
      "z": 0,
      "name": "gray_concrete"
    },
    {
      "x": 1,
      "y": 2,
      "z": 0,
      "name": "white_concrete"
    },
    {
      "x": 2,
      "y": 2,
      "z": 0,
      "name": "light_blue_stained_glass"
    },
    {
      "x": 3,
      "y": 2,
      "z": 0,
      "name": "white_concrete"
    },
    {
      "x": 4,
      "y": 2,
      "z": 0,
      "name": "white_concrete"
    },
    {
      "x": 5,
      "y": 2,
      "z": 0,
      "name": "white_concrete"
    },
    {
      "x": 7,
      "y": 2,
      "z": 0,
      "name": "white_concrete"
    },
    {
      "x": 8,
      "y": 2,
      "z": 0,
      "name": "white_concrete"
    },
    {
      "x": 9,
      "y": 2,
      "z": 0,
      "name": "white_concrete"
    },
    {
      "x": 10,
      "y": 2,
      "z": 0,
      "name": "light_blue_stained_glass"
    },
    {
      "x": 11,
      "y": 2,
      "z": 0,
      "name": "white_concrete"
    },
    {
      "x": 12,
      "y": 2,
      "z": 0,
      "name": "gray_concrete"
    },
    {
      "x": 0,
      "y": 2,
      "z": 1,
      "name": "white_concrete"
    },
    {
      "x": 12,
      "y": 2,
      "z": 1,
      "name": "white_concrete"
    },
    {
      "x": 0,
      "y": 2,
      "z": 2,
      "name": "light_blue_stained_glass"
    },
    {
      "x": 12,
      "y": 2,
      "z": 2,
      "name": "light_blue_stained_glass"
    },
    {
      "x": 0,
      "y": 2,
      "z": 3,
      "name": "white_concrete"
    },
    {
      "x": 12,
      "y": 2,
      "z": 3,
      "name": "white_concrete"
    },
    {
      "x": 0,
      "y": 2,
      "z": 4,
      "name": "white_concrete"
    },
    {
      "x": 12,
      "y": 2,
      "z": 4,
      "name": "white_concrete"
    },
    {
      "x": 0,
      "y": 2,
      "z": 5,
      "name": "white_concrete"
    },
    {
      "x": 12,
      "y": 2,
      "z": 5,
      "name": "white_concrete"
    },
    {
      "x": 0,
      "y": 2,
      "z": 6,
      "name": "white_concrete"
    },
    {
      "x": 12,
      "y": 2,
      "z": 6,
      "name": "white_concrete"
    },
    {
      "x": 0,
      "y": 2,
      "z": 7,
      "name": "light_blue_stained_glass"
    },
    {
      "x": 12,
      "y": 2,
      "z": 7,
      "name": "light_blue_stained_glass"
    },
    {
      "x": 0,
      "y": 2,
      "z": 8,
      "name": "white_concrete"
    },
    {
      "x": 12,
      "y": 2,
      "z": 8,
      "name": "white_concrete"
    },
    {
      "x": 0,
      "y": 2,
      "z": 9,
      "name": "gray_concrete"
    },
    {
      "x": 1,
      "y": 2,
      "z": 9,
      "name": "white_concrete"
    },
    {
      "x": 2,
      "y": 2,
      "z": 9,
      "name": "light_blue_stained_glass"
    },
    {
      "x": 3,
      "y": 2,
      "z": 9,
      "name": "white_concrete"
    },
    {
      "x": 4,
      "y": 2,
      "z": 9,
      "name": "white_concrete"
    },
    {
      "x": 5,
      "y": 2,
      "z": 9,
      "name": "white_concrete"
    },
    {
      "x": 6,
      "y": 2,
      "z": 9,
      "name": "white_concrete"
    },
    {
      "x": 7,
      "y": 2,
      "z": 9,
      "name": "white_concrete"
    },
    {
      "x": 8,
      "y": 2,
      "z": 9,
      "name": "white_concrete"
    },
    {
      "x": 9,
      "y": 2,
      "z": 9,
      "name": "white_concrete"
    },
    {
      "x": 10,
      "y": 2,
      "z": 9,
      "name": "light_blue_stained_glass"
    },
    {
      "x": 11,
      "y": 2,
      "z": 9,
      "name": "white_concrete"
    },
    {
      "x": 12,
      "y": 2,
      "z": 9,
      "name": "gray_concrete"
    },
    {
      "x": 0,
      "y": 3,
      "z": 0,
      "name": "gray_concrete"
    },
    {
      "x": 1,
      "y": 3,
      "z": 0,
      "name": "white_concrete"
    },
    {
      "x": 2,
      "y": 3,
      "z": 0,
      "name": "white_concrete"
    },
    {
      "x": 3,
      "y": 3,
      "z": 0,
      "name": "white_concrete"
    },
    {
      "x": 4,
      "y": 3,
      "z": 0,
      "name": "white_concrete"
    },
    {
      "x": 5,
      "y": 3,
      "z": 0,
      "name": "white_concrete"
    },
    {
      "x": 6,
      "y": 3,
      "z": 0,
      "name": "white_concrete"
    },
    {
      "x": 7,
      "y": 3,
      "z": 0,
      "name": "white_concrete"
    },
    {
      "x": 8,
      "y": 3,
      "z": 0,
      "name": "white_concrete"
    },
    {
      "x": 9,
      "y": 3,
      "z": 0,
      "name": "white_concrete"
    },
    {
      "x": 10,
      "y": 3,
      "z": 0,
      "name": "white_concrete"
    },
    {
      "x": 11,
      "y": 3,
      "z": 0,
      "name": "white_concrete"
    },
    {
      "x": 12,
      "y": 3,
      "z": 0,
      "name": "gray_concrete"
    },
    {
      "x": 0,
      "y": 3,
      "z": 1,
      "name": "white_concrete"
    },
    {
      "x": 12,
      "y": 3,
      "z": 1,
      "name": "white_concrete"
    },
    {
      "x": 0,
      "y": 3,
      "z": 2,
      "name": "white_concrete"
    },
    {
      "x": 12,
      "y": 3,
      "z": 2,
      "name": "white_concrete"
    },
    {
      "x": 0,
      "y": 3,
      "z": 3,
      "name": "white_concrete"
    },
    {
      "x": 12,
      "y": 3,
      "z": 3,
      "name": "white_concrete"
    },
    {
      "x": 0,
      "y": 3,
      "z": 4,
      "name": "white_concrete"
    },
    {
      "x": 12,
      "y": 3,
      "z": 4,
      "name": "white_concrete"
    },
    {
      "x": 0,
      "y": 3,
      "z": 5,
      "name": "white_concrete"
    },
    {
      "x": 12,
      "y": 3,
      "z": 5,
      "name": "white_concrete"
    },
    {
      "x": 0,
      "y": 3,
      "z": 6,
      "name": "white_concrete"
    },
    {
      "x": 12,
      "y": 3,
      "z": 6,
      "name": "white_concrete"
    },
    {
      "x": 0,
      "y": 3,
      "z": 7,
      "name": "white_concrete"
    },
    {
      "x": 12,
      "y": 3,
      "z": 7,
      "name": "white_concrete"
    },
    {
      "x": 0,
      "y": 3,
      "z": 8,
      "name": "white_concrete"
    },
    {
      "x": 12,
      "y": 3,
      "z": 8,
      "name": "white_concrete"
    },
    {
      "x": 0,
      "y": 3,
      "z": 9,
      "name": "gray_concrete"
    },
    {
      "x": 1,
      "y": 3,
      "z": 9,
      "name": "white_concrete"
    },
    {
      "x": 2,
      "y": 3,
      "z": 9,
      "name": "white_concrete"
    },
    {
      "x": 3,
      "y": 3,
      "z": 9,
      "name": "white_concrete"
    },
    {
      "x": 4,
      "y": 3,
      "z": 9,
      "name": "white_concrete"
    },
    {
      "x": 5,
      "y": 3,
      "z": 9,
      "name": "white_concrete"
    },
    {
      "x": 6,
      "y": 3,
      "z": 9,
      "name": "white_concrete"
    },
    {
      "x": 7,
      "y": 3,
      "z": 9,
      "name": "white_concrete"
    },
    {
      "x": 8,
      "y": 3,
      "z": 9,
      "name": "white_concrete"
    },
    {
      "x": 9,
      "y": 3,
      "z": 9,
      "name": "white_concrete"
    },
    {
      "x": 10,
      "y": 3,
      "z": 9,
      "name": "white_concrete"
    },
    {
      "x": 11,
      "y": 3,
      "z": 9,
      "name": "white_concrete"
    },
    {
      "x": 12,
      "y": 3,
      "z": 9,
      "name": "gray_concrete"
    },
    {
      "x": 0,
      "y": 4,
      "z": 0,
      "name": "gray_concrete"
    },
    {
      "x": 1,
      "y": 4,
      "z": 0,
      "name": "white_concrete"
    },
    {
      "x": 2,
      "y": 4,
      "z": 0,
      "name": "white_concrete"
    },
    {
      "x": 3,
      "y": 4,
      "z": 0,
      "name": "white_concrete"
    },
    {
      "x": 4,
      "y": 4,
      "z": 0,
      "name": "white_concrete"
    },
    {
      "x": 5,
      "y": 4,
      "z": 0,
      "name": "white_concrete"
    },
    {
      "x": 6,
      "y": 4,
      "z": 0,
      "name": "white_concrete"
    },
    {
      "x": 7,
      "y": 4,
      "z": 0,
      "name": "white_concrete"
    },
    {
      "x": 8,
      "y": 4,
      "z": 0,
      "name": "white_concrete"
    },
    {
      "x": 9,
      "y": 4,
      "z": 0,
      "name": "white_concrete"
    },
    {
      "x": 10,
      "y": 4,
      "z": 0,
      "name": "white_concrete"
    },
    {
      "x": 11,
      "y": 4,
      "z": 0,
      "name": "white_concrete"
    },
    {
      "x": 12,
      "y": 4,
      "z": 0,
      "name": "gray_concrete"
    },
    {
      "x": 0,
      "y": 4,
      "z": 1,
      "name": "white_concrete"
    },
    {
      "x": 12,
      "y": 4,
      "z": 1,
      "name": "white_concrete"
    },
    {
      "x": 0,
      "y": 4,
      "z": 2,
      "name": "white_concrete"
    },
    {
      "x": 12,
      "y": 4,
      "z": 2,
      "name": "white_concrete"
    },
    {
      "x": 0,
      "y": 4,
      "z": 3,
      "name": "white_concrete"
    },
    {
      "x": 12,
      "y": 4,
      "z": 3,
      "name": "white_concrete"
    },
    {
      "x": 0,
      "y": 4,
      "z": 4,
      "name": "white_concrete"
    },
    {
      "x": 12,
      "y": 4,
      "z": 4,
      "name": "white_concrete"
    },
    {
      "x": 0,
      "y": 4,
      "z": 5,
      "name": "white_concrete"
    },
    {
      "x": 12,
      "y": 4,
      "z": 5,
      "name": "white_concrete"
    },
    {
      "x": 0,
      "y": 4,
      "z": 6,
      "name": "white_concrete"
    },
    {
      "x": 12,
      "y": 4,
      "z": 6,
      "name": "white_concrete"
    },
    {
      "x": 0,
      "y": 4,
      "z": 7,
      "name": "white_concrete"
    },
    {
      "x": 12,
      "y": 4,
      "z": 7,
      "name": "white_concrete"
    },
    {
      "x": 0,
      "y": 4,
      "z": 8,
      "name": "white_concrete"
    },
    {
      "x": 12,
      "y": 4,
      "z": 8,
      "name": "white_concrete"
    },
    {
      "x": 0,
      "y": 4,
      "z": 9,
      "name": "gray_concrete"
    },
    {
      "x": 1,
      "y": 4,
      "z": 9,
      "name": "white_concrete"
    },
    {
      "x": 2,
      "y": 4,
      "z": 9,
      "name": "white_concrete"
    },
    {
      "x": 3,
      "y": 4,
      "z": 9,
      "name": "white_concrete"
    },
    {
      "x": 4,
      "y": 4,
      "z": 9,
      "name": "white_concrete"
    },
    {
      "x": 5,
      "y": 4,
      "z": 9,
      "name": "white_concrete"
    },
    {
      "x": 6,
      "y": 4,
      "z": 9,
      "name": "white_concrete"
    },
    {
      "x": 7,
      "y": 4,
      "z": 9,
      "name": "white_concrete"
    },
    {
      "x": 8,
      "y": 4,
      "z": 9,
      "name": "white_concrete"
    },
    {
      "x": 9,
      "y": 4,
      "z": 9,
      "name": "white_concrete"
    },
    {
      "x": 10,
      "y": 4,
      "z": 9,
      "name": "white_concrete"
    },
    {
      "x": 11,
      "y": 4,
      "z": 9,
      "name": "white_concrete"
    },
    {
      "x": 12,
      "y": 4,
      "z": 9,
      "name": "gray_concrete"
    },
    {
      "x": 0,
      "y": 5,
      "z": 0,
      "name": "gray_concrete"
    },
    {
      "x": 1,
      "y": 5,
      "z": 0,
      "name": "white_concrete"
    },
    {
      "x": 2,
      "y": 5,
      "z": 0,
      "name": "white_concrete"
    },
    {
      "x": 3,
      "y": 5,
      "z": 0,
      "name": "white_concrete"
    },
    {
      "x": 4,
      "y": 5,
      "z": 0,
      "name": "white_concrete"
    },
    {
      "x": 5,
      "y": 5,
      "z": 0,
      "name": "white_concrete"
    },
    {
      "x": 6,
      "y": 5,
      "z": 0,
      "name": "white_concrete"
    },
    {
      "x": 7,
      "y": 5,
      "z": 0,
      "name": "white_concrete"
    },
    {
      "x": 8,
      "y": 5,
      "z": 0,
      "name": "white_concrete"
    },
    {
      "x": 9,
      "y": 5,
      "z": 0,
      "name": "white_concrete"
    },
    {
      "x": 10,
      "y": 5,
      "z": 0,
      "name": "white_concrete"
    },
    {
      "x": 11,
      "y": 5,
      "z": 0,
      "name": "white_concrete"
    },
    {
      "x": 12,
      "y": 5,
      "z": 0,
      "name": "gray_concrete"
    },
    {
      "x": 0,
      "y": 5,
      "z": 1,
      "name": "white_concrete"
    },
    {
      "x": 12,
      "y": 5,
      "z": 1,
      "name": "white_concrete"
    },
    {
      "x": 0,
      "y": 5,
      "z": 2,
      "name": "white_concrete"
    },
    {
      "x": 12,
      "y": 5,
      "z": 2,
      "name": "white_concrete"
    },
    {
      "x": 0,
      "y": 5,
      "z": 3,
      "name": "white_concrete"
    },
    {
      "x": 12,
      "y": 5,
      "z": 3,
      "name": "white_concrete"
    },
    {
      "x": 0,
      "y": 5,
      "z": 4,
      "name": "white_concrete"
    },
    {
      "x": 12,
      "y": 5,
      "z": 4,
      "name": "white_concrete"
    },
    {
      "x": 0,
      "y": 5,
      "z": 5,
      "name": "white_concrete"
    },
    {
      "x": 12,
      "y": 5,
      "z": 5,
      "name": "white_concrete"
    },
    {
      "x": 0,
      "y": 5,
      "z": 6,
      "name": "white_concrete"
    },
    {
      "x": 12,
      "y": 5,
      "z": 6,
      "name": "white_concrete"
    },
    {
      "x": 0,
      "y": 5,
      "z": 7,
      "name": "white_concrete"
    },
    {
      "x": 12,
      "y": 5,
      "z": 7,
      "name": "white_concrete"
    },
    {
      "x": 0,
      "y": 5,
      "z": 8,
      "name": "white_concrete"
    },
    {
      "x": 12,
      "y": 5,
      "z": 8,
      "name": "white_concrete"
    },
    {
      "x": 0,
      "y": 5,
      "z": 9,
      "name": "gray_concrete"
    },
    {
      "x": 1,
      "y": 5,
      "z": 9,
      "name": "white_concrete"
    },
    {
      "x": 2,
      "y": 5,
      "z": 9,
      "name": "white_concrete"
    },
    {
      "x": 3,
      "y": 5,
      "z": 9,
      "name": "white_concrete"
    },
    {
      "x": 4,
      "y": 5,
      "z": 9,
      "name": "white_concrete"
    },
    {
      "x": 5,
      "y": 5,
      "z": 9,
      "name": "white_concrete"
    },
    {
      "x": 6,
      "y": 5,
      "z": 9,
      "name": "white_concrete"
    },
    {
      "x": 7,
      "y": 5,
      "z": 9,
      "name": "white_concrete"
    },
    {
      "x": 8,
      "y": 5,
      "z": 9,
      "name": "white_concrete"
    },
    {
      "x": 9,
      "y": 5,
      "z": 9,
      "name": "white_concrete"
    },
    {
      "x": 10,
      "y": 5,
      "z": 9,
      "name": "white_concrete"
    },
    {
      "x": 11,
      "y": 5,
      "z": 9,
      "name": "white_concrete"
    },
    {
      "x": 12,
      "y": 5,
      "z": 9,
      "name": "gray_concrete"
    },
    {
      "x": 0,
      "y": 6,
      "z": 0,
      "name": "gray_concrete"
    },
    {
      "x": 1,
      "y": 6,
      "z": 0,
      "name": "black_concrete"
    },
    {
      "x": 2,
      "y": 6,
      "z": 0,
      "name": "black_concrete"
    },
    {
      "x": 3,
      "y": 6,
      "z": 0,
      "name": "black_concrete"
    },
    {
      "x": 4,
      "y": 6,
      "z": 0,
      "name": "black_concrete"
    },
    {
      "x": 5,
      "y": 6,
      "z": 0,
      "name": "black_concrete"
    },
    {
      "x": 6,
      "y": 6,
      "z": 0,
      "name": "black_concrete"
    },
    {
      "x": 7,
      "y": 6,
      "z": 0,
      "name": "black_concrete"
    },
    {
      "x": 8,
      "y": 6,
      "z": 0,
      "name": "black_concrete"
    },
    {
      "x": 9,
      "y": 6,
      "z": 0,
      "name": "black_concrete"
    },
    {
      "x": 10,
      "y": 6,
      "z": 0,
      "name": "black_concrete"
    },
    {
      "x": 11,
      "y": 6,
      "z": 0,
      "name": "black_concrete"
    },
    {
      "x": 12,
      "y": 6,
      "z": 0,
      "name": "gray_concrete"
    },
    {
      "x": 0,
      "y": 6,
      "z": 1,
      "name": "white_concrete"
    },
    {
      "x": 12,
      "y": 6,
      "z": 1,
      "name": "white_concrete"
    },
    {
      "x": 0,
      "y": 6,
      "z": 2,
      "name": "white_concrete"
    },
    {
      "x": 12,
      "y": 6,
      "z": 2,
      "name": "white_concrete"
    },
    {
      "x": 0,
      "y": 6,
      "z": 3,
      "name": "white_concrete"
    },
    {
      "x": 12,
      "y": 6,
      "z": 3,
      "name": "white_concrete"
    },
    {
      "x": 0,
      "y": 6,
      "z": 4,
      "name": "white_concrete"
    },
    {
      "x": 12,
      "y": 6,
      "z": 4,
      "name": "white_concrete"
    },
    {
      "x": 0,
      "y": 6,
      "z": 5,
      "name": "white_concrete"
    },
    {
      "x": 12,
      "y": 6,
      "z": 5,
      "name": "white_concrete"
    },
    {
      "x": 0,
      "y": 6,
      "z": 6,
      "name": "white_concrete"
    },
    {
      "x": 12,
      "y": 6,
      "z": 6,
      "name": "white_concrete"
    },
    {
      "x": 0,
      "y": 6,
      "z": 7,
      "name": "white_concrete"
    },
    {
      "x": 12,
      "y": 6,
      "z": 7,
      "name": "white_concrete"
    },
    {
      "x": 0,
      "y": 6,
      "z": 8,
      "name": "white_concrete"
    },
    {
      "x": 12,
      "y": 6,
      "z": 8,
      "name": "white_concrete"
    },
    {
      "x": 0,
      "y": 6,
      "z": 9,
      "name": "gray_concrete"
    },
    {
      "x": 1,
      "y": 6,
      "z": 9,
      "name": "black_concrete"
    },
    {
      "x": 2,
      "y": 6,
      "z": 9,
      "name": "black_concrete"
    },
    {
      "x": 3,
      "y": 6,
      "z": 9,
      "name": "black_concrete"
    },
    {
      "x": 4,
      "y": 6,
      "z": 9,
      "name": "black_concrete"
    },
    {
      "x": 5,
      "y": 6,
      "z": 9,
      "name": "black_concrete"
    },
    {
      "x": 6,
      "y": 6,
      "z": 9,
      "name": "black_concrete"
    },
    {
      "x": 7,
      "y": 6,
      "z": 9,
      "name": "black_concrete"
    },
    {
      "x": 8,
      "y": 6,
      "z": 9,
      "name": "black_concrete"
    },
    {
      "x": 9,
      "y": 6,
      "z": 9,
      "name": "black_concrete"
    },
    {
      "x": 10,
      "y": 6,
      "z": 9,
      "name": "black_concrete"
    },
    {
      "x": 11,
      "y": 6,
      "z": 9,
      "name": "black_concrete"
    },
    {
      "x": 12,
      "y": 6,
      "z": 9,
      "name": "gray_concrete"
    },
    {
      "x": 0,
      "y": 7,
      "z": 0,
      "name": "smooth_quartz"
    },
    {
      "x": 1,
      "y": 7,
      "z": 0,
      "name": "smooth_quartz"
    },
    {
      "x": 2,
      "y": 7,
      "z": 0,
      "name": "smooth_quartz"
    },
    {
      "x": 3,
      "y": 7,
      "z": 0,
      "name": "smooth_quartz"
    },
    {
      "x": 4,
      "y": 7,
      "z": 0,
      "name": "smooth_quartz"
    },
    {
      "x": 5,
      "y": 7,
      "z": 0,
      "name": "smooth_quartz"
    },
    {
      "x": 6,
      "y": 7,
      "z": 0,
      "name": "smooth_quartz"
    },
    {
      "x": 7,
      "y": 7,
      "z": 0,
      "name": "smooth_quartz"
    },
    {
      "x": 8,
      "y": 7,
      "z": 0,
      "name": "smooth_quartz"
    },
    {
      "x": 9,
      "y": 7,
      "z": 0,
      "name": "smooth_quartz"
    },
    {
      "x": 10,
      "y": 7,
      "z": 0,
      "name": "smooth_quartz"
    },
    {
      "x": 11,
      "y": 7,
      "z": 0,
      "name": "smooth_quartz"
    },
    {
      "x": 12,
      "y": 7,
      "z": 0,
      "name": "smooth_quartz"
    },
    {
      "x": 0,
      "y": 7,
      "z": 1,
      "name": "smooth_quartz"
    },
    {
      "x": 1,
      "y": 7,
      "z": 1,
      "name": "smooth_quartz"
    },
    {
      "x": 2,
      "y": 7,
      "z": 1,
      "name": "smooth_quartz"
    },
    {
      "x": 3,
      "y": 7,
      "z": 1,
      "name": "smooth_quartz"
    },
    {
      "x": 4,
      "y": 7,
      "z": 1,
      "name": "smooth_quartz"
    },
    {
      "x": 5,
      "y": 7,
      "z": 1,
      "name": "smooth_quartz"
    },
    {
      "x": 6,
      "y": 7,
      "z": 1,
      "name": "smooth_quartz"
    },
    {
      "x": 7,
      "y": 7,
      "z": 1,
      "name": "smooth_quartz"
    },
    {
      "x": 8,
      "y": 7,
      "z": 1,
      "name": "smooth_quartz"
    },
    {
      "x": 9,
      "y": 7,
      "z": 1,
      "name": "smooth_quartz"
    },
    {
      "x": 10,
      "y": 7,
      "z": 1,
      "name": "smooth_quartz"
    },
    {
      "x": 11,
      "y": 7,
      "z": 1,
      "name": "smooth_quartz"
    },
    {
      "x": 12,
      "y": 7,
      "z": 1,
      "name": "smooth_quartz"
    },
    {
      "x": 0,
      "y": 7,
      "z": 2,
      "name": "smooth_quartz"
    },
    {
      "x": 1,
      "y": 7,
      "z": 2,
      "name": "smooth_quartz"
    },
    {
      "x": 2,
      "y": 7,
      "z": 2,
      "name": "smooth_quartz"
    },
    {
      "x": 3,
      "y": 7,
      "z": 2,
      "name": "smooth_quartz"
    },
    {
      "x": 4,
      "y": 7,
      "z": 2,
      "name": "smooth_quartz"
    },
    {
      "x": 5,
      "y": 7,
      "z": 2,
      "name": "smooth_quartz"
    },
    {
      "x": 6,
      "y": 7,
      "z": 2,
      "name": "smooth_quartz"
    },
    {
      "x": 7,
      "y": 7,
      "z": 2,
      "name": "smooth_quartz"
    },
    {
      "x": 8,
      "y": 7,
      "z": 2,
      "name": "smooth_quartz"
    },
    {
      "x": 9,
      "y": 7,
      "z": 2,
      "name": "smooth_quartz"
    },
    {
      "x": 10,
      "y": 7,
      "z": 2,
      "name": "smooth_quartz"
    },
    {
      "x": 11,
      "y": 7,
      "z": 2,
      "name": "smooth_quartz"
    },
    {
      "x": 12,
      "y": 7,
      "z": 2,
      "name": "smooth_quartz"
    },
    {
      "x": 0,
      "y": 7,
      "z": 3,
      "name": "smooth_quartz"
    },
    {
      "x": 1,
      "y": 7,
      "z": 3,
      "name": "smooth_quartz"
    },
    {
      "x": 2,
      "y": 7,
      "z": 3,
      "name": "smooth_quartz"
    },
    {
      "x": 3,
      "y": 7,
      "z": 3,
      "name": "smooth_quartz"
    },
    {
      "x": 4,
      "y": 7,
      "z": 3,
      "name": "smooth_quartz"
    },
    {
      "x": 5,
      "y": 7,
      "z": 3,
      "name": "smooth_quartz"
    },
    {
      "x": 6,
      "y": 7,
      "z": 3,
      "name": "smooth_quartz"
    },
    {
      "x": 7,
      "y": 7,
      "z": 3,
      "name": "smooth_quartz"
    },
    {
      "x": 8,
      "y": 7,
      "z": 3,
      "name": "smooth_quartz"
    },
    {
      "x": 9,
      "y": 7,
      "z": 3,
      "name": "smooth_quartz"
    },
    {
      "x": 10,
      "y": 7,
      "z": 3,
      "name": "smooth_quartz"
    },
    {
      "x": 11,
      "y": 7,
      "z": 3,
      "name": "smooth_quartz"
    },
    {
      "x": 12,
      "y": 7,
      "z": 3,
      "name": "smooth_quartz"
    },
    {
      "x": 0,
      "y": 7,
      "z": 4,
      "name": "smooth_quartz"
    },
    {
      "x": 1,
      "y": 7,
      "z": 4,
      "name": "smooth_quartz"
    },
    {
      "x": 2,
      "y": 7,
      "z": 4,
      "name": "smooth_quartz"
    },
    {
      "x": 3,
      "y": 7,
      "z": 4,
      "name": "smooth_quartz"
    },
    {
      "x": 4,
      "y": 7,
      "z": 4,
      "name": "smooth_quartz"
    },
    {
      "x": 5,
      "y": 7,
      "z": 4,
      "name": "smooth_quartz"
    },
    {
      "x": 6,
      "y": 7,
      "z": 4,
      "name": "smooth_quartz"
    },
    {
      "x": 7,
      "y": 7,
      "z": 4,
      "name": "smooth_quartz"
    },
    {
      "x": 8,
      "y": 7,
      "z": 4,
      "name": "smooth_quartz"
    },
    {
      "x": 9,
      "y": 7,
      "z": 4,
      "name": "smooth_quartz"
    },
    {
      "x": 10,
      "y": 7,
      "z": 4,
      "name": "smooth_quartz"
    },
    {
      "x": 11,
      "y": 7,
      "z": 4,
      "name": "smooth_quartz"
    },
    {
      "x": 12,
      "y": 7,
      "z": 4,
      "name": "smooth_quartz"
    },
    {
      "x": 0,
      "y": 7,
      "z": 5,
      "name": "smooth_quartz"
    },
    {
      "x": 1,
      "y": 7,
      "z": 5,
      "name": "smooth_quartz"
    },
    {
      "x": 2,
      "y": 7,
      "z": 5,
      "name": "smooth_quartz"
    },
    {
      "x": 3,
      "y": 7,
      "z": 5,
      "name": "smooth_quartz"
    },
    {
      "x": 4,
      "y": 7,
      "z": 5,
      "name": "smooth_quartz"
    },
    {
      "x": 5,
      "y": 7,
      "z": 5,
      "name": "smooth_quartz"
    },
    {
      "x": 6,
      "y": 7,
      "z": 5,
      "name": "smooth_quartz"
    },
    {
      "x": 7,
      "y": 7,
      "z": 5,
      "name": "smooth_quartz"
    },
    {
      "x": 8,
      "y": 7,
      "z": 5,
      "name": "smooth_quartz"
    },
    {
      "x": 9,
      "y": 7,
      "z": 5,
      "name": "smooth_quartz"
    },
    {
      "x": 10,
      "y": 7,
      "z": 5,
      "name": "smooth_quartz"
    },
    {
      "x": 11,
      "y": 7,
      "z": 5,
      "name": "smooth_quartz"
    },
    {
      "x": 12,
      "y": 7,
      "z": 5,
      "name": "smooth_quartz"
    },
    {
      "x": 0,
      "y": 7,
      "z": 6,
      "name": "smooth_quartz"
    },
    {
      "x": 1,
      "y": 7,
      "z": 6,
      "name": "smooth_quartz"
    },
    {
      "x": 2,
      "y": 7,
      "z": 6,
      "name": "smooth_quartz"
    },
    {
      "x": 3,
      "y": 7,
      "z": 6,
      "name": "smooth_quartz"
    },
    {
      "x": 4,
      "y": 7,
      "z": 6,
      "name": "smooth_quartz"
    },
    {
      "x": 5,
      "y": 7,
      "z": 6,
      "name": "smooth_quartz"
    },
    {
      "x": 6,
      "y": 7,
      "z": 6,
      "name": "smooth_quartz"
    },
    {
      "x": 7,
      "y": 7,
      "z": 6,
      "name": "smooth_quartz"
    },
    {
      "x": 8,
      "y": 7,
      "z": 6,
      "name": "smooth_quartz"
    },
    {
      "x": 9,
      "y": 7,
      "z": 6,
      "name": "smooth_quartz"
    },
    {
      "x": 10,
      "y": 7,
      "z": 6,
      "name": "smooth_quartz"
    },
    {
      "x": 11,
      "y": 7,
      "z": 6,
      "name": "smooth_quartz"
    },
    {
      "x": 12,
      "y": 7,
      "z": 6,
      "name": "smooth_quartz"
    },
    {
      "x": 0,
      "y": 7,
      "z": 7,
      "name": "smooth_quartz"
    },
    {
      "x": 1,
      "y": 7,
      "z": 7,
      "name": "smooth_quartz"
    },
    {
      "x": 2,
      "y": 7,
      "z": 7,
      "name": "smooth_quartz"
    },
    {
      "x": 3,
      "y": 7,
      "z": 7,
      "name": "smooth_quartz"
    },
    {
      "x": 4,
      "y": 7,
      "z": 7,
      "name": "smooth_quartz"
    },
    {
      "x": 5,
      "y": 7,
      "z": 7,
      "name": "smooth_quartz"
    },
    {
      "x": 6,
      "y": 7,
      "z": 7,
      "name": "smooth_quartz"
    },
    {
      "x": 7,
      "y": 7,
      "z": 7,
      "name": "smooth_quartz"
    },
    {
      "x": 8,
      "y": 7,
      "z": 7,
      "name": "smooth_quartz"
    },
    {
      "x": 9,
      "y": 7,
      "z": 7,
      "name": "smooth_quartz"
    },
    {
      "x": 10,
      "y": 7,
      "z": 7,
      "name": "smooth_quartz"
    },
    {
      "x": 11,
      "y": 7,
      "z": 7,
      "name": "smooth_quartz"
    },
    {
      "x": 12,
      "y": 7,
      "z": 7,
      "name": "smooth_quartz"
    },
    {
      "x": 0,
      "y": 7,
      "z": 8,
      "name": "smooth_quartz"
    },
    {
      "x": 1,
      "y": 7,
      "z": 8,
      "name": "smooth_quartz"
    },
    {
      "x": 2,
      "y": 7,
      "z": 8,
      "name": "smooth_quartz"
    },
    {
      "x": 3,
      "y": 7,
      "z": 8,
      "name": "smooth_quartz"
    },
    {
      "x": 4,
      "y": 7,
      "z": 8,
      "name": "smooth_quartz"
    },
    {
      "x": 5,
      "y": 7,
      "z": 8,
      "name": "smooth_quartz"
    },
    {
      "x": 6,
      "y": 7,
      "z": 8,
      "name": "smooth_quartz"
    },
    {
      "x": 7,
      "y": 7,
      "z": 8,
      "name": "smooth_quartz"
    },
    {
      "x": 8,
      "y": 7,
      "z": 8,
      "name": "smooth_quartz"
    },
    {
      "x": 9,
      "y": 7,
      "z": 8,
      "name": "smooth_quartz"
    },
    {
      "x": 10,
      "y": 7,
      "z": 8,
      "name": "smooth_quartz"
    },
    {
      "x": 11,
      "y": 7,
      "z": 8,
      "name": "smooth_quartz"
    },
    {
      "x": 12,
      "y": 7,
      "z": 8,
      "name": "smooth_quartz"
    },
    {
      "x": 0,
      "y": 7,
      "z": 9,
      "name": "smooth_quartz"
    },
    {
      "x": 1,
      "y": 7,
      "z": 9,
      "name": "smooth_quartz"
    },
    {
      "x": 2,
      "y": 7,
      "z": 9,
      "name": "smooth_quartz"
    },
    {
      "x": 3,
      "y": 7,
      "z": 9,
      "name": "smooth_quartz"
    },
    {
      "x": 4,
      "y": 7,
      "z": 9,
      "name": "smooth_quartz"
    },
    {
      "x": 5,
      "y": 7,
      "z": 9,
      "name": "smooth_quartz"
    },
    {
      "x": 6,
      "y": 7,
      "z": 9,
      "name": "smooth_quartz"
    },
    {
      "x": 7,
      "y": 7,
      "z": 9,
      "name": "smooth_quartz"
    },
    {
      "x": 8,
      "y": 7,
      "z": 9,
      "name": "smooth_quartz"
    },
    {
      "x": 9,
      "y": 7,
      "z": 9,
      "name": "smooth_quartz"
    },
    {
      "x": 10,
      "y": 7,
      "z": 9,
      "name": "smooth_quartz"
    },
    {
      "x": 11,
      "y": 7,
      "z": 9,
      "name": "smooth_quartz"
    },
    {
      "x": 12,
      "y": 7,
      "z": 9,
      "name": "smooth_quartz"
    },
    {
      "x": 0,
      "y": 8,
      "z": 0,
      "name": "gray_concrete"
    },
    {
      "x": 1,
      "y": 8,
      "z": 0,
      "name": "gray_concrete"
    },
    {
      "x": 2,
      "y": 8,
      "z": 0,
      "name": "gray_concrete"
    },
    {
      "x": 3,
      "y": 8,
      "z": 0,
      "name": "gray_concrete"
    },
    {
      "x": 4,
      "y": 8,
      "z": 0,
      "name": "gray_concrete"
    },
    {
      "x": 5,
      "y": 8,
      "z": 0,
      "name": "gray_concrete"
    },
    {
      "x": 6,
      "y": 8,
      "z": 0,
      "name": "gray_concrete"
    },
    {
      "x": 7,
      "y": 8,
      "z": 0,
      "name": "gray_concrete"
    },
    {
      "x": 8,
      "y": 8,
      "z": 0,
      "name": "gray_concrete"
    },
    {
      "x": 9,
      "y": 8,
      "z": 0,
      "name": "gray_concrete"
    },
    {
      "x": 10,
      "y": 8,
      "z": 0,
      "name": "gray_concrete"
    },
    {
      "x": 11,
      "y": 8,
      "z": 0,
      "name": "gray_concrete"
    },
    {
      "x": 12,
      "y": 8,
      "z": 0,
      "name": "gray_concrete"
    },
    {
      "x": 0,
      "y": 8,
      "z": 1,
      "name": "gray_concrete"
    },
    {
      "x": 12,
      "y": 8,
      "z": 1,
      "name": "gray_concrete"
    },
    {
      "x": 0,
      "y": 8,
      "z": 2,
      "name": "gray_concrete"
    },
    {
      "x": 12,
      "y": 8,
      "z": 2,
      "name": "gray_concrete"
    },
    {
      "x": 0,
      "y": 8,
      "z": 3,
      "name": "gray_concrete"
    },
    {
      "x": 12,
      "y": 8,
      "z": 3,
      "name": "gray_concrete"
    },
    {
      "x": 0,
      "y": 8,
      "z": 4,
      "name": "gray_concrete"
    },
    {
      "x": 12,
      "y": 8,
      "z": 4,
      "name": "gray_concrete"
    },
    {
      "x": 0,
      "y": 8,
      "z": 5,
      "name": "gray_concrete"
    },
    {
      "x": 12,
      "y": 8,
      "z": 5,
      "name": "gray_concrete"
    },
    {
      "x": 0,
      "y": 8,
      "z": 6,
      "name": "gray_concrete"
    },
    {
      "x": 12,
      "y": 8,
      "z": 6,
      "name": "gray_concrete"
    },
    {
      "x": 0,
      "y": 8,
      "z": 7,
      "name": "gray_concrete"
    },
    {
      "x": 12,
      "y": 8,
      "z": 7,
      "name": "gray_concrete"
    },
    {
      "x": 0,
      "y": 8,
      "z": 8,
      "name": "gray_concrete"
    },
    {
      "x": 12,
      "y": 8,
      "z": 8,
      "name": "gray_concrete"
    },
    {
      "x": 0,
      "y": 8,
      "z": 9,
      "name": "gray_concrete"
    },
    {
      "x": 1,
      "y": 8,
      "z": 9,
      "name": "gray_concrete"
    },
    {
      "x": 2,
      "y": 8,
      "z": 9,
      "name": "gray_concrete"
    },
    {
      "x": 3,
      "y": 8,
      "z": 9,
      "name": "gray_concrete"
    },
    {
      "x": 4,
      "y": 8,
      "z": 9,
      "name": "gray_concrete"
    },
    {
      "x": 5,
      "y": 8,
      "z": 9,
      "name": "gray_concrete"
    },
    {
      "x": 6,
      "y": 8,
      "z": 9,
      "name": "gray_concrete"
    },
    {
      "x": 7,
      "y": 8,
      "z": 9,
      "name": "gray_concrete"
    },
    {
      "x": 8,
      "y": 8,
      "z": 9,
      "name": "gray_concrete"
    },
    {
      "x": 9,
      "y": 8,
      "z": 9,
      "name": "gray_concrete"
    },
    {
      "x": 10,
      "y": 8,
      "z": 9,
      "name": "gray_concrete"
    },
    {
      "x": 11,
      "y": 8,
      "z": 9,
      "name": "gray_concrete"
    },
    {
      "x": 12,
      "y": 8,
      "z": 9,
      "name": "gray_concrete"
    }
  ]
}
