{
  "_opis": "Preprosta lesena klop za park.",
  "_category": "decor",
  "_kind": "decor",
  "_aliases": [
    "klop"
  ],
  "size": [
    7,
    4,
    3
  ],
  "blocks": [
    {
      "x": 0,
      "y": 0,
      "z": 0,
      "name": "grass_block"
    },
    {
      "x": 1,
      "y": 0,
      "z": 0,
      "name": "grass_block"
    },
    {
      "x": 2,
      "y": 0,
      "z": 0,
      "name": "grass_block"
    },
    {
      "x": 3,
      "y": 0,
      "z": 0,
      "name": "grass_block"
    },
    {
      "x": 4,
      "y": 0,
      "z": 0,
      "name": "grass_block"
    },
    {
      "x": 5,
      "y": 0,
      "z": 0,
      "name": "grass_block"
    },
    {
      "x": 6,
      "y": 0,
      "z": 0,
      "name": "grass_block"
    },
    {
      "x": 0,
      "y": 0,
      "z": 1,
      "name": "grass_block"
    },
    {
      "x": 1,
      "y": 0,
      "z": 1,
      "name": "grass_block"
    },
    {
      "x": 2,
      "y": 0,
      "z": 1,
      "name": "grass_block"
    },
    {
      "x": 3,
      "y": 0,
      "z": 1,
      "name": "grass_block"
    },
    {
      "x": 4,
      "y": 0,
      "z": 1,
      "name": "grass_block"
    },
    {
      "x": 5,
      "y": 0,
      "z": 1,
      "name": "grass_block"
    },
    {
      "x": 6,
      "y": 0,
      "z": 1,
      "name": "grass_block"
    },
    {
      "x": 0,
      "y": 0,
      "z": 2,
      "name": "grass_block"
    },
    {
      "x": 1,
      "y": 0,
      "z": 2,
      "name": "grass_block"
    },
    {
      "x": 2,
      "y": 0,
      "z": 2,
      "name": "grass_block"
    },
    {
      "x": 3,
      "y": 0,
      "z": 2,
      "name": "grass_block"
    },
    {
      "x": 4,
      "y": 0,
      "z": 2,
      "name": "grass_block"
    },
    {
      "x": 5,
      "y": 0,
      "z": 2,
      "name": "grass_block"
    },
    {
      "x": 6,
      "y": 0,
      "z": 2,
      "name": "grass_block"
    },
    {
      "x": 1,
      "y": 1,
      "z": 1,
      "name": "oak_log"
    },
    {
      "x": 5,
      "y": 1,
      "z": 1,
      "name": "oak_log"
    },
    {
      "x": 1,
      "y": 2,
      "z": 1,
      "name": "oak_slab"
    },
    {
      "x": 2,
      "y": 2,
      "z": 1,
      "name": "oak_slab"
    },
    {
      "x": 3,
      "y": 2,
      "z": 1,
      "name": "oak_slab"
    },
    {
      "x": 4,
      "y": 2,
      "z": 1,
      "name": "oak_slab"
    },
    {
      "x": 5,
      "y": 2,
      "z": 1,
      "name": "oak_slab"
    },
    {
      "x": 1,
      "y": 3,
      "z": 2,
      "name": "oak_slab"
    },
    {
      "x": 2,
      "y": 3,
      "z": 2,
      "name": "oak_slab"
    },
    {
      "x": 3,
      "y": 3,
      "z": 2,
      "name": "oak_slab"
    },
    {
      "x": 4,
      "y": 3,
      "z": 2,
      "name": "oak_slab"
    },
    {
      "x": 5,
      "y": 3,
      "z": 2,
      "name": "oak_slab"
    }
  ]
}
