{
  "_opis": "Piknik miza s klopema in majhno senco.",
  "_category": "decor",
  "_kind": "decor",
  "_aliases": [
    "piknik",
    "picnic"
  ],
  "size": [
    7,
    4,
    5
  ],
  "blocks": [
    {
      "x": 0,
      "y": 0,
      "z": 0,
      "name": "grass_block"
    },
    {
      "x": 1,
      "y": 0,
      "z": 0,
      "name": "grass_block"
    },
    {
      "x": 2,
      "y": 0,
      "z": 0,
      "name": "grass_block"
    },
    {
      "x": 3,
      "y": 0,
      "z": 0,
      "name": "grass_block"
    },
    {
      "x": 4,
      "y": 0,
      "z": 0,
      "name": "grass_block"
    },
    {
      "x": 5,
      "y": 0,
      "z": 0,
      "name": "grass_block"
    },
    {
      "x": 6,
      "y": 0,
      "z": 0,
      "name": "grass_block"
    },
    {
      "x": 0,
      "y": 0,
      "z": 1,
      "name": "grass_block"
    },
    {
      "x": 1,
      "y": 0,
      "z": 1,
      "name": "grass_block"
    },
    {
      "x": 2,
      "y": 0,
      "z": 1,
      "name": "grass_block"
    },
    {
      "x": 3,
      "y": 0,
      "z": 1,
      "name": "grass_block"
    },
    {
      "x": 4,
      "y": 0,
      "z": 1,
      "name": "grass_block"
    },
    {
      "x": 5,
      "y": 0,
      "z": 1,
      "name": "grass_block"
    },
    {
      "x": 6,
      "y": 0,
      "z": 1,
      "name": "grass_block"
    },
    {
      "x": 0,
      "y": 0,
      "z": 2,
      "name": "grass_block"
    },
    {
      "x": 1,
      "y": 0,
      "z": 2,
      "name": "grass_block"
    },
    {
      "x": 2,
      "y": 0,
      "z": 2,
      "name": "grass_block"
    },
    {
      "x": 3,
      "y": 0,
      "z": 2,
      "name": "grass_block"
    },
    {
      "x": 4,
      "y": 0,
      "z": 2,
      "name": "grass_block"
    },
    {
      "x": 5,
      "y": 0,
      "z": 2,
      "name": "grass_block"
    },
    {
      "x": 6,
      "y": 0,
      "z": 2,
      "name": "grass_block"
    },
    {
      "x": 0,
      "y": 0,
      "z": 3,
      "name": "grass_block"
    },
    {
      "x": 1,
      "y": 0,
      "z": 3,
      "name": "grass_block"
    },
    {
      "x": 2,
      "y": 0,
      "z": 3,
      "name": "grass_block"
    },
    {
      "x": 3,
      "y": 0,
      "z": 3,
      "name": "grass_block"
    },
    {
      "x": 4,
      "y": 0,
      "z": 3,
      "name": "grass_block"
    },
    {
      "x": 5,
      "y": 0,
      "z": 3,
      "name": "grass_block"
    },
    {
      "x": 6,
      "y": 0,
      "z": 3,
      "name": "grass_block"
    },
    {
      "x": 0,
      "y": 0,
      "z": 4,
      "name": "grass_block"
    },
    {
      "x": 1,
      "y": 0,
      "z": 4,
      "name": "grass_block"
    },
    {
      "x": 2,
      "y": 0,
      "z": 4,
      "name": "grass_block"
    },
    {
      "x": 3,
      "y": 0,
      "z": 4,
      "name": "grass_block"
    },
    {
      "x": 4,
      "y": 0,
      "z": 4,
      "name": "grass_block"
    },
    {
      "x": 5,
      "y": 0,
      "z": 4,
      "name": "grass_block"
    },
    {
      "x": 6,
      "y": 0,
      "z": 4,
      "name": "grass_block"
    },
    {
      "x": 1,
      "y": 1,
      "z": 1,
      "name": "spruce_slab"
    },
    {
      "x": 2,
      "y": 1,
      "z": 1,
      "name": "spruce_slab"
    },
    {
      "x": 3,
      "y": 1,
      "z": 1,
      "name": "spruce_slab"
    },
    {
      "x": 4,
      "y": 1,
      "z": 1,
      "name": "spruce_slab"
    },
    {
      "x": 5,
      "y": 1,
      "z": 1,
      "name": "spruce_slab"
    },
    {
      "x": 2,
      "y": 1,
      "z": 2,
      "name": "oak_fence"
    },
    {
      "x": 3,
      "y": 1,
      "z": 2,
      "name": "oak_fence"
    },
    {
      "x": 4,
      "y": 1,
      "z": 2,
      "name": "oak_fence"
    },
    {
      "x": 1,
      "y": 1,
      "z": 3,
      "name": "spruce_slab"
    },
    {
      "x": 2,
      "y": 1,
      "z": 3,
      "name": "spruce_slab"
    },
    {
      "x": 3,
      "y": 1,
      "z": 3,
      "name": "spruce_slab"
    },
    {
      "x": 4,
      "y": 1,
      "z": 3,
      "name": "spruce_slab"
    },
    {
      "x": 5,
      "y": 1,
      "z": 3,
      "name": "spruce_slab"
    },
    {
      "x": 2,
      "y": 2,
      "z": 2,
      "name": "oak_slab"
    },
    {
      "x": 3,
      "y": 2,
      "z": 2,
      "name": "oak_fence"
    },
    {
      "x": 4,
      "y": 2,
      "z": 2,
      "name": "oak_slab"
    },
    {
      "x": 2,
      "y": 3,
      "z": 1,
      "name": "yellow_wool"
    },
    {
      "x": 3,
      "y": 3,
      "z": 1,
      "name": "yellow_wool"
    },
    {
      "x": 4,
      "y": 3,
      "z": 1,
      "name": "yellow_wool"
    },
    {
      "x": 2,
      "y": 3,
      "z": 2,
      "name": "yellow_wool"
    },
    {
      "x": 3,
      "y": 3,
      "z": 2,
      "name": "yellow_wool"
    },
    {
      "x": 4,
      "y": 3,
      "z": 2,
      "name": "yellow_wool"
    },
    {
      "x": 2,
      "y": 3,
      "z": 3,
      "name": "yellow_wool"
    },
    {
      "x": 3,
      "y": 3,
      "z": 3,
      "name": "yellow_wool"
    },
    {
      "x": 4,
      "y": 3,
      "z": 3,
      "name": "yellow_wool"
    }
  ]
}
