{
  "_opis": "Strasilo za rob polja ali vrt.",
  "_category": "decor",
  "_kind": "decor",
  "_aliases": [
    "strasilo",
    "scarecrow"
  ],
  "size": [
    5,
    6,
    5
  ],
  "blocks": [
    {
      "x": 0,
      "y": 0,
      "z": 0,
      "name": "farmland"
    },
    {
      "x": 1,
      "y": 0,
      "z": 0,
      "name": "farmland"
    },
    {
      "x": 2,
      "y": 0,
      "z": 0,
      "name": "farmland"
    },
    {
      "x": 3,
      "y": 0,
      "z": 0,
      "name": "farmland"
    },
    {
      "x": 4,
      "y": 0,
      "z": 0,
      "name": "farmland"
    },
    {
      "x": 0,
      "y": 0,
      "z": 1,
      "name": "farmland"
    },
    {
      "x": 1,
      "y": 0,
      "z": 1,
      "name": "farmland"
    },
    {
      "x": 2,
      "y": 0,
      "z": 1,
      "name": "farmland"
    },
    {
      "x": 3,
      "y": 0,
      "z": 1,
      "name": "farmland"
    },
    {
      "x": 4,
      "y": 0,
      "z": 1,
      "name": "farmland"
    },
    {
      "x": 0,
      "y": 0,
      "z": 2,
      "name": "farmland"
    },
    {
      "x": 1,
      "y": 0,
      "z": 2,
      "name": "farmland"
    },
    {
      "x": 2,
      "y": 0,
      "z": 2,
      "name": "farmland"
    },
    {
      "x": 3,
      "y": 0,
      "z": 2,
      "name": "farmland"
    },
    {
      "x": 4,
      "y": 0,
      "z": 2,
      "name": "farmland"
    },
    {
      "x": 0,
      "y": 0,
      "z": 3,
      "name": "farmland"
    },
    {
      "x": 1,
      "y": 0,
      "z": 3,
      "name": "farmland"
    },
    {
      "x": 2,
      "y": 0,
      "z": 3,
      "name": "farmland"
    },
    {
      "x": 3,
      "y": 0,
      "z": 3,
      "name": "farmland"
    },
    {
      "x": 4,
      "y": 0,
      "z": 3,
      "name": "farmland"
    },
    {
      "x": 0,
      "y": 0,
      "z": 4,
      "name": "farmland"
    },
    {
      "x": 1,
      "y": 0,
      "z": 4,
      "name": "farmland"
    },
    {
      "x": 2,
      "y": 0,
      "z": 4,
      "name": "farmland"
    },
    {
      "x": 3,
      "y": 0,
      "z": 4,
      "name": "farmland"
    },
    {
      "x": 4,
      "y": 0,
      "z": 4,
      "name": "farmland"
    },
    {
      "x": 2,
      "y": 1,
      "z": 2,
      "name": "oak_fence"
    },
    {
      "x": 1,
      "y": 2,
      "z": 1,
      "name": "wheat"
    },
    {
      "x": 3,
      "y": 2,
      "z": 1,
      "name": "wheat"
    },
    {
      "x": 2,
      "y": 2,
      "z": 2,
      "name": "oak_fence"
    },
    {
      "x": 1,
      "y": 2,
      "z": 3,
      "name": "carrots"
    },
    {
      "x": 3,
      "y": 2,
      "z": 3,
      "name": "potatoes"
    },
    {
      "x": 0,
      "y": 3,
      "z": 2,
      "name": "oak_fence"
    },
    {
      "x": 1,
      "y": 3,
      "z": 2,
      "name": "oak_fence"
    },
    {
      "x": 2,
      "y": 3,
      "z": 2,
      "name": "oak_fence"
    },
    {
      "x": 3,
      "y": 3,
      "z": 2,
      "name": "oak_fence"
    },
    {
      "x": 4,
      "y": 3,
      "z": 2,
      "name": "oak_fence"
    },
    {
      "x": 2,
      "y": 4,
      "z": 2,
      "name": "hay_block"
    },
    {
      "x": 2,
      "y": 5,
      "z": 2,
      "name": "carved_pumpkin"
    }
  ]
}
