{"_opis":"3x3 kamniti stolp, 8 visok","size":[3,9,3],"blocks":[{"x":0,"y":0,"z":0,"name":"cobblestone"},{"x":0,"y":8,"z":0,"name":"cobblestone"},{"x":0,"y":0,"z":1,"name":"cobblestone"},{"x":0,"y":8,"z":1,"name":"cobblestone"},{"x":0,"y":0,"z":2,"name":"cobblestone"},{"x":0,"y":8,"z":2,"name":"cobblestone"},{"x":1,"y":0,"z":0,"name":"cobblestone"},{"x":1,"y":8,"z":0,"name":"cobblestone"},{"x":1,"y":0,"z":1,"name":"cobblestone"},{"x":1,"y":8,"z":1,"name":"cobblestone"},{"x":1,"y":0,"z":2,"name":"cobblestone"},{"x":1,"y":8,"z":2,"name":"cobblestone"},{"x":2,"y":0,"z":0,"name":"cobblestone"},{"x":2,"y":8,"z":0,"name":"cobblestone"},{"x":2,"y":0,"z":1,"name":"cobblestone"},{"x":2,"y":8,"z":1,"name":"cobblestone"},{"x":2,"y":0,"z":2,"name":"cobblestone"},{"x":2,"y":8,"z":2,"name":"cobblestone"},{"x":0,"y":1,"z":0,"name":"cobblestone"},{"x":0,"y":1,"z":1,"name":"cobblestone"},{"x":0,"y":1,"z":2,"name":"cobblestone"},{"x":1,"y":1,"z":2,"name":"cobblestone"},{"x":2,"y":1,"z":0,"name":"cobblestone"},{"x":2,"y":1,"z":1,"name":"cobblestone"},{"x":2,"y":1,"z":2,"name":"cobblestone"},{"x":0,"y":2,"z":0,"name":"cobblestone"},{"x":0,"y":2,"z":1,"name":"cobblestone"},{"x":0,"y":2,"z":2,"name":"cobblestone"},{"x":1,"y":2,"z":2,"name":"cobblestone"},{"x":2,"y":2,"z":0,"name":"cobblestone"},{"x":2,"y":2,"z":1,"name":"cobblestone"},{"x":2,"y":2,"z":2,"name":"cobblestone"},{"x":0,"y":3,"z":0,"name":"cobblestone"},{"x":0,"y":3,"z":1,"name":"cobblestone"},{"x":0,"y":3,"z":2,"name":"cobblestone"},{"x":1,"y":3,"z":0,"name":"cobblestone"},{"x":1,"y":3,"z":2,"name":"cobblestone"},{"x":2,"y":3,"z":0,"name":"cobblestone"},{"x":2,"y":3,"z":1,"name":"cobblestone"},{"x":2,"y":3,"z":2,"name":"cobblestone"},{"x":0,"y":4,"z":0,"name":"cobblestone"},{"x":0,"y":4,"z":1,"name":"cobblestone"},{"x":0,"y":4,"z":2,"name":"cobblestone"},{"x":1,"y":4,"z":0,"name":"cobblestone"},{"x":1,"y":4,"z":2,"name":"cobblestone"},{"x":2,"y":4,"z":0,"name":"cobblestone"},{"x":2,"y":4,"z":1,"name":"cobblestone"},{"x":2,"y":4,"z":2,"name":"cobblestone"},{"x":0,"y":5,"z":0,"name":"cobblestone"},{"x":0,"y":5,"z":1,"name":"cobblestone"},{"x":0,"y":5,"z":2,"name":"cobblestone"},{"x":1,"y":5,"z":0,"name":"cobblestone"},{"x":1,"y":5,"z":2,"name":"cobblestone"},{"x":2,"y":5,"z":0,"name":"cobblestone"},{"x":2,"y":5,"z":1,"name":"cobblestone"},{"x":2,"y":5,"z":2,"name":"cobblestone"},{"x":0,"y":6,"z":0,"name":"cobblestone"},{"x":0,"y":6,"z":1,"name":"cobblestone"},{"x":0,"y":6,"z":2,"name":"cobblestone"},{"x":1,"y":6,"z":0,"name":"cobblestone"},{"x":1,"y":6,"z":2,"name":"cobblestone"},{"x":2,"y":6,"z":0,"name":"cobblestone"},{"x":2,"y":6,"z":1,"name":"cobblestone"},{"x":2,"y":6,"z":2,"name":"cobblestone"},{"x":0,"y":7,"z":0,"name":"cobblestone"},{"x":0,"y":7,"z":1,"name":"cobblestone"},{"x":0,"y":7,"z":2,"name":"cobblestone"},{"x":1,"y":7,"z":0,"name":"cobblestone"},{"x":1,"y":7,"z":2,"name":"cobblestone"},{"x":2,"y":7,"z":0,"name":"cobblestone"},{"x":2,"y":7,"z":1,"name":"cobblestone"},{"x":2,"y":7,"z":2,"name":"cobblestone"}]}